[ERROR][2020-12-03 03:00:28,711][log.py:228]Internal Server Error: /api/customers/
Traceback (most recent call last):
  File "/usr/local/lib/python3.7/site-packages/django/core/handlers/exception.py", line 34, in inner
    response = get_response(request)
  File "/usr/local/lib/python3.7/site-packages/django/utils/deprecation.py", line 93, in __call__
    response = self.process_request(request)
  File "/usr/local/lib/python3.7/site-packages/django/contrib/auth/middleware.py", line 23, in process_request
    ) % ("_CLASSES" if settings.MIDDLEWARE is None else "")
AssertionError: The Django authentication middleware requires session middleware to be installed. Edit your MIDDLEWARE setting to insert 'django.contrib.sessions.middleware.SessionMiddleware' before 'django.contrib.auth.middleware.AuthenticationMiddleware'.
[ERROR][2020-12-03 03:00:30,815][log.py:228]Internal Server Error: /api/orders/
Traceback (most recent call last):
  File "/usr/local/lib/python3.7/site-packages/django/core/handlers/exception.py", line 34, in inner
    response = get_response(request)
  File "/usr/local/lib/python3.7/site-packages/django/utils/deprecation.py", line 93, in __call__
    response = self.process_request(request)
  File "/usr/local/lib/python3.7/site-packages/django/contrib/auth/middleware.py", line 23, in process_request
    ) % ("_CLASSES" if settings.MIDDLEWARE is None else "")
AssertionError: The Django authentication middleware requires session middleware to be installed. Edit your MIDDLEWARE setting to insert 'django.contrib.sessions.middleware.SessionMiddleware' before 'django.contrib.auth.middleware.AuthenticationMiddleware'.
[ERROR][2020-12-03 03:00:58,551][log.py:228]Internal Server Error: /api/staffs/1/
Traceback (most recent call last):
  File "/usr/local/lib/python3.7/site-packages/django/core/handlers/exception.py", line 34, in inner
    response = get_response(request)
  File "/usr/local/lib/python3.7/site-packages/django/utils/deprecation.py", line 93, in __call__
    response = self.process_request(request)
  File "/usr/local/lib/python3.7/site-packages/django/contrib/messages/middleware.py", line 12, in process_request
    request._messages = default_storage(request)
  File "/usr/local/lib/python3.7/site-packages/django/contrib/messages/storage/__init__.py", line 12, in default_storage
    return import_string(settings.MESSAGE_STORAGE)(request)
  File "/usr/local/lib/python3.7/site-packages/django/contrib/messages/storage/fallback.py", line 16, in __init__
    for storage_class in self.storage_classes]
  File "/usr/local/lib/python3.7/site-packages/django/contrib/messages/storage/fallback.py", line 16, in <listcomp>
    for storage_class in self.storage_classes]
  File "/usr/local/lib/python3.7/site-packages/django/contrib/messages/storage/session.py", line 20, in __init__
    "MIDDLEWARE%s list." % ("_CLASSES" if settings.MIDDLEWARE is None else "")
AssertionError: The session-based temporary message storage requires session middleware to be installed, and come before the message middleware in the MIDDLEWARE list.
[ERROR][2020-12-03 03:00:58,721][log.py:228]Internal Server Error: /api/orders/
Traceback (most recent call last):
  File "/usr/local/lib/python3.7/site-packages/django/core/handlers/exception.py", line 34, in inner
    response = get_response(request)
  File "/usr/local/lib/python3.7/site-packages/django/utils/deprecation.py", line 93, in __call__
    response = self.process_request(request)
  File "/usr/local/lib/python3.7/site-packages/django/contrib/messages/middleware.py", line 12, in process_request
    request._messages = default_storage(request)
  File "/usr/local/lib/python3.7/site-packages/django/contrib/messages/storage/__init__.py", line 12, in default_storage
    return import_string(settings.MESSAGE_STORAGE)(request)
  File "/usr/local/lib/python3.7/site-packages/django/contrib/messages/storage/fallback.py", line 16, in __init__
    for storage_class in self.storage_classes]
  File "/usr/local/lib/python3.7/site-packages/django/contrib/messages/storage/fallback.py", line 16, in <listcomp>
    for storage_class in self.storage_classes]
  File "/usr/local/lib/python3.7/site-packages/django/contrib/messages/storage/session.py", line 20, in __init__
    "MIDDLEWARE%s list." % ("_CLASSES" if settings.MIDDLEWARE is None else "")
AssertionError: The session-based temporary message storage requires session middleware to be installed, and come before the message middleware in the MIDDLEWARE list.
[ERROR][2020-12-03 06:35:02,680][log.py:228]Internal Server Error: /api/product_to_pack/
Traceback (most recent call last):
  File "/usr/local/lib/python3.7/site-packages/django/db/backends/utils.py", line 86, in _execute
    return self.cursor.execute(sql, params)
psycopg2.errors.NotNullViolation: null value in column "packs_id" violates not-null constraint
DETAIL:  Failing row contains (1, 2020-12-03, null, null).


The above exception was the direct cause of the following exception:

Traceback (most recent call last):
  File "/usr/local/lib/python3.7/site-packages/django/core/handlers/exception.py", line 34, in inner
    response = get_response(request)
  File "/usr/local/lib/python3.7/site-packages/django/core/handlers/base.py", line 115, in _get_response
    response = self.process_exception_by_middleware(e, request)
  File "/usr/local/lib/python3.7/site-packages/django/core/handlers/base.py", line 113, in _get_response
    response = wrapped_callback(request, *callback_args, **callback_kwargs)
  File "/usr/local/lib/python3.7/site-packages/django/views/decorators/csrf.py", line 54, in wrapped_view
    return view_func(*args, **kwargs)
  File "/usr/local/lib/python3.7/site-packages/rest_framework/viewsets.py", line 114, in view
    return self.dispatch(request, *args, **kwargs)
  File "/usr/local/lib/python3.7/site-packages/rest_framework/views.py", line 505, in dispatch
    response = self.handle_exception(exc)
  File "/usr/local/lib/python3.7/site-packages/rest_framework/views.py", line 465, in handle_exception
    self.raise_uncaught_exception(exc)
  File "/usr/local/lib/python3.7/site-packages/rest_framework/views.py", line 476, in raise_uncaught_exception
    raise exc
  File "/usr/local/lib/python3.7/site-packages/rest_framework/views.py", line 502, in dispatch
    response = handler(request, *args, **kwargs)
  File "/usr/local/lib/python3.7/site-packages/rest_framework/mixins.py", line 19, in create
    self.perform_create(serializer)
  File "/usr/local/lib/python3.7/site-packages/rest_framework/mixins.py", line 24, in perform_create
    serializer.save()
  File "/usr/local/lib/python3.7/site-packages/rest_framework/serializers.py", line 213, in save
    self.instance = self.create(validated_data)
  File "/usr/local/lib/python3.7/site-packages/rest_framework/serializers.py", line 932, in create
    instance = ModelClass._default_manager.create(**validated_data)
  File "/usr/local/lib/python3.7/site-packages/django/db/models/manager.py", line 82, in manager_method
    return getattr(self.get_queryset(), name)(*args, **kwargs)
  File "/usr/local/lib/python3.7/site-packages/django/db/models/query.py", line 433, in create
    obj.save(force_insert=True, using=self.db)
  File "/usr/local/lib/python3.7/site-packages/django/db/models/base.py", line 746, in save
    force_update=force_update, update_fields=update_fields)
  File "/usr/local/lib/python3.7/site-packages/django/db/models/base.py", line 784, in save_base
    force_update, using, update_fields,
  File "/usr/local/lib/python3.7/site-packages/django/db/models/base.py", line 887, in _save_table
    results = self._do_insert(cls._base_manager, using, fields, returning_fields, raw)
  File "/usr/local/lib/python3.7/site-packages/django/db/models/base.py", line 926, in _do_insert
    using=using, raw=raw,
  File "/usr/local/lib/python3.7/site-packages/django/db/models/manager.py", line 82, in manager_method
    return getattr(self.get_queryset(), name)(*args, **kwargs)
  File "/usr/local/lib/python3.7/site-packages/django/db/models/query.py", line 1204, in _insert
    return query.get_compiler(using=using).execute_sql(returning_fields)
  File "/usr/local/lib/python3.7/site-packages/django/db/models/sql/compiler.py", line 1391, in execute_sql
    cursor.execute(sql, params)
  File "/usr/local/lib/python3.7/site-packages/django/db/backends/utils.py", line 100, in execute
    return super().execute(sql, params)
  File "/usr/local/lib/python3.7/site-packages/django/db/backends/utils.py", line 68, in execute
    return self._execute_with_wrappers(sql, params, many=False, executor=self._execute)
  File "/usr/local/lib/python3.7/site-packages/django/db/backends/utils.py", line 77, in _execute_with_wrappers
    return executor(sql, params, many, context)
  File "/usr/local/lib/python3.7/site-packages/django/db/backends/utils.py", line 86, in _execute
    return self.cursor.execute(sql, params)
  File "/usr/local/lib/python3.7/site-packages/django/db/utils.py", line 90, in __exit__
    raise dj_exc_value.with_traceback(traceback) from exc_value
  File "/usr/local/lib/python3.7/site-packages/django/db/backends/utils.py", line 86, in _execute
    return self.cursor.execute(sql, params)
django.db.utils.IntegrityError: null value in column "packs_id" violates not-null constraint
DETAIL:  Failing row contains (1, 2020-12-03, null, null).

[ERROR][2020-12-03 06:35:42,725][log.py:228]Internal Server Error: /api/product_to_pack/
Traceback (most recent call last):
  File "/usr/local/lib/python3.7/site-packages/django/db/backends/utils.py", line 86, in _execute
    return self.cursor.execute(sql, params)
psycopg2.errors.NotNullViolation: null value in column "packs_id" violates not-null constraint
DETAIL:  Failing row contains (2, 2020-12-03, null, null).


The above exception was the direct cause of the following exception:

Traceback (most recent call last):
  File "/usr/local/lib/python3.7/site-packages/django/core/handlers/exception.py", line 34, in inner
    response = get_response(request)
  File "/usr/local/lib/python3.7/site-packages/django/core/handlers/base.py", line 115, in _get_response
    response = self.process_exception_by_middleware(e, request)
  File "/usr/local/lib/python3.7/site-packages/django/core/handlers/base.py", line 113, in _get_response
    response = wrapped_callback(request, *callback_args, **callback_kwargs)
  File "/usr/local/lib/python3.7/site-packages/django/views/decorators/csrf.py", line 54, in wrapped_view
    return view_func(*args, **kwargs)
  File "/usr/local/lib/python3.7/site-packages/rest_framework/viewsets.py", line 114, in view
    return self.dispatch(request, *args, **kwargs)
  File "/usr/local/lib/python3.7/site-packages/rest_framework/views.py", line 505, in dispatch
    response = self.handle_exception(exc)
  File "/usr/local/lib/python3.7/site-packages/rest_framework/views.py", line 465, in handle_exception
    self.raise_uncaught_exception(exc)
  File "/usr/local/lib/python3.7/site-packages/rest_framework/views.py", line 476, in raise_uncaught_exception
    raise exc
  File "/usr/local/lib/python3.7/site-packages/rest_framework/views.py", line 502, in dispatch
    response = handler(request, *args, **kwargs)
  File "/usr/local/lib/python3.7/site-packages/rest_framework/mixins.py", line 19, in create
    self.perform_create(serializer)
  File "/usr/local/lib/python3.7/site-packages/rest_framework/mixins.py", line 24, in perform_create
    serializer.save()
  File "/usr/local/lib/python3.7/site-packages/rest_framework/serializers.py", line 213, in save
    self.instance = self.create(validated_data)
  File "/usr/local/lib/python3.7/site-packages/rest_framework/serializers.py", line 932, in create
    instance = ModelClass._default_manager.create(**validated_data)
  File "/usr/local/lib/python3.7/site-packages/django/db/models/manager.py", line 82, in manager_method
    return getattr(self.get_queryset(), name)(*args, **kwargs)
  File "/usr/local/lib/python3.7/site-packages/django/db/models/query.py", line 433, in create
    obj.save(force_insert=True, using=self.db)
  File "/usr/local/lib/python3.7/site-packages/django/db/models/base.py", line 746, in save
    force_update=force_update, update_fields=update_fields)
  File "/usr/local/lib/python3.7/site-packages/django/db/models/base.py", line 784, in save_base
    force_update, using, update_fields,
  File "/usr/local/lib/python3.7/site-packages/django/db/models/base.py", line 887, in _save_table
    results = self._do_insert(cls._base_manager, using, fields, returning_fields, raw)
  File "/usr/local/lib/python3.7/site-packages/django/db/models/base.py", line 926, in _do_insert
    using=using, raw=raw,
  File "/usr/local/lib/python3.7/site-packages/django/db/models/manager.py", line 82, in manager_method
    return getattr(self.get_queryset(), name)(*args, **kwargs)
  File "/usr/local/lib/python3.7/site-packages/django/db/models/query.py", line 1204, in _insert
    return query.get_compiler(using=using).execute_sql(returning_fields)
  File "/usr/local/lib/python3.7/site-packages/django/db/models/sql/compiler.py", line 1391, in execute_sql
    cursor.execute(sql, params)
  File "/usr/local/lib/python3.7/site-packages/django/db/backends/utils.py", line 100, in execute
    return super().execute(sql, params)
  File "/usr/local/lib/python3.7/site-packages/django/db/backends/utils.py", line 68, in execute
    return self._execute_with_wrappers(sql, params, many=False, executor=self._execute)
  File "/usr/local/lib/python3.7/site-packages/django/db/backends/utils.py", line 77, in _execute_with_wrappers
    return executor(sql, params, many, context)
  File "/usr/local/lib/python3.7/site-packages/django/db/backends/utils.py", line 86, in _execute
    return self.cursor.execute(sql, params)
  File "/usr/local/lib/python3.7/site-packages/django/db/utils.py", line 90, in __exit__
    raise dj_exc_value.with_traceback(traceback) from exc_value
  File "/usr/local/lib/python3.7/site-packages/django/db/backends/utils.py", line 86, in _execute
    return self.cursor.execute(sql, params)
django.db.utils.IntegrityError: null value in column "packs_id" violates not-null constraint
DETAIL:  Failing row contains (2, 2020-12-03, null, null).

[ERROR][2020-12-03 06:36:36,323][log.py:228]Internal Server Error: /api/product_to_pack/
Traceback (most recent call last):
  File "/usr/local/lib/python3.7/site-packages/django/db/backends/utils.py", line 86, in _execute
    return self.cursor.execute(sql, params)
psycopg2.errors.NotNullViolation: null value in column "packs_id" violates not-null constraint
DETAIL:  Failing row contains (3, 2020-12-03, null, null).


The above exception was the direct cause of the following exception:

Traceback (most recent call last):
  File "/usr/local/lib/python3.7/site-packages/django/core/handlers/exception.py", line 34, in inner
    response = get_response(request)
  File "/usr/local/lib/python3.7/site-packages/django/core/handlers/base.py", line 115, in _get_response
    response = self.process_exception_by_middleware(e, request)
  File "/usr/local/lib/python3.7/site-packages/django/core/handlers/base.py", line 113, in _get_response
    response = wrapped_callback(request, *callback_args, **callback_kwargs)
  File "/usr/local/lib/python3.7/site-packages/django/views/decorators/csrf.py", line 54, in wrapped_view
    return view_func(*args, **kwargs)
  File "/usr/local/lib/python3.7/site-packages/rest_framework/viewsets.py", line 114, in view
    return self.dispatch(request, *args, **kwargs)
  File "/usr/local/lib/python3.7/site-packages/rest_framework/views.py", line 505, in dispatch
    response = self.handle_exception(exc)
  File "/usr/local/lib/python3.7/site-packages/rest_framework/views.py", line 465, in handle_exception
    self.raise_uncaught_exception(exc)
  File "/usr/local/lib/python3.7/site-packages/rest_framework/views.py", line 476, in raise_uncaught_exception
    raise exc
  File "/usr/local/lib/python3.7/site-packages/rest_framework/views.py", line 502, in dispatch
    response = handler(request, *args, **kwargs)
  File "/usr/local/lib/python3.7/site-packages/rest_framework/mixins.py", line 19, in create
    self.perform_create(serializer)
  File "/usr/local/lib/python3.7/site-packages/rest_framework/mixins.py", line 24, in perform_create
    serializer.save()
  File "/usr/local/lib/python3.7/site-packages/rest_framework/serializers.py", line 213, in save
    self.instance = self.create(validated_data)
  File "/usr/local/lib/python3.7/site-packages/rest_framework/serializers.py", line 932, in create
    instance = ModelClass._default_manager.create(**validated_data)
  File "/usr/local/lib/python3.7/site-packages/django/db/models/manager.py", line 82, in manager_method
    return getattr(self.get_queryset(), name)(*args, **kwargs)
  File "/usr/local/lib/python3.7/site-packages/django/db/models/query.py", line 433, in create
    obj.save(force_insert=True, using=self.db)
  File "/usr/local/lib/python3.7/site-packages/django/db/models/base.py", line 746, in save
    force_update=force_update, update_fields=update_fields)
  File "/usr/local/lib/python3.7/site-packages/django/db/models/base.py", line 784, in save_base
    force_update, using, update_fields,
  File "/usr/local/lib/python3.7/site-packages/django/db/models/base.py", line 887, in _save_table
    results = self._do_insert(cls._base_manager, using, fields, returning_fields, raw)
  File "/usr/local/lib/python3.7/site-packages/django/db/models/base.py", line 926, in _do_insert
    using=using, raw=raw,
  File "/usr/local/lib/python3.7/site-packages/django/db/models/manager.py", line 82, in manager_method
    return getattr(self.get_queryset(), name)(*args, **kwargs)
  File "/usr/local/lib/python3.7/site-packages/django/db/models/query.py", line 1204, in _insert
    return query.get_compiler(using=using).execute_sql(returning_fields)
  File "/usr/local/lib/python3.7/site-packages/django/db/models/sql/compiler.py", line 1391, in execute_sql
    cursor.execute(sql, params)
  File "/usr/local/lib/python3.7/site-packages/django/db/backends/utils.py", line 100, in execute
    return super().execute(sql, params)
  File "/usr/local/lib/python3.7/site-packages/django/db/backends/utils.py", line 68, in execute
    return self._execute_with_wrappers(sql, params, many=False, executor=self._execute)
  File "/usr/local/lib/python3.7/site-packages/django/db/backends/utils.py", line 77, in _execute_with_wrappers
    return executor(sql, params, many, context)
  File "/usr/local/lib/python3.7/site-packages/django/db/backends/utils.py", line 86, in _execute
    return self.cursor.execute(sql, params)
  File "/usr/local/lib/python3.7/site-packages/django/db/utils.py", line 90, in __exit__
    raise dj_exc_value.with_traceback(traceback) from exc_value
  File "/usr/local/lib/python3.7/site-packages/django/db/backends/utils.py", line 86, in _execute
    return self.cursor.execute(sql, params)
django.db.utils.IntegrityError: null value in column "packs_id" violates not-null constraint
DETAIL:  Failing row contains (3, 2020-12-03, null, null).

[ERROR][2020-12-03 06:37:02,239][log.py:228]Internal Server Error: /api/product_to_pack/
Traceback (most recent call last):
  File "/usr/local/lib/python3.7/site-packages/django/db/backends/utils.py", line 86, in _execute
    return self.cursor.execute(sql, params)
psycopg2.errors.NotNullViolation: null value in column "packs_id" violates not-null constraint
DETAIL:  Failing row contains (4, 2020-12-03, null, null).


The above exception was the direct cause of the following exception:

Traceback (most recent call last):
  File "/usr/local/lib/python3.7/site-packages/django/core/handlers/exception.py", line 34, in inner
    response = get_response(request)
  File "/usr/local/lib/python3.7/site-packages/django/core/handlers/base.py", line 115, in _get_response
    response = self.process_exception_by_middleware(e, request)
  File "/usr/local/lib/python3.7/site-packages/django/core/handlers/base.py", line 113, in _get_response
    response = wrapped_callback(request, *callback_args, **callback_kwargs)
  File "/usr/local/lib/python3.7/site-packages/django/views/decorators/csrf.py", line 54, in wrapped_view
    return view_func(*args, **kwargs)
  File "/usr/local/lib/python3.7/site-packages/rest_framework/viewsets.py", line 114, in view
    return self.dispatch(request, *args, **kwargs)
  File "/usr/local/lib/python3.7/site-packages/rest_framework/views.py", line 505, in dispatch
    response = self.handle_exception(exc)
  File "/usr/local/lib/python3.7/site-packages/rest_framework/views.py", line 465, in handle_exception
    self.raise_uncaught_exception(exc)
  File "/usr/local/lib/python3.7/site-packages/rest_framework/views.py", line 476, in raise_uncaught_exception
    raise exc
  File "/usr/local/lib/python3.7/site-packages/rest_framework/views.py", line 502, in dispatch
    response = handler(request, *args, **kwargs)
  File "/usr/local/lib/python3.7/site-packages/rest_framework/mixins.py", line 19, in create
    self.perform_create(serializer)
  File "/usr/local/lib/python3.7/site-packages/rest_framework/mixins.py", line 24, in perform_create
    serializer.save()
  File "/usr/local/lib/python3.7/site-packages/rest_framework/serializers.py", line 213, in save
    self.instance = self.create(validated_data)
  File "/usr/local/lib/python3.7/site-packages/rest_framework/serializers.py", line 932, in create
    instance = ModelClass._default_manager.create(**validated_data)
  File "/usr/local/lib/python3.7/site-packages/django/db/models/manager.py", line 82, in manager_method
    return getattr(self.get_queryset(), name)(*args, **kwargs)
  File "/usr/local/lib/python3.7/site-packages/django/db/models/query.py", line 433, in create
    obj.save(force_insert=True, using=self.db)
  File "/usr/local/lib/python3.7/site-packages/django/db/models/base.py", line 746, in save
    force_update=force_update, update_fields=update_fields)
  File "/usr/local/lib/python3.7/site-packages/django/db/models/base.py", line 784, in save_base
    force_update, using, update_fields,
  File "/usr/local/lib/python3.7/site-packages/django/db/models/base.py", line 887, in _save_table
    results = self._do_insert(cls._base_manager, using, fields, returning_fields, raw)
  File "/usr/local/lib/python3.7/site-packages/django/db/models/base.py", line 926, in _do_insert
    using=using, raw=raw,
  File "/usr/local/lib/python3.7/site-packages/django/db/models/manager.py", line 82, in manager_method
    return getattr(self.get_queryset(), name)(*args, **kwargs)
  File "/usr/local/lib/python3.7/site-packages/django/db/models/query.py", line 1204, in _insert
    return query.get_compiler(using=using).execute_sql(returning_fields)
  File "/usr/local/lib/python3.7/site-packages/django/db/models/sql/compiler.py", line 1391, in execute_sql
    cursor.execute(sql, params)
  File "/usr/local/lib/python3.7/site-packages/django/db/backends/utils.py", line 100, in execute
    return super().execute(sql, params)
  File "/usr/local/lib/python3.7/site-packages/django/db/backends/utils.py", line 68, in execute
    return self._execute_with_wrappers(sql, params, many=False, executor=self._execute)
  File "/usr/local/lib/python3.7/site-packages/django/db/backends/utils.py", line 77, in _execute_with_wrappers
    return executor(sql, params, many, context)
  File "/usr/local/lib/python3.7/site-packages/django/db/backends/utils.py", line 86, in _execute
    return self.cursor.execute(sql, params)
  File "/usr/local/lib/python3.7/site-packages/django/db/utils.py", line 90, in __exit__
    raise dj_exc_value.with_traceback(traceback) from exc_value
  File "/usr/local/lib/python3.7/site-packages/django/db/backends/utils.py", line 86, in _execute
    return self.cursor.execute(sql, params)
django.db.utils.IntegrityError: null value in column "packs_id" violates not-null constraint
DETAIL:  Failing row contains (4, 2020-12-03, null, null).

[ERROR][2020-12-03 13:17:25,424][log.py:228]Internal Server Error: /api/products/
Traceback (most recent call last):
  File "/usr/local/lib/python3.7/site-packages/django/db/backends/utils.py", line 86, in _execute
    return self.cursor.execute(sql, params)
psycopg2.errors.UndefinedColumn: column upload_image.is_cover does not exist
LINE 1: ...pload_image"."is_edit", "upload_image"."is_used", "upload_im...
                                                             ^
HINT:  Perhaps you meant to reference the column "upload_image.is_home".


The above exception was the direct cause of the following exception:

Traceback (most recent call last):
  File "/usr/local/lib/python3.7/site-packages/django/core/handlers/exception.py", line 34, in inner
    response = get_response(request)
  File "/usr/local/lib/python3.7/site-packages/django/core/handlers/base.py", line 115, in _get_response
    response = self.process_exception_by_middleware(e, request)
  File "/usr/local/lib/python3.7/site-packages/django/core/handlers/base.py", line 113, in _get_response
    response = wrapped_callback(request, *callback_args, **callback_kwargs)
  File "/usr/local/lib/python3.7/site-packages/django/views/decorators/csrf.py", line 54, in wrapped_view
    return view_func(*args, **kwargs)
  File "/usr/local/lib/python3.7/site-packages/rest_framework/viewsets.py", line 114, in view
    return self.dispatch(request, *args, **kwargs)
  File "/usr/local/lib/python3.7/site-packages/rest_framework/views.py", line 505, in dispatch
    response = self.handle_exception(exc)
  File "/usr/local/lib/python3.7/site-packages/rest_framework/views.py", line 465, in handle_exception
    self.raise_uncaught_exception(exc)
  File "/usr/local/lib/python3.7/site-packages/rest_framework/views.py", line 476, in raise_uncaught_exception
    raise exc
  File "/usr/local/lib/python3.7/site-packages/rest_framework/views.py", line 502, in dispatch
    response = handler(request, *args, **kwargs)
  File "/usr/local/lib/python3.7/site-packages/rest_framework/mixins.py", line 43, in list
    return self.get_paginated_response(serializer.data)
  File "/usr/local/lib/python3.7/site-packages/rest_framework/serializers.py", line 757, in data
    ret = super().data
  File "/usr/local/lib/python3.7/site-packages/rest_framework/serializers.py", line 261, in data
    self._data = self.to_representation(self.instance)
  File "/usr/local/lib/python3.7/site-packages/rest_framework/serializers.py", line 675, in to_representation
    self.child.to_representation(item) for item in iterable
  File "/usr/local/lib/python3.7/site-packages/rest_framework/serializers.py", line 675, in <listcomp>
    self.child.to_representation(item) for item in iterable
  File "/usr/local/lib/python3.7/site-packages/rest_framework/serializers.py", line 526, in to_representation
    ret[field.field_name] = field.to_representation(attribute)
  File "/usr/local/lib/python3.7/site-packages/rest_framework/relations.py", line 535, in to_representation
    for value in iterable
  File "/usr/local/lib/python3.7/site-packages/django/db/models/query.py", line 276, in __iter__
    self._fetch_all()
  File "/usr/local/lib/python3.7/site-packages/django/db/models/query.py", line 1261, in _fetch_all
    self._result_cache = list(self._iterable_class(self))
  File "/usr/local/lib/python3.7/site-packages/django/db/models/query.py", line 57, in __iter__
    results = compiler.execute_sql(chunked_fetch=self.chunked_fetch, chunk_size=self.chunk_size)
  File "/usr/local/lib/python3.7/site-packages/django/db/models/sql/compiler.py", line 1151, in execute_sql
    cursor.execute(sql, params)
  File "/usr/local/lib/python3.7/site-packages/django/db/backends/utils.py", line 100, in execute
    return super().execute(sql, params)
  File "/usr/local/lib/python3.7/site-packages/django/db/backends/utils.py", line 68, in execute
    return self._execute_with_wrappers(sql, params, many=False, executor=self._execute)
  File "/usr/local/lib/python3.7/site-packages/django/db/backends/utils.py", line 77, in _execute_with_wrappers
    return executor(sql, params, many, context)
  File "/usr/local/lib/python3.7/site-packages/django/db/backends/utils.py", line 86, in _execute
    return self.cursor.execute(sql, params)
  File "/usr/local/lib/python3.7/site-packages/django/db/utils.py", line 90, in __exit__
    raise dj_exc_value.with_traceback(traceback) from exc_value
  File "/usr/local/lib/python3.7/site-packages/django/db/backends/utils.py", line 86, in _execute
    return self.cursor.execute(sql, params)
django.db.utils.ProgrammingError: column upload_image.is_cover does not exist
LINE 1: ...pload_image"."is_edit", "upload_image"."is_used", "upload_im...
                                                             ^
HINT:  Perhaps you meant to reference the column "upload_image.is_home".

[ERROR][2020-12-03 13:29:06,619][log.py:228]Internal Server Error: /api/upload/
Traceback (most recent call last):
  File "/usr/local/lib/python3.7/site-packages/django/utils/datastructures.py", line 76, in __getitem__
    list_ = super().__getitem__(key)
KeyError: 'image_alt'

During handling of the above exception, another exception occurred:

Traceback (most recent call last):
  File "/usr/local/lib/python3.7/site-packages/django/core/handlers/exception.py", line 34, in inner
    response = get_response(request)
  File "/usr/local/lib/python3.7/site-packages/django/core/handlers/base.py", line 115, in _get_response
    response = self.process_exception_by_middleware(e, request)
  File "/usr/local/lib/python3.7/site-packages/django/core/handlers/base.py", line 113, in _get_response
    response = wrapped_callback(request, *callback_args, **callback_kwargs)
  File "/usr/local/lib/python3.7/site-packages/django/views/decorators/csrf.py", line 54, in wrapped_view
    return view_func(*args, **kwargs)
  File "/usr/local/lib/python3.7/site-packages/rest_framework/viewsets.py", line 114, in view
    return self.dispatch(request, *args, **kwargs)
  File "/usr/local/lib/python3.7/site-packages/rest_framework/views.py", line 505, in dispatch
    response = self.handle_exception(exc)
  File "/usr/local/lib/python3.7/site-packages/rest_framework/views.py", line 465, in handle_exception
    self.raise_uncaught_exception(exc)
  File "/usr/local/lib/python3.7/site-packages/rest_framework/views.py", line 476, in raise_uncaught_exception
    raise exc
  File "/usr/local/lib/python3.7/site-packages/rest_framework/views.py", line 502, in dispatch
    response = handler(request, *args, **kwargs)
  File "/usr/src/api/upload/views.py", line 95, in create
    upload_img.image_alt = request.data['image_alt']
  File "/usr/local/lib/python3.7/site-packages/django/utils/datastructures.py", line 78, in __getitem__
    raise MultiValueDictKeyError(key)
django.utils.datastructures.MultiValueDictKeyError: 'image_alt'
[ERROR][2020-12-03 13:46:49,287][log.py:228]Internal Server Error: /api/product_to_pack/
Traceback (most recent call last):
  File "/usr/local/lib/python3.7/site-packages/django/core/handlers/exception.py", line 34, in inner
    response = get_response(request)
  File "/usr/local/lib/python3.7/site-packages/django/core/handlers/base.py", line 115, in _get_response
    response = self.process_exception_by_middleware(e, request)
  File "/usr/local/lib/python3.7/site-packages/django/core/handlers/base.py", line 113, in _get_response
    response = wrapped_callback(request, *callback_args, **callback_kwargs)
  File "/usr/local/lib/python3.7/site-packages/django/views/decorators/csrf.py", line 54, in wrapped_view
    return view_func(*args, **kwargs)
  File "/usr/local/lib/python3.7/site-packages/rest_framework/viewsets.py", line 114, in view
    return self.dispatch(request, *args, **kwargs)
  File "/usr/local/lib/python3.7/site-packages/rest_framework/views.py", line 507, in dispatch
    self.response = self.finalize_response(request, response, *args, **kwargs)
  File "/usr/local/lib/python3.7/site-packages/rest_framework/views.py", line 422, in finalize_response
    % type(response)
AssertionError: Expected a `Response`, `HttpResponse` or `HttpStreamingResponse` to be returned from the view, but received a `<class 'NoneType'>`
[ERROR][2020-12-03 13:49:44,177][log.py:228]Internal Server Error: /api/product_to_pack/
Traceback (most recent call last):
  File "/usr/local/lib/python3.7/site-packages/django/core/handlers/exception.py", line 34, in inner
    response = get_response(request)
  File "/usr/local/lib/python3.7/site-packages/django/core/handlers/base.py", line 115, in _get_response
    response = self.process_exception_by_middleware(e, request)
  File "/usr/local/lib/python3.7/site-packages/django/core/handlers/base.py", line 113, in _get_response
    response = wrapped_callback(request, *callback_args, **callback_kwargs)
  File "/usr/local/lib/python3.7/site-packages/django/views/decorators/csrf.py", line 54, in wrapped_view
    return view_func(*args, **kwargs)
  File "/usr/local/lib/python3.7/site-packages/rest_framework/viewsets.py", line 114, in view
    return self.dispatch(request, *args, **kwargs)
  File "/usr/local/lib/python3.7/site-packages/rest_framework/views.py", line 505, in dispatch
    response = self.handle_exception(exc)
  File "/usr/local/lib/python3.7/site-packages/rest_framework/views.py", line 465, in handle_exception
    self.raise_uncaught_exception(exc)
  File "/usr/local/lib/python3.7/site-packages/rest_framework/views.py", line 476, in raise_uncaught_exception
    raise exc
  File "/usr/local/lib/python3.7/site-packages/rest_framework/views.py", line 502, in dispatch
    response = handler(request, *args, **kwargs)
  File "/usr/src/api/webapi/views.py", line 226, in list
    print(kwargs['product_id'])
KeyError: 'product_id'
