[2020-09-16 05:13:15,820][MainThread:140172061588808][task_id:django.utils.autoreload][autoreload.py:598][INFO][Watching for file changes with StatReloader]
[2020-09-16 08:39:12,255][MainThread:140500864671048][task_id:django.utils.autoreload][autoreload.py:598][INFO][Watching for file changes with StatReloader]
[2020-09-16 08:41:39,185][MainThread:140500864671048][task_id:django.utils.autoreload][autoreload.py:222][INFO][/usr/src/api/api/models.py changed, reloading.]
[2020-09-16 08:41:40,271][MainThread:140301931605320][task_id:django.utils.autoreload][autoreload.py:598][INFO][Watching for file changes with StatReloader]
[2020-09-16 08:43:48,245][MainThread:140301931605320][task_id:django.utils.autoreload][autoreload.py:222][INFO][/usr/src/api/webapi/views.py changed, reloading.]
[2020-09-16 08:43:49,191][MainThread:140702795926856][task_id:django.utils.autoreload][autoreload.py:598][INFO][Watching for file changes with StatReloader]
[2020-09-16 08:43:56,892][MainThread:140702795926856][task_id:django.utils.autoreload][autoreload.py:222][INFO][/usr/src/api/webapi/views.py changed, reloading.]
[2020-09-16 08:43:57,777][MainThread:139904859290952][task_id:django.utils.autoreload][autoreload.py:598][INFO][Watching for file changes with StatReloader]
[2020-09-16 08:44:01,712][MainThread:139904859290952][task_id:django.utils.autoreload][autoreload.py:222][INFO][/usr/src/api/webapi/views.py changed, reloading.]
[2020-09-16 08:44:02,666][MainThread:139759475535176][task_id:django.utils.autoreload][autoreload.py:598][INFO][Watching for file changes with StatReloader]
[2020-09-16 15:11:16,447][MainThread:139759475535176][task_id:django.utils.autoreload][autoreload.py:222][INFO][/usr/src/api/api/models.py changed, reloading.]
[2020-09-16 15:11:17,484][MainThread:140031417757000][task_id:django.utils.autoreload][autoreload.py:598][INFO][Watching for file changes with StatReloader]
[2020-09-16 15:12:36,213][MainThread:140031417757000][task_id:django.utils.autoreload][autoreload.py:222][INFO][/usr/src/api/api/models.py changed, reloading.]
[2020-09-16 15:12:37,127][MainThread:140680710892872][task_id:django.utils.autoreload][autoreload.py:598][INFO][Watching for file changes with StatReloader]
[2020-09-16 16:35:09,114][Thread-1:140680664472352][task_id:django.request][log.py:228][WARNING][Not Found: /api/staffs/null/]
[2020-09-16 16:55:47,212][MainThread:140680710892872][task_id:django.utils.autoreload][autoreload.py:222][INFO][/usr/src/api/upload/views.py changed, reloading.]
[2020-09-16 16:55:48,190][MainThread:140090667384136][task_id:django.utils.autoreload][autoreload.py:598][INFO][Watching for file changes with StatReloader]
[2020-09-16 16:59:22,291][MainThread:140090667384136][task_id:django.utils.autoreload][autoreload.py:222][INFO][/usr/src/api/upload/views.py changed, reloading.]
[2020-09-16 16:59:23,242][MainThread:140135475916104][task_id:django.utils.autoreload][autoreload.py:598][INFO][Watching for file changes with StatReloader]
[2020-09-16 17:03:17,108][MainThread:140135475916104][task_id:django.utils.autoreload][autoreload.py:222][INFO][/usr/src/api/upload/views.py changed, reloading.]
[2020-09-16 17:03:18,083][MainThread:139861477997896][task_id:django.utils.autoreload][autoreload.py:598][INFO][Watching for file changes with StatReloader]
[2020-09-16 17:07:46,469][MainThread:139861477997896][task_id:django.utils.autoreload][autoreload.py:222][INFO][/usr/src/api/upload/views.py changed, reloading.]
[2020-09-16 17:07:47,325][MainThread:139995362733384][task_id:django.utils.autoreload][autoreload.py:598][INFO][Watching for file changes with StatReloader]
[2020-09-16 17:10:20,605][Thread-1:139995316402976][task_id:django.request][log.py:228][WARNING][Not Found: /api/upload/[object Object]/]
[2020-09-16 17:10:20,610][Thread-2:139995315342112][task_id:django.request][log.py:228][WARNING][Not Found: /api/upload/[object Object]/]
[2020-09-16 17:10:20,612][Thread-9:139995306343200][task_id:django.request][log.py:228][WARNING][Not Found: /api/upload/[object Object]/]
[2020-09-16 17:11:15,165][Thread-9:139995306343200][task_id:django.request][log.py:228][WARNING][Not Found: /api/upload/[object Object]/]
[2020-09-16 17:11:37,134][Thread-9:139995306343200][task_id:django.request][log.py:228][WARNING][Not Found: /api/upload/[object Object]/]
[2020-09-16 17:12:25,143][MainThread:139995362733384][task_id:django.utils.autoreload][autoreload.py:222][INFO][/usr/src/api/upload/views.py changed, reloading.]
[2020-09-16 17:12:26,056][MainThread:140486749691208][task_id:django.utils.autoreload][autoreload.py:598][INFO][Watching for file changes with StatReloader]
[2020-09-16 17:16:07,918][Thread-2:140486701947680][task_id:django.request][log.py:228][WARNING][Not Found: /api/upload/[object Object]/]
[2020-09-17 03:42:34,081][MainThread:140486749691208][task_id:django.utils.autoreload][autoreload.py:222][INFO][/usr/src/api/api/models.py changed, reloading.]
[2020-09-17 03:42:35,188][MainThread:139625070017864][task_id:django.utils.autoreload][autoreload.py:598][INFO][Watching for file changes with StatReloader]
[2020-09-17 04:49:39,254][Thread-1:139625023597344][task_id:django.request][log.py:228][WARNING][Not Found: /api/staffs/null/]
[2020-09-17 06:38:13,861][MainThread:139625070017864][task_id:django.utils.autoreload][autoreload.py:222][INFO][/usr/src/api/api/views.py changed, reloading.]
[2020-09-17 06:38:14,792][MainThread:140085265521992][task_id:django.utils.autoreload][autoreload.py:598][INFO][Watching for file changes with StatReloader]
[2020-09-17 11:53:51,794][MainThread:140085265521992][task_id:django.utils.autoreload][autoreload.py:222][INFO][/usr/src/api/api/views.py changed, reloading.]
[2020-09-17 11:53:53,078][MainThread:140713205579080][task_id:django.utils.autoreload][autoreload.py:598][INFO][Watching for file changes with StatReloader]
[2020-09-17 11:54:55,189][MainThread:140713205579080][task_id:django.utils.autoreload][autoreload.py:222][INFO][/usr/src/api/api/views.py changed, reloading.]
[2020-09-17 11:54:56,021][MainThread:140591438409032][task_id:django.utils.autoreload][autoreload.py:598][INFO][Watching for file changes with StatReloader]
[2020-09-17 11:55:54,278][MainThread:140591438409032][task_id:django.utils.autoreload][autoreload.py:222][INFO][/usr/src/api/api/views.py changed, reloading.]
[2020-09-17 11:55:55,149][MainThread:139689302441288][task_id:django.utils.autoreload][autoreload.py:598][INFO][Watching for file changes with StatReloader]
[2020-09-17 11:56:21,461][MainThread:139689302441288][task_id:django.utils.autoreload][autoreload.py:222][INFO][/usr/src/api/api/views.py changed, reloading.]
[2020-09-17 11:56:22,508][MainThread:139722942479688][task_id:django.utils.autoreload][autoreload.py:598][INFO][Watching for file changes with StatReloader]
[2020-09-17 11:56:44,808][MainThread:139722942479688][task_id:django.utils.autoreload][autoreload.py:222][INFO][/usr/src/api/api/views.py changed, reloading.]
[2020-09-17 11:56:45,651][MainThread:140421064289608][task_id:django.utils.autoreload][autoreload.py:598][INFO][Watching for file changes with StatReloader]
[2020-09-17 11:58:01,812][MainThread:140421064289608][task_id:django.utils.autoreload][autoreload.py:222][INFO][/usr/src/api/api/views.py changed, reloading.]
[2020-09-17 11:58:02,759][MainThread:140657648979272][task_id:django.utils.autoreload][autoreload.py:598][INFO][Watching for file changes with StatReloader]
[2020-09-17 12:37:47,536][Thread-6:140657602558752][task_id:django.request][log.py:228][ERROR][Internal Server Error: /api/staffs/1/]
Traceback (most recent call last):
  File "/usr/local/lib/python3.7/site-packages/django/core/handlers/exception.py", line 34, in inner
    response = get_response(request)
  File "/usr/local/lib/python3.7/site-packages/django/core/handlers/base.py", line 115, in _get_response
    response = self.process_exception_by_middleware(e, request)
  File "/usr/local/lib/python3.7/site-packages/django/core/handlers/base.py", line 113, in _get_response
    response = wrapped_callback(request, *callback_args, **callback_kwargs)
  File "/usr/local/lib/python3.7/site-packages/django/views/decorators/csrf.py", line 54, in wrapped_view
    return view_func(*args, **kwargs)
  File "/usr/local/lib/python3.7/site-packages/rest_framework/viewsets.py", line 114, in view
    return self.dispatch(request, *args, **kwargs)
  File "/usr/local/lib/python3.7/site-packages/rest_framework/views.py", line 505, in dispatch
    response = self.handle_exception(exc)
  File "/usr/local/lib/python3.7/site-packages/rest_framework/views.py", line 465, in handle_exception
    self.raise_uncaught_exception(exc)
  File "/usr/local/lib/python3.7/site-packages/rest_framework/views.py", line 476, in raise_uncaught_exception
    raise exc
  File "/usr/local/lib/python3.7/site-packages/rest_framework/views.py", line 493, in dispatch
    self.initial(request, *args, **kwargs)
  File "/usr/local/lib/python3.7/site-packages/rest_framework/views.py", line 410, in initial
    self.perform_authentication(request)
  File "/usr/local/lib/python3.7/site-packages/rest_framework/views.py", line 324, in perform_authentication
    request.user
  File "/usr/local/lib/python3.7/site-packages/rest_framework/request.py", line 220, in user
    self._authenticate()
  File "/usr/local/lib/python3.7/site-packages/rest_framework/request.py", line 373, in _authenticate
    user_auth_tuple = authenticator.authenticate(self)
  File "/usr/src/api/user/authentications.py", line 23, in authenticate
    token = request.headers['authorization']
  File "/usr/local/lib/python3.7/site-packages/django/http/request.py", line 388, in __getitem__
    return super().__getitem__(key.replace('_', '-'))
  File "/usr/local/lib/python3.7/site-packages/django/utils/datastructures.py", line 320, in __getitem__
    return self._store[key.lower()][1]
KeyError: 'authorization'
[2020-09-17 14:30:35,149][MainThread:140657648979272][task_id:django.utils.autoreload][autoreload.py:222][INFO][/usr/src/api/api/views.py changed, reloading.]
[2020-09-17 14:30:36,153][MainThread:140676022685000][task_id:django.utils.autoreload][autoreload.py:598][INFO][Watching for file changes with StatReloader]
[2020-09-17 14:32:39,146][MainThread:140676022685000][task_id:django.utils.autoreload][autoreload.py:222][INFO][/usr/src/api/api/serializer.py changed, reloading.]
[2020-09-17 14:32:40,153][MainThread:140128470359368][task_id:django.utils.autoreload][autoreload.py:598][INFO][Watching for file changes with StatReloader]
[2020-09-17 14:32:47,501][Thread-1:140128423938848][task_id:django.request][log.py:228][ERROR][Internal Server Error: /api/orders/ali202000002/]
Traceback (most recent call last):
  File "/usr/local/lib/python3.7/site-packages/django/core/handlers/exception.py", line 34, in inner
    response = get_response(request)
  File "/usr/local/lib/python3.7/site-packages/django/core/handlers/base.py", line 115, in _get_response
    response = self.process_exception_by_middleware(e, request)
  File "/usr/local/lib/python3.7/site-packages/django/core/handlers/base.py", line 113, in _get_response
    response = wrapped_callback(request, *callback_args, **callback_kwargs)
  File "/usr/local/lib/python3.7/site-packages/django/views/decorators/csrf.py", line 54, in wrapped_view
    return view_func(*args, **kwargs)
  File "/usr/local/lib/python3.7/site-packages/rest_framework/viewsets.py", line 114, in view
    return self.dispatch(request, *args, **kwargs)
  File "/usr/local/lib/python3.7/site-packages/rest_framework/views.py", line 505, in dispatch
    response = self.handle_exception(exc)
  File "/usr/local/lib/python3.7/site-packages/rest_framework/views.py", line 465, in handle_exception
    self.raise_uncaught_exception(exc)
  File "/usr/local/lib/python3.7/site-packages/rest_framework/views.py", line 476, in raise_uncaught_exception
    raise exc
  File "/usr/local/lib/python3.7/site-packages/rest_framework/views.py", line 502, in dispatch
    response = handler(request, *args, **kwargs)
  File "/usr/local/lib/python3.7/site-packages/rest_framework/mixins.py", line 82, in partial_update
    return self.update(request, *args, **kwargs)
  File "/usr/local/lib/python3.7/site-packages/rest_framework/mixins.py", line 67, in update
    serializer.is_valid(raise_exception=True)
  File "/usr/local/lib/python3.7/site-packages/rest_framework/serializers.py", line 235, in is_valid
    self._validated_data = self.run_validation(self.initial_data)
  File "/usr/local/lib/python3.7/site-packages/rest_framework/serializers.py", line 430, in run_validation
    value = self.to_internal_value(data)
  File "/usr/local/lib/python3.7/site-packages/rest_framework/serializers.py", line 483, in to_internal_value
    for field in fields:
  File "/usr/local/lib/python3.7/site-packages/rest_framework/serializers.py", line 366, in _writable_fields
    for field in self.fields.values():
  File "/usr/local/lib/python3.7/site-packages/django/utils/functional.py", line 48, in __get__
    res = instance.__dict__[self.name] = self.func(instance)
  File "/usr/local/lib/python3.7/site-packages/rest_framework/serializers.py", line 360, in fields
    for key, value in self.get_fields().items():
  File "/usr/local/lib/python3.7/site-packages/rest_framework/serializers.py", line 1022, in get_fields
    field_names = self.get_field_names(declared_fields, info)
  File "/usr/local/lib/python3.7/site-packages/rest_framework/serializers.py", line 1099, in get_field_names
    serializer_class=self.__class__.__name__
AssertionError: ("Creating a ModelSerializer without either the 'fields' attribute or the 'exclude' attribute has been deprecated since 3.3.0, and is now disallowed. Add an explicit fields = '__all__' to the OrdersSerializer serializer.",)
[2020-09-17 14:33:32,279][MainThread:140128470359368][task_id:django.utils.autoreload][autoreload.py:222][INFO][/usr/src/api/api/serializer.py changed, reloading.]
[2020-09-17 14:33:33,262][MainThread:139649463082312][task_id:django.utils.autoreload][autoreload.py:598][INFO][Watching for file changes with StatReloader]
[2020-09-18 07:12:28,579][MainThread:139649463082312][task_id:django.utils.autoreload][autoreload.py:222][INFO][/usr/src/api/api/views.py changed, reloading.]
[2020-09-18 07:12:29,631][MainThread:139740530904392][task_id:django.utils.autoreload][autoreload.py:598][INFO][Watching for file changes with StatReloader]
[2020-09-18 07:12:40,336][Thread-1:139740484573984][task_id:django.request][log.py:228][ERROR][Internal Server Error: /api/orders/]
Traceback (most recent call last):
  File "/usr/local/lib/python3.7/site-packages/django/core/handlers/exception.py", line 34, in inner
    response = get_response(request)
  File "/usr/local/lib/python3.7/site-packages/django/core/handlers/base.py", line 115, in _get_response
    response = self.process_exception_by_middleware(e, request)
  File "/usr/local/lib/python3.7/site-packages/django/core/handlers/base.py", line 113, in _get_response
    response = wrapped_callback(request, *callback_args, **callback_kwargs)
  File "/usr/local/lib/python3.7/site-packages/django/views/decorators/csrf.py", line 54, in wrapped_view
    return view_func(*args, **kwargs)
  File "/usr/local/lib/python3.7/site-packages/rest_framework/viewsets.py", line 114, in view
    return self.dispatch(request, *args, **kwargs)
  File "/usr/local/lib/python3.7/site-packages/rest_framework/views.py", line 505, in dispatch
    response = self.handle_exception(exc)
  File "/usr/local/lib/python3.7/site-packages/rest_framework/views.py", line 465, in handle_exception
    self.raise_uncaught_exception(exc)
  File "/usr/local/lib/python3.7/site-packages/rest_framework/views.py", line 476, in raise_uncaught_exception
    raise exc
  File "/usr/local/lib/python3.7/site-packages/rest_framework/views.py", line 502, in dispatch
    response = handler(request, *args, **kwargs)
  File "/usr/src/api/api/views.py", line 47, in list
    queryset = self.filter_queryset(self.get_queryset())
  File "/usr/src/api/api/views.py", line 43, in get_queryset
    self.queryset['test'] = 'test'
TypeError: 'QuerySet' object does not support item assignment
[2020-09-18 07:13:10,715][MainThread:139740530904392][task_id:django.utils.autoreload][autoreload.py:222][INFO][/usr/src/api/api/views.py changed, reloading.]
[2020-09-18 07:13:11,713][MainThread:139712794721608][task_id:django.utils.autoreload][autoreload.py:598][INFO][Watching for file changes with StatReloader]
[2020-09-18 07:13:40,546][MainThread:139712794721608][task_id:django.utils.autoreload][autoreload.py:222][INFO][/usr/src/api/api/views.py changed, reloading.]
[2020-09-18 07:13:41,616][MainThread:139998444543304][task_id:django.utils.autoreload][autoreload.py:598][INFO][Watching for file changes with StatReloader]
[2020-09-18 07:13:46,906][Thread-1:139998398122784][task_id:django.request][log.py:228][ERROR][Internal Server Error: /api/orders/]
Traceback (most recent call last):
  File "/usr/local/lib/python3.7/site-packages/django/core/handlers/exception.py", line 34, in inner
    response = get_response(request)
  File "/usr/local/lib/python3.7/site-packages/django/core/handlers/base.py", line 115, in _get_response
    response = self.process_exception_by_middleware(e, request)
  File "/usr/local/lib/python3.7/site-packages/django/core/handlers/base.py", line 113, in _get_response
    response = wrapped_callback(request, *callback_args, **callback_kwargs)
  File "/usr/local/lib/python3.7/site-packages/django/views/decorators/csrf.py", line 54, in wrapped_view
    return view_func(*args, **kwargs)
  File "/usr/local/lib/python3.7/site-packages/rest_framework/viewsets.py", line 114, in view
    return self.dispatch(request, *args, **kwargs)
  File "/usr/local/lib/python3.7/site-packages/rest_framework/views.py", line 505, in dispatch
    response = self.handle_exception(exc)
  File "/usr/local/lib/python3.7/site-packages/rest_framework/views.py", line 465, in handle_exception
    self.raise_uncaught_exception(exc)
  File "/usr/local/lib/python3.7/site-packages/rest_framework/views.py", line 476, in raise_uncaught_exception
    raise exc
  File "/usr/local/lib/python3.7/site-packages/rest_framework/views.py", line 502, in dispatch
    response = handler(request, *args, **kwargs)
  File "/usr/src/api/api/views.py", line 60, in list
    serializer.data['test'] = 'test'
TypeError: list indices must be integers or slices, not str
[2020-09-18 07:14:15,453][MainThread:139998444543304][task_id:django.utils.autoreload][autoreload.py:222][INFO][/usr/src/api/api/views.py changed, reloading.]
[2020-09-18 07:14:16,335][MainThread:139994472090952][task_id:django.utils.autoreload][autoreload.py:598][INFO][Watching for file changes with StatReloader]
[2020-09-18 07:14:46,669][MainThread:139994472090952][task_id:django.utils.autoreload][autoreload.py:222][INFO][/usr/src/api/api/views.py changed, reloading.]
[2020-09-18 07:14:47,730][MainThread:139628341214536][task_id:django.utils.autoreload][autoreload.py:598][INFO][Watching for file changes with StatReloader]
[2020-09-18 07:15:53,420][MainThread:139628341214536][task_id:django.utils.autoreload][autoreload.py:222][INFO][/usr/src/api/api/serializer.py changed, reloading.]
[2020-09-18 07:15:54,372][MainThread:140428134022472][task_id:django.utils.autoreload][autoreload.py:598][INFO][Watching for file changes with StatReloader]
[2020-09-18 07:16:00,012][Thread-1:140428087601952][task_id:django.request][log.py:228][ERROR][Internal Server Error: /api/orders/]
Traceback (most recent call last):
  File "/usr/local/lib/python3.7/site-packages/django/core/handlers/exception.py", line 34, in inner
    response = get_response(request)
  File "/usr/local/lib/python3.7/site-packages/django/core/handlers/base.py", line 115, in _get_response
    response = self.process_exception_by_middleware(e, request)
  File "/usr/local/lib/python3.7/site-packages/django/core/handlers/base.py", line 113, in _get_response
    response = wrapped_callback(request, *callback_args, **callback_kwargs)
  File "/usr/local/lib/python3.7/site-packages/django/views/decorators/csrf.py", line 54, in wrapped_view
    return view_func(*args, **kwargs)
  File "/usr/local/lib/python3.7/site-packages/rest_framework/viewsets.py", line 114, in view
    return self.dispatch(request, *args, **kwargs)
  File "/usr/local/lib/python3.7/site-packages/rest_framework/views.py", line 505, in dispatch
    response = self.handle_exception(exc)
  File "/usr/local/lib/python3.7/site-packages/rest_framework/views.py", line 465, in handle_exception
    self.raise_uncaught_exception(exc)
  File "/usr/local/lib/python3.7/site-packages/rest_framework/views.py", line 476, in raise_uncaught_exception
    raise exc
  File "/usr/local/lib/python3.7/site-packages/rest_framework/views.py", line 502, in dispatch
    response = handler(request, *args, **kwargs)
  File "/usr/src/api/api/views.py", line 60, in list
    return self.get_paginated_response(serializer.data)
  File "/usr/local/lib/python3.7/site-packages/rest_framework/serializers.py", line 757, in data
    ret = super().data
  File "/usr/local/lib/python3.7/site-packages/rest_framework/serializers.py", line 261, in data
    self._data = self.to_representation(self.instance)
  File "/usr/local/lib/python3.7/site-packages/rest_framework/serializers.py", line 675, in to_representation
    self.child.to_representation(item) for item in iterable
  File "/usr/local/lib/python3.7/site-packages/rest_framework/serializers.py", line 675, in <listcomp>
    self.child.to_representation(item) for item in iterable
  File "/usr/local/lib/python3.7/site-packages/rest_framework/serializers.py", line 513, in to_representation
    attribute = field.get_attribute(instance)
  File "/usr/local/lib/python3.7/site-packages/rest_framework/relations.py", line 529, in get_attribute
    relationship = get_attribute(instance, self.source_attrs)
  File "/usr/local/lib/python3.7/site-packages/rest_framework/fields.py", line 93, in get_attribute
    instance = getattr(instance, attr)
AttributeError: 'OrderCatalog' object has no attribute 'sub_order'
[2020-09-18 07:17:12,744][MainThread:140428134022472][task_id:django.utils.autoreload][autoreload.py:222][INFO][/usr/src/api/api/serializer.py changed, reloading.]
[2020-09-18 07:17:13,761][MainThread:140223043214664][task_id:django.utils.autoreload][autoreload.py:598][INFO][Watching for file changes with StatReloader]
[2020-09-18 07:17:19,243][Thread-1:140222996794144][task_id:django.request][log.py:228][ERROR][Internal Server Error: /api/orders/]
Traceback (most recent call last):
  File "/usr/local/lib/python3.7/site-packages/django/core/handlers/exception.py", line 34, in inner
    response = get_response(request)
  File "/usr/local/lib/python3.7/site-packages/django/core/handlers/base.py", line 115, in _get_response
    response = self.process_exception_by_middleware(e, request)
  File "/usr/local/lib/python3.7/site-packages/django/core/handlers/base.py", line 113, in _get_response
    response = wrapped_callback(request, *callback_args, **callback_kwargs)
  File "/usr/local/lib/python3.7/site-packages/django/views/decorators/csrf.py", line 54, in wrapped_view
    return view_func(*args, **kwargs)
  File "/usr/local/lib/python3.7/site-packages/rest_framework/viewsets.py", line 114, in view
    return self.dispatch(request, *args, **kwargs)
  File "/usr/local/lib/python3.7/site-packages/rest_framework/views.py", line 505, in dispatch
    response = self.handle_exception(exc)
  File "/usr/local/lib/python3.7/site-packages/rest_framework/views.py", line 465, in handle_exception
    self.raise_uncaught_exception(exc)
  File "/usr/local/lib/python3.7/site-packages/rest_framework/views.py", line 476, in raise_uncaught_exception
    raise exc
  File "/usr/local/lib/python3.7/site-packages/rest_framework/views.py", line 502, in dispatch
    response = handler(request, *args, **kwargs)
  File "/usr/src/api/api/views.py", line 60, in list
    return self.get_paginated_response(serializer.data)
  File "/usr/local/lib/python3.7/site-packages/rest_framework/serializers.py", line 757, in data
    ret = super().data
  File "/usr/local/lib/python3.7/site-packages/rest_framework/serializers.py", line 261, in data
    self._data = self.to_representation(self.instance)
  File "/usr/local/lib/python3.7/site-packages/rest_framework/serializers.py", line 675, in to_representation
    self.child.to_representation(item) for item in iterable
  File "/usr/local/lib/python3.7/site-packages/rest_framework/serializers.py", line 675, in <listcomp>
    self.child.to_representation(item) for item in iterable
  File "/usr/local/lib/python3.7/site-packages/rest_framework/serializers.py", line 526, in to_representation
    ret[field.field_name] = field.to_representation(attribute)
  File "/usr/local/lib/python3.7/site-packages/rest_framework/relations.py", line 535, in to_representation
    for value in iterable
  File "/usr/local/lib/python3.7/site-packages/rest_framework/relations.py", line 535, in <listcomp>
    for value in iterable
  File "/usr/local/lib/python3.7/site-packages/rest_framework/relations.py", line 460, in to_representation
    return getattr(obj, self.slug_field)
TypeError: getattr(): attribute name must be string
[2020-09-18 07:17:57,243][MainThread:140223043214664][task_id:django.utils.autoreload][autoreload.py:222][INFO][/usr/src/api/api/serializer.py changed, reloading.]
[2020-09-18 07:17:58,247][MainThread:139692777229640][task_id:django.utils.autoreload][autoreload.py:598][INFO][Watching for file changes with StatReloader]
[2020-09-18 07:21:17,966][MainThread:139692777229640][task_id:django.utils.autoreload][autoreload.py:222][INFO][/usr/src/api/api/serializer.py changed, reloading.]
[2020-09-18 07:21:18,857][MainThread:139904778022216][task_id:django.utils.autoreload][autoreload.py:598][INFO][Watching for file changes with StatReloader]
[2020-09-18 07:22:54,919][MainThread:140040365063496][task_id:django.utils.autoreload][autoreload.py:598][INFO][Watching for file changes with StatReloader]
[2020-09-18 07:25:48,746][MainThread:140693597224264][task_id:django.utils.autoreload][autoreload.py:598][INFO][Watching for file changes with StatReloader]
[2020-09-18 08:07:24,079][MainThread:140693597224264][task_id:django.utils.autoreload][autoreload.py:222][INFO][/usr/src/api/api/models.py changed, reloading.]
[2020-09-18 08:07:25,046][MainThread:140712913562952][task_id:django.utils.autoreload][autoreload.py:598][INFO][Watching for file changes with StatReloader]
[2020-09-18 08:18:05,919][MainThread:140712913562952][task_id:django.utils.autoreload][autoreload.py:222][INFO][/usr/src/api/api/models.py changed, reloading.]
[2020-09-18 08:18:06,981][MainThread:140217382083912][task_id:django.utils.autoreload][autoreload.py:598][INFO][Watching for file changes with StatReloader]
[2020-09-18 08:18:20,668][MainThread:140217382083912][task_id:django.utils.autoreload][autoreload.py:222][INFO][/usr/src/api/api/models.py changed, reloading.]
[2020-09-18 08:18:21,668][MainThread:140559496940872][task_id:django.utils.autoreload][autoreload.py:598][INFO][Watching for file changes with StatReloader]
[2020-09-18 14:48:06,268][MainThread:140559496940872][task_id:django.utils.autoreload][autoreload.py:222][INFO][/usr/src/api/api/serializer.py changed, reloading.]
[2020-09-18 14:48:07,609][MainThread:140006368349512][task_id:django.utils.autoreload][autoreload.py:598][INFO][Watching for file changes with StatReloader]
[2020-09-18 14:50:49,405][MainThread:140006368349512][task_id:django.utils.autoreload][autoreload.py:222][INFO][/usr/src/api/api/views.py changed, reloading.]
[2020-09-18 14:50:50,799][MainThread:139827007470920][task_id:django.utils.autoreload][autoreload.py:598][INFO][Watching for file changes with StatReloader]
[2020-09-18 14:52:06,443][MainThread:139827007470920][task_id:django.utils.autoreload][autoreload.py:222][INFO][/usr/src/api/vuebackend/urls.py changed, reloading.]
[2020-09-18 14:52:08,028][MainThread:140027952348488][task_id:django.utils.autoreload][autoreload.py:598][INFO][Watching for file changes with StatReloader]
[2020-09-18 14:53:03,067][MainThread:140027952348488][task_id:django.utils.autoreload][autoreload.py:222][INFO][/usr/src/api/api/views.py changed, reloading.]
[2020-09-18 14:53:04,233][MainThread:140640944758088][task_id:django.utils.autoreload][autoreload.py:598][INFO][Watching for file changes with StatReloader]
[2020-09-18 17:59:12,578][MainThread:140640944758088][task_id:django.utils.autoreload][autoreload.py:222][INFO][/usr/src/api/api/models.py changed, reloading.]
[2020-09-18 17:59:13,564][MainThread:139743670287688][task_id:django.utils.autoreload][autoreload.py:598][INFO][Watching for file changes with StatReloader]
[2020-09-18 17:59:46,281][Thread-1:139743623605024][task_id:django.request][log.py:228][ERROR][Internal Server Error: /api/customer_addr/]
Traceback (most recent call last):
  File "/usr/local/lib/python3.7/site-packages/django/core/handlers/exception.py", line 34, in inner
    response = get_response(request)
  File "/usr/local/lib/python3.7/site-packages/django/core/handlers/base.py", line 115, in _get_response
    response = self.process_exception_by_middleware(e, request)
  File "/usr/local/lib/python3.7/site-packages/django/core/handlers/base.py", line 113, in _get_response
    response = wrapped_callback(request, *callback_args, **callback_kwargs)
  File "/usr/local/lib/python3.7/site-packages/django/views/decorators/csrf.py", line 54, in wrapped_view
    return view_func(*args, **kwargs)
  File "/usr/local/lib/python3.7/site-packages/rest_framework/viewsets.py", line 114, in view
    return self.dispatch(request, *args, **kwargs)
  File "/usr/local/lib/python3.7/site-packages/rest_framework/views.py", line 505, in dispatch
    response = self.handle_exception(exc)
  File "/usr/local/lib/python3.7/site-packages/rest_framework/views.py", line 465, in handle_exception
    self.raise_uncaught_exception(exc)
  File "/usr/local/lib/python3.7/site-packages/rest_framework/views.py", line 476, in raise_uncaught_exception
    raise exc
  File "/usr/local/lib/python3.7/site-packages/rest_framework/views.py", line 502, in dispatch
    response = handler(request, *args, **kwargs)
  File "/usr/local/lib/python3.7/site-packages/rest_framework/mixins.py", line 43, in list
    return self.get_paginated_response(serializer.data)
  File "/usr/local/lib/python3.7/site-packages/rest_framework/serializers.py", line 757, in data
    ret = super().data
  File "/usr/local/lib/python3.7/site-packages/rest_framework/serializers.py", line 261, in data
    self._data = self.to_representation(self.instance)
  File "/usr/local/lib/python3.7/site-packages/rest_framework/serializers.py", line 675, in to_representation
    self.child.to_representation(item) for item in iterable
  File "/usr/local/lib/python3.7/site-packages/rest_framework/serializers.py", line 675, in <listcomp>
    self.child.to_representation(item) for item in iterable
  File "/usr/local/lib/python3.7/site-packages/rest_framework/serializers.py", line 526, in to_representation
    ret[field.field_name] = field.to_representation(attribute)
  File "/usr/local/lib/python3.7/site-packages/rest_framework/fields.py", line 1289, in to_representation
    'Expected a `date`, but got a `datetime`. Refusing to coerce, '
AssertionError: Expected a `date`, but got a `datetime`. Refusing to coerce, as this may mean losing timezone information. Use a custom read-only field and deal with timezone issues explicitly.
[2020-09-18 18:00:41,220][MainThread:140220617583944][task_id:django.utils.autoreload][autoreload.py:598][INFO][Watching for file changes with StatReloader]
[2020-09-18 20:08:42,602][MainThread:140220617583944][task_id:django.utils.autoreload][autoreload.py:222][INFO][/usr/src/api/api/models.py changed, reloading.]
[2020-09-18 20:08:43,679][MainThread:139769586736456][task_id:django.utils.autoreload][autoreload.py:598][INFO][Watching for file changes with StatReloader]
[2020-09-18 20:08:52,334][MainThread:139769586736456][task_id:django.utils.autoreload][autoreload.py:222][INFO][/usr/src/api/api/models.py changed, reloading.]
[2020-09-18 20:08:53,209][MainThread:139889476042056][task_id:django.utils.autoreload][autoreload.py:598][INFO][Watching for file changes with StatReloader]
[2020-09-18 20:10:40,333][MainThread:139889476042056][task_id:django.utils.autoreload][autoreload.py:222][INFO][/usr/src/api/api/views.py changed, reloading.]
[2020-09-18 20:10:41,222][MainThread:140131942927688][task_id:django.utils.autoreload][autoreload.py:598][INFO][Watching for file changes with StatReloader]
[2020-09-19 14:00:52,334][MainThread:139824488602952][task_id:django.utils.autoreload][autoreload.py:598][INFO][Watching for file changes with StatReloader]
[2020-09-19 14:02:53,999][MainThread:139824488602952][task_id:django.utils.autoreload][autoreload.py:222][INFO][/usr/src/api/api/models.py changed, reloading.]
[2020-09-19 14:02:55,220][MainThread:140146884369736][task_id:django.utils.autoreload][autoreload.py:598][INFO][Watching for file changes with StatReloader]
[2020-09-19 14:11:17,757][MainThread:140146884369736][task_id:django.utils.autoreload][autoreload.py:222][INFO][/usr/src/api/api/models.py changed, reloading.]
[2020-09-19 14:11:18,703][MainThread:140007244098888][task_id:django.utils.autoreload][autoreload.py:598][INFO][Watching for file changes with StatReloader]
[2020-09-19 14:38:18,510][MainThread:140007244098888][task_id:django.utils.autoreload][autoreload.py:222][INFO][/usr/src/api/api/models.py changed, reloading.]
[2020-09-19 14:38:20,542][MainThread:139789982248264][task_id:django.utils.autoreload][autoreload.py:598][INFO][Watching for file changes with StatReloader]
[2020-09-19 14:42:17,395][MainThread:139789982248264][task_id:django.utils.autoreload][autoreload.py:222][INFO][/usr/src/api/api/models.py changed, reloading.]
[2020-09-19 14:42:18,841][MainThread:140701859425608][task_id:django.utils.autoreload][autoreload.py:598][INFO][Watching for file changes with StatReloader]
[2020-09-19 14:50:52,454][MainThread:140701859425608][task_id:django.utils.autoreload][autoreload.py:222][INFO][/usr/src/api/api/models.py changed, reloading.]
[2020-09-19 14:50:53,784][MainThread:139977642151240][task_id:django.utils.autoreload][autoreload.py:598][INFO][Watching for file changes with StatReloader]
[2020-09-19 14:52:19,405][MainThread:139977642151240][task_id:django.utils.autoreload][autoreload.py:222][INFO][/usr/src/api/api/models.py changed, reloading.]
[2020-09-19 14:52:20,859][MainThread:140659446959432][task_id:django.utils.autoreload][autoreload.py:598][INFO][Watching for file changes with StatReloader]
[2020-09-19 14:53:43,766][MainThread:140659446959432][task_id:django.utils.autoreload][autoreload.py:222][INFO][/usr/src/api/api/models.py changed, reloading.]
[2020-09-19 14:53:45,398][MainThread:140536649452872][task_id:django.utils.autoreload][autoreload.py:598][INFO][Watching for file changes with StatReloader]
[2020-09-19 14:57:35,627][MainThread:140536649452872][task_id:django.utils.autoreload][autoreload.py:222][INFO][/usr/src/api/api/models.py changed, reloading.]
[2020-09-19 14:57:37,066][MainThread:139912928173384][task_id:django.utils.autoreload][autoreload.py:598][INFO][Watching for file changes with StatReloader]
[2020-09-19 15:10:17,358][MainThread:139912928173384][task_id:django.utils.autoreload][autoreload.py:222][INFO][/usr/src/api/api/models.py changed, reloading.]
[2020-09-19 15:10:19,008][MainThread:139859498179912][task_id:django.utils.autoreload][autoreload.py:598][INFO][Watching for file changes with StatReloader]
[2020-09-19 15:13:05,469][MainThread:139859498179912][task_id:django.utils.autoreload][autoreload.py:222][INFO][/usr/src/api/api/views.py changed, reloading.]
[2020-09-19 15:13:07,003][MainThread:140671657430344][task_id:django.utils.autoreload][autoreload.py:598][INFO][Watching for file changes with StatReloader]
[2020-09-19 15:19:50,586][MainThread:140671657430344][task_id:django.utils.autoreload][autoreload.py:222][INFO][/usr/src/api/api/views.py changed, reloading.]
[2020-09-19 15:19:52,353][MainThread:140391809027400][task_id:django.utils.autoreload][autoreload.py:598][INFO][Watching for file changes with StatReloader]
[2020-09-19 15:59:29,230][MainThread:140391809027400][task_id:django.utils.autoreload][autoreload.py:222][INFO][/usr/src/api/api/models.py changed, reloading.]
[2020-09-19 15:59:30,305][MainThread:139664769211720][task_id:django.utils.autoreload][autoreload.py:598][INFO][Watching for file changes with StatReloader]
[2020-09-19 16:07:45,002][MainThread:140384488492360][task_id:django.utils.autoreload][autoreload.py:598][INFO][Watching for file changes with StatReloader]
[2020-09-19 16:25:31,913][MainThread:140384488492360][task_id:django.utils.autoreload][autoreload.py:222][INFO][/usr/src/api/api/models.py changed, reloading.]
[2020-09-19 16:25:32,918][MainThread:140193227722056][task_id:django.utils.autoreload][autoreload.py:598][INFO][Watching for file changes with StatReloader]
[2020-09-19 16:38:13,001][MainThread:140193227722056][task_id:django.utils.autoreload][autoreload.py:222][INFO][/usr/src/api/api/models.py changed, reloading.]
[2020-09-19 16:38:13,791][MainThread:139820587863368][task_id:django.utils.autoreload][autoreload.py:598][INFO][Watching for file changes with StatReloader]
[2020-09-19 16:39:17,481][MainThread:139820587863368][task_id:django.utils.autoreload][autoreload.py:222][INFO][/usr/src/api/api/models.py changed, reloading.]
[2020-09-19 16:39:18,332][MainThread:140537518693704][task_id:django.utils.autoreload][autoreload.py:598][INFO][Watching for file changes with StatReloader]
[2020-09-19 16:58:42,889][MainThread:140537518693704][task_id:django.utils.autoreload][autoreload.py:222][INFO][/usr/src/api/api/models.py changed, reloading.]
[2020-09-19 16:58:44,025][MainThread:140005874875720][task_id:django.utils.autoreload][autoreload.py:598][INFO][Watching for file changes with StatReloader]
[2020-09-19 17:00:43,565][MainThread:140005874875720][task_id:django.utils.autoreload][autoreload.py:222][INFO][/usr/src/api/api/models.py changed, reloading.]
[2020-09-19 17:00:44,402][MainThread:140588968508744][task_id:django.utils.autoreload][autoreload.py:598][INFO][Watching for file changes with StatReloader]
[2020-09-19 17:07:45,163][MainThread:140588968508744][task_id:django.utils.autoreload][autoreload.py:222][INFO][/usr/src/api/api/models.py changed, reloading.]
[2020-09-19 17:07:46,032][MainThread:139890588892488][task_id:django.utils.autoreload][autoreload.py:598][INFO][Watching for file changes with StatReloader]
[2020-09-19 17:25:50,156][MainThread:139890588892488][task_id:django.utils.autoreload][autoreload.py:222][INFO][/usr/src/api/api/models.py changed, reloading.]
[2020-09-19 17:25:51,270][MainThread:139810482359624][task_id:django.utils.autoreload][autoreload.py:598][INFO][Watching for file changes with StatReloader]
[2020-09-19 18:01:17,668][Thread-3:139810435676960][task_id:django.request][log.py:228][WARNING][Not Found: /api/customer_addr/[object Object]/]
[2020-09-20 08:24:20,482][Thread-10:139810435676960][task_id:django.request][log.py:228][ERROR][Internal Server Error: /api/order_model/]
Traceback (most recent call last):
  File "/usr/local/lib/python3.7/site-packages/django/db/backends/utils.py", line 86, in _execute
    return self.cursor.execute(sql, params)
psycopg2.errors.UndefinedColumn: column api_ordermodel.material does not exist
LINE 1: ...api_ordermodel"."number", "api_ordermodel"."atr", "api_order...
                                                             ^


The above exception was the direct cause of the following exception:

Traceback (most recent call last):
  File "/usr/local/lib/python3.7/site-packages/django/core/handlers/exception.py", line 34, in inner
    response = get_response(request)
  File "/usr/local/lib/python3.7/site-packages/django/core/handlers/base.py", line 115, in _get_response
    response = self.process_exception_by_middleware(e, request)
  File "/usr/local/lib/python3.7/site-packages/django/core/handlers/base.py", line 113, in _get_response
    response = wrapped_callback(request, *callback_args, **callback_kwargs)
  File "/usr/local/lib/python3.7/site-packages/django/views/decorators/csrf.py", line 54, in wrapped_view
    return view_func(*args, **kwargs)
  File "/usr/local/lib/python3.7/site-packages/rest_framework/viewsets.py", line 114, in view
    return self.dispatch(request, *args, **kwargs)
  File "/usr/local/lib/python3.7/site-packages/rest_framework/views.py", line 505, in dispatch
    response = self.handle_exception(exc)
  File "/usr/local/lib/python3.7/site-packages/rest_framework/views.py", line 465, in handle_exception
    self.raise_uncaught_exception(exc)
  File "/usr/local/lib/python3.7/site-packages/rest_framework/views.py", line 476, in raise_uncaught_exception
    raise exc
  File "/usr/local/lib/python3.7/site-packages/rest_framework/views.py", line 502, in dispatch
    response = handler(request, *args, **kwargs)
  File "/usr/local/lib/python3.7/site-packages/rest_framework/mixins.py", line 40, in list
    page = self.paginate_queryset(queryset)
  File "/usr/local/lib/python3.7/site-packages/rest_framework/generics.py", line 171, in paginate_queryset
    return self.paginator.paginate_queryset(queryset, self.request, view=self)
  File "/usr/local/lib/python3.7/site-packages/rest_framework/pagination.py", line 218, in paginate_queryset
    return list(self.page)
  File "/usr/local/lib/python3.7/site-packages/django/core/paginator.py", line 150, in __len__
    return len(self.object_list)
  File "/usr/local/lib/python3.7/site-packages/django/db/models/query.py", line 258, in __len__
    self._fetch_all()
  File "/usr/local/lib/python3.7/site-packages/django/db/models/query.py", line 1261, in _fetch_all
    self._result_cache = list(self._iterable_class(self))
  File "/usr/local/lib/python3.7/site-packages/django/db/models/query.py", line 57, in __iter__
    results = compiler.execute_sql(chunked_fetch=self.chunked_fetch, chunk_size=self.chunk_size)
  File "/usr/local/lib/python3.7/site-packages/django/db/models/sql/compiler.py", line 1151, in execute_sql
    cursor.execute(sql, params)
  File "/usr/local/lib/python3.7/site-packages/django/db/backends/utils.py", line 100, in execute
    return super().execute(sql, params)
  File "/usr/local/lib/python3.7/site-packages/django/db/backends/utils.py", line 68, in execute
    return self._execute_with_wrappers(sql, params, many=False, executor=self._execute)
  File "/usr/local/lib/python3.7/site-packages/django/db/backends/utils.py", line 77, in _execute_with_wrappers
    return executor(sql, params, many, context)
  File "/usr/local/lib/python3.7/site-packages/django/db/backends/utils.py", line 86, in _execute
    return self.cursor.execute(sql, params)
  File "/usr/local/lib/python3.7/site-packages/django/db/utils.py", line 90, in __exit__
    raise dj_exc_value.with_traceback(traceback) from exc_value
  File "/usr/local/lib/python3.7/site-packages/django/db/backends/utils.py", line 86, in _execute
    return self.cursor.execute(sql, params)
django.db.utils.ProgrammingError: column api_ordermodel.material does not exist
LINE 1: ...api_ordermodel"."number", "api_ordermodel"."atr", "api_order...
                                                             ^

[2020-09-21 04:52:06,020][MainThread:139892243324232][task_id:django.utils.autoreload][autoreload.py:598][INFO][Watching for file changes with StatReloader]
[2020-09-21 04:52:44,588][Thread-1:139892196641568][task_id:django.request][log.py:228][ERROR][Internal Server Error: /api/staffs/null/]
Traceback (most recent call last):
  File "/usr/local/lib/python3.7/site-packages/rest_framework/request.py", line 74, in wrap_attributeerrors
    yield
  File "/usr/local/lib/python3.7/site-packages/rest_framework/request.py", line 220, in user
    self._authenticate()
  File "/usr/local/lib/python3.7/site-packages/rest_framework/request.py", line 373, in _authenticate
    user_auth_tuple = authenticator.authenticate(self)
  File "/usr/src/api/user/authentications.py", line 25, in authenticate
    if token and user.is_use == 1:
AttributeError: 'NoneType' object has no attribute 'is_use'

During handling of the above exception, another exception occurred:

Traceback (most recent call last):
  File "/usr/local/lib/python3.7/site-packages/django/core/handlers/exception.py", line 34, in inner
    response = get_response(request)
  File "/usr/local/lib/python3.7/site-packages/django/core/handlers/base.py", line 115, in _get_response
    response = self.process_exception_by_middleware(e, request)
  File "/usr/local/lib/python3.7/site-packages/django/core/handlers/base.py", line 113, in _get_response
    response = wrapped_callback(request, *callback_args, **callback_kwargs)
  File "/usr/local/lib/python3.7/site-packages/django/views/decorators/csrf.py", line 54, in wrapped_view
    return view_func(*args, **kwargs)
  File "/usr/local/lib/python3.7/site-packages/rest_framework/viewsets.py", line 114, in view
    return self.dispatch(request, *args, **kwargs)
  File "/usr/local/lib/python3.7/site-packages/rest_framework/views.py", line 505, in dispatch
    response = self.handle_exception(exc)
  File "/usr/local/lib/python3.7/site-packages/rest_framework/views.py", line 465, in handle_exception
    self.raise_uncaught_exception(exc)
  File "/usr/local/lib/python3.7/site-packages/rest_framework/views.py", line 476, in raise_uncaught_exception
    raise exc
  File "/usr/local/lib/python3.7/site-packages/rest_framework/views.py", line 493, in dispatch
    self.initial(request, *args, **kwargs)
  File "/usr/local/lib/python3.7/site-packages/rest_framework/views.py", line 410, in initial
    self.perform_authentication(request)
  File "/usr/local/lib/python3.7/site-packages/rest_framework/views.py", line 324, in perform_authentication
    request.user
  File "/usr/local/lib/python3.7/site-packages/rest_framework/request.py", line 220, in user
    self._authenticate()
  File "/usr/local/lib/python3.7/contextlib.py", line 130, in __exit__
    self.gen.throw(type, value, traceback)
  File "/usr/local/lib/python3.7/site-packages/rest_framework/request.py", line 78, in wrap_attributeerrors
    raise exc.with_traceback(info[2])
  File "/usr/local/lib/python3.7/site-packages/rest_framework/request.py", line 74, in wrap_attributeerrors
    yield
  File "/usr/local/lib/python3.7/site-packages/rest_framework/request.py", line 220, in user
    self._authenticate()
  File "/usr/local/lib/python3.7/site-packages/rest_framework/request.py", line 373, in _authenticate
    user_auth_tuple = authenticator.authenticate(self)
  File "/usr/src/api/user/authentications.py", line 25, in authenticate
    if token and user.is_use == 1:
rest_framework.request.WrappedAttributeError: 'NoneType' object has no attribute 'is_use'
[2020-09-21 04:53:03,365][Thread-2:139892194007840][task_id:django.request][log.py:228][WARNING][Not Found: /product/]
[2020-09-21 04:53:03,375][Thread-3:139892192946976][task_id:django.request][log.py:228][WARNING][Not Found: /apple-touch-icon-precomposed.png]
[2020-09-21 04:53:03,380][Thread-3:139892192946976][task_id:django.request][log.py:228][WARNING][Not Found: /apple-touch-icon.png]
[2020-09-21 04:53:03,384][Thread-3:139892192946976][task_id:django.request][log.py:228][WARNING][Not Found: /favicon.ico]
[2020-09-21 04:53:03,389][Thread-3:139892192946976][task_id:django.request][log.py:228][WARNING][Not Found: /apple-touch-icon-precomposed.png]
[2020-09-21 04:53:03,393][Thread-3:139892192946976][task_id:django.request][log.py:228][WARNING][Not Found: /apple-touch-icon.png]
[2020-09-21 04:53:03,397][Thread-3:139892192946976][task_id:django.request][log.py:228][WARNING][Not Found: /favicon.ico]
[2020-09-21 04:53:03,403][Thread-2:139892194007840][task_id:django.request][log.py:228][WARNING][Not Found: /product/]
[2020-09-21 04:53:03,410][Thread-3:139892192946976][task_id:django.request][log.py:228][WARNING][Not Found: /apple-touch-icon-precomposed.png]
[2020-09-21 04:53:03,414][Thread-3:139892192946976][task_id:django.request][log.py:228][WARNING][Not Found: /apple-touch-icon.png]
[2020-09-21 04:53:03,419][Thread-3:139892192946976][task_id:django.request][log.py:228][WARNING][Not Found: /favicon.ico]
[2020-09-21 04:53:03,423][Thread-3:139892192946976][task_id:django.request][log.py:228][WARNING][Not Found: /apple-touch-icon-precomposed.png]
[2020-09-21 04:53:03,428][Thread-3:139892192946976][task_id:django.request][log.py:228][WARNING][Not Found: /apple-touch-icon.png]
[2020-09-21 04:53:03,432][Thread-3:139892192946976][task_id:django.request][log.py:228][WARNING][Not Found: /favicon.ico]
[2020-09-21 04:53:39,800][Thread-1:139892196641568][task_id:django.request][log.py:228][ERROR][Internal Server Error: /api/staffs/null/]
Traceback (most recent call last):
  File "/usr/local/lib/python3.7/site-packages/rest_framework/request.py", line 74, in wrap_attributeerrors
    yield
  File "/usr/local/lib/python3.7/site-packages/rest_framework/request.py", line 220, in user
    self._authenticate()
  File "/usr/local/lib/python3.7/site-packages/rest_framework/request.py", line 373, in _authenticate
    user_auth_tuple = authenticator.authenticate(self)
  File "/usr/src/api/user/authentications.py", line 25, in authenticate
    if token and user.is_use == 1:
AttributeError: 'NoneType' object has no attribute 'is_use'

During handling of the above exception, another exception occurred:

Traceback (most recent call last):
  File "/usr/local/lib/python3.7/site-packages/django/core/handlers/exception.py", line 34, in inner
    response = get_response(request)
  File "/usr/local/lib/python3.7/site-packages/django/core/handlers/base.py", line 115, in _get_response
    response = self.process_exception_by_middleware(e, request)
  File "/usr/local/lib/python3.7/site-packages/django/core/handlers/base.py", line 113, in _get_response
    response = wrapped_callback(request, *callback_args, **callback_kwargs)
  File "/usr/local/lib/python3.7/site-packages/django/views/decorators/csrf.py", line 54, in wrapped_view
    return view_func(*args, **kwargs)
  File "/usr/local/lib/python3.7/site-packages/rest_framework/viewsets.py", line 114, in view
    return self.dispatch(request, *args, **kwargs)
  File "/usr/local/lib/python3.7/site-packages/rest_framework/views.py", line 505, in dispatch
    response = self.handle_exception(exc)
  File "/usr/local/lib/python3.7/site-packages/rest_framework/views.py", line 465, in handle_exception
    self.raise_uncaught_exception(exc)
  File "/usr/local/lib/python3.7/site-packages/rest_framework/views.py", line 476, in raise_uncaught_exception
    raise exc
  File "/usr/local/lib/python3.7/site-packages/rest_framework/views.py", line 493, in dispatch
    self.initial(request, *args, **kwargs)
  File "/usr/local/lib/python3.7/site-packages/rest_framework/views.py", line 410, in initial
    self.perform_authentication(request)
  File "/usr/local/lib/python3.7/site-packages/rest_framework/views.py", line 324, in perform_authentication
    request.user
  File "/usr/local/lib/python3.7/site-packages/rest_framework/request.py", line 220, in user
    self._authenticate()
  File "/usr/local/lib/python3.7/contextlib.py", line 130, in __exit__
    self.gen.throw(type, value, traceback)
  File "/usr/local/lib/python3.7/site-packages/rest_framework/request.py", line 78, in wrap_attributeerrors
    raise exc.with_traceback(info[2])
  File "/usr/local/lib/python3.7/site-packages/rest_framework/request.py", line 74, in wrap_attributeerrors
    yield
  File "/usr/local/lib/python3.7/site-packages/rest_framework/request.py", line 220, in user
    self._authenticate()
  File "/usr/local/lib/python3.7/site-packages/rest_framework/request.py", line 373, in _authenticate
    user_auth_tuple = authenticator.authenticate(self)
  File "/usr/src/api/user/authentications.py", line 25, in authenticate
    if token and user.is_use == 1:
rest_framework.request.WrappedAttributeError: 'NoneType' object has no attribute 'is_use'
[2020-09-21 04:54:39,317][Thread-1:139892196641568][task_id:django.request][log.py:228][ERROR][Internal Server Error: /api/customer_addr/]
Traceback (most recent call last):
  File "/usr/local/lib/python3.7/site-packages/django/db/backends/utils.py", line 86, in _execute
    return self.cursor.execute(sql, params)
psycopg2.errors.UndefinedTable: relation "api_customeraddr" does not exist
LINE 1: SELECT COUNT(*) AS "__count" FROM "api_customeraddr" WHERE "...
                                          ^


The above exception was the direct cause of the following exception:

Traceback (most recent call last):
  File "/usr/local/lib/python3.7/site-packages/django/core/handlers/exception.py", line 34, in inner
    response = get_response(request)
  File "/usr/local/lib/python3.7/site-packages/django/core/handlers/base.py", line 115, in _get_response
    response = self.process_exception_by_middleware(e, request)
  File "/usr/local/lib/python3.7/site-packages/django/core/handlers/base.py", line 113, in _get_response
    response = wrapped_callback(request, *callback_args, **callback_kwargs)
  File "/usr/local/lib/python3.7/site-packages/django/views/decorators/csrf.py", line 54, in wrapped_view
    return view_func(*args, **kwargs)
  File "/usr/local/lib/python3.7/site-packages/rest_framework/viewsets.py", line 114, in view
    return self.dispatch(request, *args, **kwargs)
  File "/usr/local/lib/python3.7/site-packages/rest_framework/views.py", line 505, in dispatch
    response = self.handle_exception(exc)
  File "/usr/local/lib/python3.7/site-packages/rest_framework/views.py", line 465, in handle_exception
    self.raise_uncaught_exception(exc)
  File "/usr/local/lib/python3.7/site-packages/rest_framework/views.py", line 476, in raise_uncaught_exception
    raise exc
  File "/usr/local/lib/python3.7/site-packages/rest_framework/views.py", line 502, in dispatch
    response = handler(request, *args, **kwargs)
  File "/usr/local/lib/python3.7/site-packages/rest_framework/mixins.py", line 40, in list
    page = self.paginate_queryset(queryset)
  File "/usr/local/lib/python3.7/site-packages/rest_framework/generics.py", line 171, in paginate_queryset
    return self.paginator.paginate_queryset(queryset, self.request, view=self)
  File "/usr/local/lib/python3.7/site-packages/rest_framework/pagination.py", line 206, in paginate_queryset
    self.page = paginator.page(page_number)
  File "/usr/local/lib/python3.7/site-packages/django/core/paginator.py", line 70, in page
    number = self.validate_number(number)
  File "/usr/local/lib/python3.7/site-packages/django/core/paginator.py", line 48, in validate_number
    if number > self.num_pages:
  File "/usr/local/lib/python3.7/site-packages/django/utils/functional.py", line 48, in __get__
    res = instance.__dict__[self.name] = self.func(instance)
  File "/usr/local/lib/python3.7/site-packages/django/core/paginator.py", line 97, in num_pages
    if self.count == 0 and not self.allow_empty_first_page:
  File "/usr/local/lib/python3.7/site-packages/django/utils/functional.py", line 48, in __get__
    res = instance.__dict__[self.name] = self.func(instance)
  File "/usr/local/lib/python3.7/site-packages/django/core/paginator.py", line 91, in count
    return c()
  File "/usr/local/lib/python3.7/site-packages/django/db/models/query.py", line 397, in count
    return self.query.get_count(using=self.db)
  File "/usr/local/lib/python3.7/site-packages/django/db/models/sql/query.py", line 517, in get_count
    number = obj.get_aggregation(using, ['__count'])['__count']
  File "/usr/local/lib/python3.7/site-packages/django/db/models/sql/query.py", line 502, in get_aggregation
    result = compiler.execute_sql(SINGLE)
  File "/usr/local/lib/python3.7/site-packages/django/db/models/sql/compiler.py", line 1151, in execute_sql
    cursor.execute(sql, params)
  File "/usr/local/lib/python3.7/site-packages/django/db/backends/utils.py", line 100, in execute
    return super().execute(sql, params)
  File "/usr/local/lib/python3.7/site-packages/django/db/backends/utils.py", line 68, in execute
    return self._execute_with_wrappers(sql, params, many=False, executor=self._execute)
  File "/usr/local/lib/python3.7/site-packages/django/db/backends/utils.py", line 77, in _execute_with_wrappers
    return executor(sql, params, many, context)
  File "/usr/local/lib/python3.7/site-packages/django/db/backends/utils.py", line 86, in _execute
    return self.cursor.execute(sql, params)
  File "/usr/local/lib/python3.7/site-packages/django/db/utils.py", line 90, in __exit__
    raise dj_exc_value.with_traceback(traceback) from exc_value
  File "/usr/local/lib/python3.7/site-packages/django/db/backends/utils.py", line 86, in _execute
    return self.cursor.execute(sql, params)
django.db.utils.ProgrammingError: relation "api_customeraddr" does not exist
LINE 1: SELECT COUNT(*) AS "__count" FROM "api_customeraddr" WHERE "...
                                          ^

[2020-09-21 04:54:51,929][Thread-1:139892196641568][task_id:django.request][log.py:228][ERROR][Internal Server Error: /api/customer_addr/]
Traceback (most recent call last):
  File "/usr/local/lib/python3.7/site-packages/django/db/backends/utils.py", line 86, in _execute
    return self.cursor.execute(sql, params)
psycopg2.errors.UndefinedTable: relation "api_customeraddr" does not exist
LINE 1: SELECT COUNT(*) AS "__count" FROM "api_customeraddr" WHERE "...
                                          ^


The above exception was the direct cause of the following exception:

Traceback (most recent call last):
  File "/usr/local/lib/python3.7/site-packages/django/core/handlers/exception.py", line 34, in inner
    response = get_response(request)
  File "/usr/local/lib/python3.7/site-packages/django/core/handlers/base.py", line 115, in _get_response
    response = self.process_exception_by_middleware(e, request)
  File "/usr/local/lib/python3.7/site-packages/django/core/handlers/base.py", line 113, in _get_response
    response = wrapped_callback(request, *callback_args, **callback_kwargs)
  File "/usr/local/lib/python3.7/site-packages/django/views/decorators/csrf.py", line 54, in wrapped_view
    return view_func(*args, **kwargs)
  File "/usr/local/lib/python3.7/site-packages/rest_framework/viewsets.py", line 114, in view
    return self.dispatch(request, *args, **kwargs)
  File "/usr/local/lib/python3.7/site-packages/rest_framework/views.py", line 505, in dispatch
    response = self.handle_exception(exc)
  File "/usr/local/lib/python3.7/site-packages/rest_framework/views.py", line 465, in handle_exception
    self.raise_uncaught_exception(exc)
  File "/usr/local/lib/python3.7/site-packages/rest_framework/views.py", line 476, in raise_uncaught_exception
    raise exc
  File "/usr/local/lib/python3.7/site-packages/rest_framework/views.py", line 502, in dispatch
    response = handler(request, *args, **kwargs)
  File "/usr/local/lib/python3.7/site-packages/rest_framework/mixins.py", line 40, in list
    page = self.paginate_queryset(queryset)
  File "/usr/local/lib/python3.7/site-packages/rest_framework/generics.py", line 171, in paginate_queryset
    return self.paginator.paginate_queryset(queryset, self.request, view=self)
  File "/usr/local/lib/python3.7/site-packages/rest_framework/pagination.py", line 206, in paginate_queryset
    self.page = paginator.page(page_number)
  File "/usr/local/lib/python3.7/site-packages/django/core/paginator.py", line 70, in page
    number = self.validate_number(number)
  File "/usr/local/lib/python3.7/site-packages/django/core/paginator.py", line 48, in validate_number
    if number > self.num_pages:
  File "/usr/local/lib/python3.7/site-packages/django/utils/functional.py", line 48, in __get__
    res = instance.__dict__[self.name] = self.func(instance)
  File "/usr/local/lib/python3.7/site-packages/django/core/paginator.py", line 97, in num_pages
    if self.count == 0 and not self.allow_empty_first_page:
  File "/usr/local/lib/python3.7/site-packages/django/utils/functional.py", line 48, in __get__
    res = instance.__dict__[self.name] = self.func(instance)
  File "/usr/local/lib/python3.7/site-packages/django/core/paginator.py", line 91, in count
    return c()
  File "/usr/local/lib/python3.7/site-packages/django/db/models/query.py", line 397, in count
    return self.query.get_count(using=self.db)
  File "/usr/local/lib/python3.7/site-packages/django/db/models/sql/query.py", line 517, in get_count
    number = obj.get_aggregation(using, ['__count'])['__count']
  File "/usr/local/lib/python3.7/site-packages/django/db/models/sql/query.py", line 502, in get_aggregation
    result = compiler.execute_sql(SINGLE)
  File "/usr/local/lib/python3.7/site-packages/django/db/models/sql/compiler.py", line 1151, in execute_sql
    cursor.execute(sql, params)
  File "/usr/local/lib/python3.7/site-packages/django/db/backends/utils.py", line 100, in execute
    return super().execute(sql, params)
  File "/usr/local/lib/python3.7/site-packages/django/db/backends/utils.py", line 68, in execute
    return self._execute_with_wrappers(sql, params, many=False, executor=self._execute)
  File "/usr/local/lib/python3.7/site-packages/django/db/backends/utils.py", line 77, in _execute_with_wrappers
    return executor(sql, params, many, context)
  File "/usr/local/lib/python3.7/site-packages/django/db/backends/utils.py", line 86, in _execute
    return self.cursor.execute(sql, params)
  File "/usr/local/lib/python3.7/site-packages/django/db/utils.py", line 90, in __exit__
    raise dj_exc_value.with_traceback(traceback) from exc_value
  File "/usr/local/lib/python3.7/site-packages/django/db/backends/utils.py", line 86, in _execute
    return self.cursor.execute(sql, params)
django.db.utils.ProgrammingError: relation "api_customeraddr" does not exist
LINE 1: SELECT COUNT(*) AS "__count" FROM "api_customeraddr" WHERE "...
                                          ^

[2020-09-21 04:58:41,426][Thread-6:139892190538528][task_id:django.request][log.py:228][WARNING][Not Found: /product/]
[2020-09-21 05:03:55,704][MainThread:139892243324232][task_id:django.utils.autoreload][autoreload.py:222][INFO][/usr/src/api/api/models.py changed, reloading.]
[2020-09-21 05:03:56,325][MainThread:139856839798088][task_id:django.utils.autoreload][autoreload.py:598][INFO][Watching for file changes with StatReloader]
[2020-09-21 05:08:51,730][MainThread:139856839798088][task_id:django.utils.autoreload][autoreload.py:222][INFO][/usr/src/api/api/models.py changed, reloading.]
[2020-09-21 05:08:52,321][MainThread:140449705692488][task_id:django.utils.autoreload][autoreload.py:598][INFO][Watching for file changes with StatReloader]
[2020-09-21 05:09:12,141][MainThread:140449705692488][task_id:django.utils.autoreload][autoreload.py:222][INFO][/usr/src/api/api/models.py changed, reloading.]
[2020-09-21 05:09:12,759][MainThread:139995876093256][task_id:django.utils.autoreload][autoreload.py:598][INFO][Watching for file changes with StatReloader]
[2020-09-21 05:09:19,912][MainThread:139677902933320][task_id:django.utils.autoreload][autoreload.py:598][INFO][Watching for file changes with StatReloader]
[2020-09-21 05:10:17,815][MainThread:140592744815944][task_id:django.utils.autoreload][autoreload.py:598][INFO][Watching for file changes with StatReloader]
[2020-09-21 05:17:45,870][MainThread:140592744815944][task_id:django.utils.autoreload][autoreload.py:222][INFO][/usr/src/api/api/models.py changed, reloading.]
[2020-09-21 05:17:46,462][MainThread:140067393559880][task_id:django.utils.autoreload][autoreload.py:598][INFO][Watching for file changes with StatReloader]
[2020-09-21 05:47:06,029][Thread-2:140067346877216][task_id:django.request][log.py:228][WARNING][Bad Request: /api/order_model/]
[2020-09-21 05:48:12,318][Thread-2:140067346877216][task_id:django.request][log.py:228][ERROR][Internal Server Error: /api/order_model/]
Traceback (most recent call last):
  File "/usr/local/lib/python3.7/site-packages/django/db/models/base.py", line 466, in __init__
    val = kwargs.pop(field.attname)
KeyError: 'number'

During handling of the above exception, another exception occurred:

Traceback (most recent call last):
  File "/usr/local/lib/python3.7/site-packages/django/core/handlers/exception.py", line 34, in inner
    response = get_response(request)
  File "/usr/local/lib/python3.7/site-packages/django/core/handlers/base.py", line 115, in _get_response
    response = self.process_exception_by_middleware(e, request)
  File "/usr/local/lib/python3.7/site-packages/django/core/handlers/base.py", line 113, in _get_response
    response = wrapped_callback(request, *callback_args, **callback_kwargs)
  File "/usr/local/lib/python3.7/site-packages/django/views/decorators/csrf.py", line 54, in wrapped_view
    return view_func(*args, **kwargs)
  File "/usr/local/lib/python3.7/site-packages/rest_framework/viewsets.py", line 114, in view
    return self.dispatch(request, *args, **kwargs)
  File "/usr/local/lib/python3.7/site-packages/rest_framework/views.py", line 505, in dispatch
    response = self.handle_exception(exc)
  File "/usr/local/lib/python3.7/site-packages/rest_framework/views.py", line 465, in handle_exception
    self.raise_uncaught_exception(exc)
  File "/usr/local/lib/python3.7/site-packages/rest_framework/views.py", line 476, in raise_uncaught_exception
    raise exc
  File "/usr/local/lib/python3.7/site-packages/rest_framework/views.py", line 502, in dispatch
    response = handler(request, *args, **kwargs)
  File "/usr/local/lib/python3.7/site-packages/rest_framework/mixins.py", line 19, in create
    self.perform_create(serializer)
  File "/usr/local/lib/python3.7/site-packages/rest_framework/mixins.py", line 24, in perform_create
    serializer.save()
  File "/usr/local/lib/python3.7/site-packages/rest_framework/serializers.py", line 213, in save
    self.instance = self.create(validated_data)
  File "/usr/local/lib/python3.7/site-packages/rest_framework/serializers.py", line 932, in create
    instance = ModelClass._default_manager.create(**validated_data)
  File "/usr/local/lib/python3.7/site-packages/django/db/models/manager.py", line 82, in manager_method
    return getattr(self.get_queryset(), name)(*args, **kwargs)
  File "/usr/local/lib/python3.7/site-packages/django/db/models/query.py", line 431, in create
    obj = self.model(**kwargs)
  File "/usr/local/lib/python3.7/site-packages/django/db/models/base.py", line 472, in __init__
    val = field.get_default()
  File "/usr/local/lib/python3.7/site-packages/django/db/models/fields/__init__.py", line 829, in get_default
    return self._get_default()
  File "/usr/src/api/api/models.py", line 157, in make_model_number
    now_id = OrderModel.objects.latest().id + 1
  File "/usr/local/lib/python3.7/site-packages/django/db/models/manager.py", line 82, in manager_method
    return getattr(self.get_queryset(), name)(*args, **kwargs)
  File "/usr/local/lib/python3.7/site-packages/django/db/models/query.py", line 660, in latest
    return self.reverse()._earliest(*fields)
  File "/usr/local/lib/python3.7/site-packages/django/db/models/query.py", line 644, in _earliest
    "earliest() and latest() require either fields as positional "
ValueError: earliest() and latest() require either fields as positional arguments or 'get_latest_by' in the model's Meta.
[2020-09-21 05:50:20,023][MainThread:140067393559880][task_id:django.utils.autoreload][autoreload.py:222][INFO][/usr/src/api/api/models.py changed, reloading.]
[2020-09-21 05:50:20,645][MainThread:139866311638344][task_id:django.utils.autoreload][autoreload.py:598][INFO][Watching for file changes with StatReloader]
[2020-09-21 05:51:07,671][Thread-1:139866264955680][task_id:django.request][log.py:228][ERROR][Internal Server Error: /api/order_model/]
Traceback (most recent call last):
  File "/usr/local/lib/python3.7/site-packages/django/db/models/base.py", line 466, in __init__
    val = kwargs.pop(field.attname)
KeyError: 'number'

During handling of the above exception, another exception occurred:

Traceback (most recent call last):
  File "/usr/local/lib/python3.7/site-packages/django/core/handlers/exception.py", line 34, in inner
    response = get_response(request)
  File "/usr/local/lib/python3.7/site-packages/django/core/handlers/base.py", line 115, in _get_response
    response = self.process_exception_by_middleware(e, request)
  File "/usr/local/lib/python3.7/site-packages/django/core/handlers/base.py", line 113, in _get_response
    response = wrapped_callback(request, *callback_args, **callback_kwargs)
  File "/usr/local/lib/python3.7/site-packages/django/views/decorators/csrf.py", line 54, in wrapped_view
    return view_func(*args, **kwargs)
  File "/usr/local/lib/python3.7/site-packages/rest_framework/viewsets.py", line 114, in view
    return self.dispatch(request, *args, **kwargs)
  File "/usr/local/lib/python3.7/site-packages/rest_framework/views.py", line 505, in dispatch
    response = self.handle_exception(exc)
  File "/usr/local/lib/python3.7/site-packages/rest_framework/views.py", line 465, in handle_exception
    self.raise_uncaught_exception(exc)
  File "/usr/local/lib/python3.7/site-packages/rest_framework/views.py", line 476, in raise_uncaught_exception
    raise exc
  File "/usr/local/lib/python3.7/site-packages/rest_framework/views.py", line 502, in dispatch
    response = handler(request, *args, **kwargs)
  File "/usr/local/lib/python3.7/site-packages/rest_framework/mixins.py", line 19, in create
    self.perform_create(serializer)
  File "/usr/local/lib/python3.7/site-packages/rest_framework/mixins.py", line 24, in perform_create
    serializer.save()
  File "/usr/local/lib/python3.7/site-packages/rest_framework/serializers.py", line 213, in save
    self.instance = self.create(validated_data)
  File "/usr/local/lib/python3.7/site-packages/rest_framework/serializers.py", line 932, in create
    instance = ModelClass._default_manager.create(**validated_data)
  File "/usr/local/lib/python3.7/site-packages/django/db/models/manager.py", line 82, in manager_method
    return getattr(self.get_queryset(), name)(*args, **kwargs)
  File "/usr/local/lib/python3.7/site-packages/django/db/models/query.py", line 431, in create
    obj = self.model(**kwargs)
  File "/usr/local/lib/python3.7/site-packages/django/db/models/base.py", line 472, in __init__
    val = field.get_default()
  File "/usr/local/lib/python3.7/site-packages/django/db/models/fields/__init__.py", line 829, in get_default
    return self._get_default()
  File "/usr/src/api/api/models.py", line 157, in make_model_number
    now_id = OrderModel.objects.latest().id + 1
  File "/usr/local/lib/python3.7/site-packages/django/db/models/manager.py", line 82, in manager_method
    return getattr(self.get_queryset(), name)(*args, **kwargs)
  File "/usr/local/lib/python3.7/site-packages/django/db/models/query.py", line 660, in latest
    return self.reverse()._earliest(*fields)
  File "/usr/local/lib/python3.7/site-packages/django/db/models/query.py", line 644, in _earliest
    "earliest() and latest() require either fields as positional "
ValueError: earliest() and latest() require either fields as positional arguments or 'get_latest_by' in the model's Meta.
[2020-09-21 05:51:36,334][MainThread:139866311638344][task_id:django.utils.autoreload][autoreload.py:222][INFO][/usr/src/api/api/models.py changed, reloading.]
[2020-09-21 05:51:36,990][MainThread:140342420761928][task_id:django.utils.autoreload][autoreload.py:598][INFO][Watching for file changes with StatReloader]
[2020-09-21 05:51:53,716][MainThread:140342420761928][task_id:django.utils.autoreload][autoreload.py:222][INFO][/usr/src/api/api/models.py changed, reloading.]
[2020-09-21 05:51:54,322][MainThread:139755637402952][task_id:django.utils.autoreload][autoreload.py:598][INFO][Watching for file changes with StatReloader]
[2020-09-21 05:52:00,414][Thread-1:139755590810400][task_id:django.request][log.py:228][ERROR][Internal Server Error: /api/order_model/]
Traceback (most recent call last):
  File "/usr/local/lib/python3.7/site-packages/django/db/models/base.py", line 466, in __init__
    val = kwargs.pop(field.attname)
KeyError: 'number'

During handling of the above exception, another exception occurred:

Traceback (most recent call last):
  File "/usr/local/lib/python3.7/site-packages/django/core/handlers/exception.py", line 34, in inner
    response = get_response(request)
  File "/usr/local/lib/python3.7/site-packages/django/core/handlers/base.py", line 115, in _get_response
    response = self.process_exception_by_middleware(e, request)
  File "/usr/local/lib/python3.7/site-packages/django/core/handlers/base.py", line 113, in _get_response
    response = wrapped_callback(request, *callback_args, **callback_kwargs)
  File "/usr/local/lib/python3.7/site-packages/django/views/decorators/csrf.py", line 54, in wrapped_view
    return view_func(*args, **kwargs)
  File "/usr/local/lib/python3.7/site-packages/rest_framework/viewsets.py", line 114, in view
    return self.dispatch(request, *args, **kwargs)
  File "/usr/local/lib/python3.7/site-packages/rest_framework/views.py", line 505, in dispatch
    response = self.handle_exception(exc)
  File "/usr/local/lib/python3.7/site-packages/rest_framework/views.py", line 465, in handle_exception
    self.raise_uncaught_exception(exc)
  File "/usr/local/lib/python3.7/site-packages/rest_framework/views.py", line 476, in raise_uncaught_exception
    raise exc
  File "/usr/local/lib/python3.7/site-packages/rest_framework/views.py", line 502, in dispatch
    response = handler(request, *args, **kwargs)
  File "/usr/local/lib/python3.7/site-packages/rest_framework/mixins.py", line 19, in create
    self.perform_create(serializer)
  File "/usr/local/lib/python3.7/site-packages/rest_framework/mixins.py", line 24, in perform_create
    serializer.save()
  File "/usr/local/lib/python3.7/site-packages/rest_framework/serializers.py", line 213, in save
    self.instance = self.create(validated_data)
  File "/usr/local/lib/python3.7/site-packages/rest_framework/serializers.py", line 932, in create
    instance = ModelClass._default_manager.create(**validated_data)
  File "/usr/local/lib/python3.7/site-packages/django/db/models/manager.py", line 82, in manager_method
    return getattr(self.get_queryset(), name)(*args, **kwargs)
  File "/usr/local/lib/python3.7/site-packages/django/db/models/query.py", line 431, in create
    obj = self.model(**kwargs)
  File "/usr/local/lib/python3.7/site-packages/django/db/models/base.py", line 472, in __init__
    val = field.get_default()
  File "/usr/local/lib/python3.7/site-packages/django/db/models/fields/__init__.py", line 829, in get_default
    return self._get_default()
  File "/usr/src/api/api/models.py", line 157, in make_model_number
    now_id = OrderModel.objects.last().id + 1
AttributeError: 'NoneType' object has no attribute 'id'
[2020-09-21 05:52:16,366][MainThread:139755637402952][task_id:django.utils.autoreload][autoreload.py:222][INFO][/usr/src/api/api/models.py changed, reloading.]
[2020-09-21 05:52:16,981][MainThread:139879124077896][task_id:django.utils.autoreload][autoreload.py:598][INFO][Watching for file changes with StatReloader]
[2020-09-21 05:52:23,348][Thread-1:139879077395232][task_id:django.request][log.py:228][ERROR][Internal Server Error: /api/order_model/]
Traceback (most recent call last):
  File "/usr/local/lib/python3.7/site-packages/django/db/models/base.py", line 466, in __init__
    val = kwargs.pop(field.attname)
KeyError: 'number'

During handling of the above exception, another exception occurred:

Traceback (most recent call last):
  File "/usr/local/lib/python3.7/site-packages/django/core/handlers/exception.py", line 34, in inner
    response = get_response(request)
  File "/usr/local/lib/python3.7/site-packages/django/core/handlers/base.py", line 115, in _get_response
    response = self.process_exception_by_middleware(e, request)
  File "/usr/local/lib/python3.7/site-packages/django/core/handlers/base.py", line 113, in _get_response
    response = wrapped_callback(request, *callback_args, **callback_kwargs)
  File "/usr/local/lib/python3.7/site-packages/django/views/decorators/csrf.py", line 54, in wrapped_view
    return view_func(*args, **kwargs)
  File "/usr/local/lib/python3.7/site-packages/rest_framework/viewsets.py", line 114, in view
    return self.dispatch(request, *args, **kwargs)
  File "/usr/local/lib/python3.7/site-packages/rest_framework/views.py", line 505, in dispatch
    response = self.handle_exception(exc)
  File "/usr/local/lib/python3.7/site-packages/rest_framework/views.py", line 465, in handle_exception
    self.raise_uncaught_exception(exc)
  File "/usr/local/lib/python3.7/site-packages/rest_framework/views.py", line 476, in raise_uncaught_exception
    raise exc
  File "/usr/local/lib/python3.7/site-packages/rest_framework/views.py", line 502, in dispatch
    response = handler(request, *args, **kwargs)
  File "/usr/local/lib/python3.7/site-packages/rest_framework/mixins.py", line 19, in create
    self.perform_create(serializer)
  File "/usr/local/lib/python3.7/site-packages/rest_framework/mixins.py", line 24, in perform_create
    serializer.save()
  File "/usr/local/lib/python3.7/site-packages/rest_framework/serializers.py", line 213, in save
    self.instance = self.create(validated_data)
  File "/usr/local/lib/python3.7/site-packages/rest_framework/serializers.py", line 932, in create
    instance = ModelClass._default_manager.create(**validated_data)
  File "/usr/local/lib/python3.7/site-packages/django/db/models/manager.py", line 82, in manager_method
    return getattr(self.get_queryset(), name)(*args, **kwargs)
  File "/usr/local/lib/python3.7/site-packages/django/db/models/query.py", line 431, in create
    obj = self.model(**kwargs)
  File "/usr/local/lib/python3.7/site-packages/django/db/models/base.py", line 472, in __init__
    val = field.get_default()
  File "/usr/local/lib/python3.7/site-packages/django/db/models/fields/__init__.py", line 829, in get_default
    return self._get_default()
  File "/usr/src/api/api/models.py", line 157, in make_model_number
    now_id = OrderModel.objects.last().id + 1
AttributeError: 'NoneType' object has no attribute 'id'
[2020-09-21 05:55:38,332][MainThread:139879124077896][task_id:django.utils.autoreload][autoreload.py:222][INFO][/usr/src/api/api/models.py changed, reloading.]
[2020-09-21 05:55:38,952][MainThread:140007024364872][task_id:django.utils.autoreload][autoreload.py:598][INFO][Watching for file changes with StatReloader]
[2020-09-21 05:58:14,873][MainThread:140007024364872][task_id:django.utils.autoreload][autoreload.py:222][INFO][/usr/src/api/api/models.py changed, reloading.]
[2020-09-21 05:58:15,476][MainThread:139923914640712][task_id:django.utils.autoreload][autoreload.py:598][INFO][Watching for file changes with StatReloader]
[2020-09-21 06:02:00,115][MainThread:139923914640712][task_id:django.utils.autoreload][autoreload.py:222][INFO][/usr/src/api/api/models.py changed, reloading.]
[2020-09-21 06:02:00,742][MainThread:139655600225608][task_id:django.utils.autoreload][autoreload.py:598][INFO][Watching for file changes with StatReloader]
[2020-09-21 06:02:55,224][MainThread:139655600225608][task_id:django.utils.autoreload][autoreload.py:222][INFO][/usr/src/api/api/models.py changed, reloading.]
[2020-09-21 06:02:55,828][MainThread:140036287286600][task_id:django.utils.autoreload][autoreload.py:598][INFO][Watching for file changes with StatReloader]
[2020-09-21 06:03:41,409][MainThread:140036287286600][task_id:django.utils.autoreload][autoreload.py:222][INFO][/usr/src/api/api/models.py changed, reloading.]
[2020-09-21 06:03:42,036][MainThread:140593695309128][task_id:django.utils.autoreload][autoreload.py:598][INFO][Watching for file changes with StatReloader]
[2020-09-21 06:04:09,494][Thread-1:140593648626464][task_id:django.request][log.py:228][ERROR][Internal Server Error: /api/order_model/]
Traceback (most recent call last):
  File "/usr/local/lib/python3.7/site-packages/django/core/handlers/exception.py", line 34, in inner
    response = get_response(request)
  File "/usr/local/lib/python3.7/site-packages/django/core/handlers/base.py", line 115, in _get_response
    response = self.process_exception_by_middleware(e, request)
  File "/usr/local/lib/python3.7/site-packages/django/core/handlers/base.py", line 113, in _get_response
    response = wrapped_callback(request, *callback_args, **callback_kwargs)
  File "/usr/local/lib/python3.7/site-packages/django/views/decorators/csrf.py", line 54, in wrapped_view
    return view_func(*args, **kwargs)
  File "/usr/local/lib/python3.7/site-packages/rest_framework/viewsets.py", line 114, in view
    return self.dispatch(request, *args, **kwargs)
  File "/usr/local/lib/python3.7/site-packages/rest_framework/views.py", line 505, in dispatch
    response = self.handle_exception(exc)
  File "/usr/local/lib/python3.7/site-packages/rest_framework/views.py", line 465, in handle_exception
    self.raise_uncaught_exception(exc)
  File "/usr/local/lib/python3.7/site-packages/rest_framework/views.py", line 476, in raise_uncaught_exception
    raise exc
  File "/usr/local/lib/python3.7/site-packages/rest_framework/views.py", line 502, in dispatch
    response = handler(request, *args, **kwargs)
  File "/usr/local/lib/python3.7/site-packages/rest_framework/mixins.py", line 43, in list
    return self.get_paginated_response(serializer.data)
  File "/usr/local/lib/python3.7/site-packages/rest_framework/serializers.py", line 757, in data
    ret = super().data
  File "/usr/local/lib/python3.7/site-packages/rest_framework/serializers.py", line 261, in data
    self._data = self.to_representation(self.instance)
  File "/usr/local/lib/python3.7/site-packages/rest_framework/serializers.py", line 675, in to_representation
    self.child.to_representation(item) for item in iterable
  File "/usr/local/lib/python3.7/site-packages/rest_framework/serializers.py", line 675, in <listcomp>
    self.child.to_representation(item) for item in iterable
  File "/usr/local/lib/python3.7/site-packages/rest_framework/serializers.py", line 526, in to_representation
    ret[field.field_name] = field.to_representation(attribute)
  File "/usr/local/lib/python3.7/site-packages/rest_framework/fields.py", line 1289, in to_representation
    'Expected a `date`, but got a `datetime`. Refusing to coerce, '
AssertionError: Expected a `date`, but got a `datetime`. Refusing to coerce, as this may mean losing timezone information. Use a custom read-only field and deal with timezone issues explicitly.
[2020-09-21 06:04:26,777][MainThread:140593695309128][task_id:django.utils.autoreload][autoreload.py:222][INFO][/usr/src/api/api/models.py changed, reloading.]
[2020-09-21 06:04:27,375][MainThread:140185007775048][task_id:django.utils.autoreload][autoreload.py:598][INFO][Watching for file changes with StatReloader]
[2020-09-21 06:08:13,927][MainThread:140185007775048][task_id:django.utils.autoreload][autoreload.py:222][INFO][/usr/src/api/api/models.py changed, reloading.]
[2020-09-21 06:08:14,540][MainThread:140500143357256][task_id:django.utils.autoreload][autoreload.py:598][INFO][Watching for file changes with StatReloader]
[2020-09-21 06:08:26,814][Thread-1:140500096674592][task_id:django.request][log.py:228][ERROR][Internal Server Error: /api/order_model/]
Traceback (most recent call last):
  File "/usr/local/lib/python3.7/site-packages/django/core/handlers/exception.py", line 34, in inner
    response = get_response(request)
  File "/usr/local/lib/python3.7/site-packages/django/core/handlers/base.py", line 115, in _get_response
    response = self.process_exception_by_middleware(e, request)
  File "/usr/local/lib/python3.7/site-packages/django/core/handlers/base.py", line 113, in _get_response
    response = wrapped_callback(request, *callback_args, **callback_kwargs)
  File "/usr/local/lib/python3.7/site-packages/django/views/decorators/csrf.py", line 54, in wrapped_view
    return view_func(*args, **kwargs)
  File "/usr/local/lib/python3.7/site-packages/rest_framework/viewsets.py", line 114, in view
    return self.dispatch(request, *args, **kwargs)
  File "/usr/local/lib/python3.7/site-packages/rest_framework/views.py", line 505, in dispatch
    response = self.handle_exception(exc)
  File "/usr/local/lib/python3.7/site-packages/rest_framework/views.py", line 465, in handle_exception
    self.raise_uncaught_exception(exc)
  File "/usr/local/lib/python3.7/site-packages/rest_framework/views.py", line 476, in raise_uncaught_exception
    raise exc
  File "/usr/local/lib/python3.7/site-packages/rest_framework/views.py", line 502, in dispatch
    response = handler(request, *args, **kwargs)
  File "/usr/local/lib/python3.7/site-packages/rest_framework/mixins.py", line 43, in list
    return self.get_paginated_response(serializer.data)
  File "/usr/local/lib/python3.7/site-packages/rest_framework/serializers.py", line 757, in data
    ret = super().data
  File "/usr/local/lib/python3.7/site-packages/rest_framework/serializers.py", line 261, in data
    self._data = self.to_representation(self.instance)
  File "/usr/local/lib/python3.7/site-packages/rest_framework/serializers.py", line 675, in to_representation
    self.child.to_representation(item) for item in iterable
  File "/usr/local/lib/python3.7/site-packages/rest_framework/serializers.py", line 675, in <listcomp>
    self.child.to_representation(item) for item in iterable
  File "/usr/local/lib/python3.7/site-packages/rest_framework/serializers.py", line 526, in to_representation
    ret[field.field_name] = field.to_representation(attribute)
  File "/usr/local/lib/python3.7/site-packages/rest_framework/fields.py", line 1289, in to_representation
    'Expected a `date`, but got a `datetime`. Refusing to coerce, '
AssertionError: Expected a `date`, but got a `datetime`. Refusing to coerce, as this may mean losing timezone information. Use a custom read-only field and deal with timezone issues explicitly.
[2020-09-21 06:33:54,618][MainThread:140500143357256][task_id:django.utils.autoreload][autoreload.py:222][INFO][/usr/src/api/api/views.py changed, reloading.]
[2020-09-21 06:33:55,276][MainThread:139629374471496][task_id:django.utils.autoreload][autoreload.py:598][INFO][Watching for file changes with StatReloader]
[2020-09-21 06:34:03,289][MainThread:139629374471496][task_id:django.utils.autoreload][autoreload.py:222][INFO][/usr/src/api/api/views.py changed, reloading.]
[2020-09-21 06:34:03,929][MainThread:140591101492552][task_id:django.utils.autoreload][autoreload.py:598][INFO][Watching for file changes with StatReloader]
[2020-09-21 06:34:34,480][MainThread:140591101492552][task_id:django.utils.autoreload][autoreload.py:222][INFO][/usr/src/api/api/models.py changed, reloading.]
[2020-09-21 06:34:35,121][MainThread:140168256720200][task_id:django.utils.autoreload][autoreload.py:598][INFO][Watching for file changes with StatReloader]
[2020-09-21 06:34:54,471][Thread-1:140168210037536][task_id:django.request][log.py:228][ERROR][Internal Server Error: /api/order_model/]
Traceback (most recent call last):
  File "/usr/local/lib/python3.7/site-packages/django/db/backends/utils.py", line 86, in _execute
    return self.cursor.execute(sql, params)
psycopg2.errors.NotNullViolation: null value in column "pro_date" violates not-null constraint
DETAIL:  Failing row contains (3, ct-model-1, 1, 1, , , null, null, 100.00, test, 0, alibaba).


The above exception was the direct cause of the following exception:

Traceback (most recent call last):
  File "/usr/local/lib/python3.7/site-packages/django/core/handlers/exception.py", line 34, in inner
    response = get_response(request)
  File "/usr/local/lib/python3.7/site-packages/django/core/handlers/base.py", line 115, in _get_response
    response = self.process_exception_by_middleware(e, request)
  File "/usr/local/lib/python3.7/site-packages/django/core/handlers/base.py", line 113, in _get_response
    response = wrapped_callback(request, *callback_args, **callback_kwargs)
  File "/usr/local/lib/python3.7/site-packages/django/views/decorators/csrf.py", line 54, in wrapped_view
    return view_func(*args, **kwargs)
  File "/usr/local/lib/python3.7/site-packages/rest_framework/viewsets.py", line 114, in view
    return self.dispatch(request, *args, **kwargs)
  File "/usr/local/lib/python3.7/site-packages/rest_framework/views.py", line 505, in dispatch
    response = self.handle_exception(exc)
  File "/usr/local/lib/python3.7/site-packages/rest_framework/views.py", line 465, in handle_exception
    self.raise_uncaught_exception(exc)
  File "/usr/local/lib/python3.7/site-packages/rest_framework/views.py", line 476, in raise_uncaught_exception
    raise exc
  File "/usr/local/lib/python3.7/site-packages/rest_framework/views.py", line 502, in dispatch
    response = handler(request, *args, **kwargs)
  File "/usr/local/lib/python3.7/site-packages/rest_framework/mixins.py", line 19, in create
    self.perform_create(serializer)
  File "/usr/local/lib/python3.7/site-packages/rest_framework/mixins.py", line 24, in perform_create
    serializer.save()
  File "/usr/local/lib/python3.7/site-packages/rest_framework/serializers.py", line 213, in save
    self.instance = self.create(validated_data)
  File "/usr/local/lib/python3.7/site-packages/rest_framework/serializers.py", line 932, in create
    instance = ModelClass._default_manager.create(**validated_data)
  File "/usr/local/lib/python3.7/site-packages/django/db/models/manager.py", line 82, in manager_method
    return getattr(self.get_queryset(), name)(*args, **kwargs)
  File "/usr/local/lib/python3.7/site-packages/django/db/models/query.py", line 433, in create
    obj.save(force_insert=True, using=self.db)
  File "/usr/local/lib/python3.7/site-packages/django/db/models/base.py", line 746, in save
    force_update=force_update, update_fields=update_fields)
  File "/usr/local/lib/python3.7/site-packages/django/db/models/base.py", line 784, in save_base
    force_update, using, update_fields,
  File "/usr/local/lib/python3.7/site-packages/django/db/models/base.py", line 887, in _save_table
    results = self._do_insert(cls._base_manager, using, fields, returning_fields, raw)
  File "/usr/local/lib/python3.7/site-packages/django/db/models/base.py", line 926, in _do_insert
    using=using, raw=raw,
  File "/usr/local/lib/python3.7/site-packages/django/db/models/manager.py", line 82, in manager_method
    return getattr(self.get_queryset(), name)(*args, **kwargs)
  File "/usr/local/lib/python3.7/site-packages/django/db/models/query.py", line 1204, in _insert
    return query.get_compiler(using=using).execute_sql(returning_fields)
  File "/usr/local/lib/python3.7/site-packages/django/db/models/sql/compiler.py", line 1391, in execute_sql
    cursor.execute(sql, params)
  File "/usr/local/lib/python3.7/site-packages/django/db/backends/utils.py", line 100, in execute
    return super().execute(sql, params)
  File "/usr/local/lib/python3.7/site-packages/django/db/backends/utils.py", line 68, in execute
    return self._execute_with_wrappers(sql, params, many=False, executor=self._execute)
  File "/usr/local/lib/python3.7/site-packages/django/db/backends/utils.py", line 77, in _execute_with_wrappers
    return executor(sql, params, many, context)
  File "/usr/local/lib/python3.7/site-packages/django/db/backends/utils.py", line 86, in _execute
    return self.cursor.execute(sql, params)
  File "/usr/local/lib/python3.7/site-packages/django/db/utils.py", line 90, in __exit__
    raise dj_exc_value.with_traceback(traceback) from exc_value
  File "/usr/local/lib/python3.7/site-packages/django/db/backends/utils.py", line 86, in _execute
    return self.cursor.execute(sql, params)
django.db.utils.IntegrityError: null value in column "pro_date" violates not-null constraint
DETAIL:  Failing row contains (3, ct-model-1, 1, 1, , , null, null, 100.00, test, 0, alibaba).

[2020-09-21 06:36:08,051][MainThread:140168256720200][task_id:django.utils.autoreload][autoreload.py:222][INFO][/usr/src/api/api/models.py changed, reloading.]
[2020-09-21 06:36:08,731][MainThread:139693965966664][task_id:django.utils.autoreload][autoreload.py:598][INFO][Watching for file changes with StatReloader]
[2020-09-21 06:36:16,566][Thread-1:139693919284000][task_id:django.request][log.py:228][ERROR][Internal Server Error: /api/order_model/]
Traceback (most recent call last):
  File "/usr/local/lib/python3.7/site-packages/django/db/models/fields/__init__.py", line 1772, in get_prep_value
    return int(value)
TypeError: int() argument must be a string, a bytes-like object or a number, not 'getset_descriptor'

The above exception was the direct cause of the following exception:

Traceback (most recent call last):
  File "/usr/local/lib/python3.7/site-packages/rest_framework/serializers.py", line 932, in create
    instance = ModelClass._default_manager.create(**validated_data)
  File "/usr/local/lib/python3.7/site-packages/django/db/models/manager.py", line 82, in manager_method
    return getattr(self.get_queryset(), name)(*args, **kwargs)
  File "/usr/local/lib/python3.7/site-packages/django/db/models/query.py", line 433, in create
    obj.save(force_insert=True, using=self.db)
  File "/usr/local/lib/python3.7/site-packages/django/db/models/base.py", line 746, in save
    force_update=force_update, update_fields=update_fields)
  File "/usr/local/lib/python3.7/site-packages/django/db/models/base.py", line 784, in save_base
    force_update, using, update_fields,
  File "/usr/local/lib/python3.7/site-packages/django/db/models/base.py", line 887, in _save_table
    results = self._do_insert(cls._base_manager, using, fields, returning_fields, raw)
  File "/usr/local/lib/python3.7/site-packages/django/db/models/base.py", line 926, in _do_insert
    using=using, raw=raw,
  File "/usr/local/lib/python3.7/site-packages/django/db/models/manager.py", line 82, in manager_method
    return getattr(self.get_queryset(), name)(*args, **kwargs)
  File "/usr/local/lib/python3.7/site-packages/django/db/models/query.py", line 1204, in _insert
    return query.get_compiler(using=using).execute_sql(returning_fields)
  File "/usr/local/lib/python3.7/site-packages/django/db/models/sql/compiler.py", line 1390, in execute_sql
    for sql, params in self.as_sql():
  File "/usr/local/lib/python3.7/site-packages/django/db/models/sql/compiler.py", line 1335, in as_sql
    for obj in self.query.objs
  File "/usr/local/lib/python3.7/site-packages/django/db/models/sql/compiler.py", line 1335, in <listcomp>
    for obj in self.query.objs
  File "/usr/local/lib/python3.7/site-packages/django/db/models/sql/compiler.py", line 1334, in <listcomp>
    [self.prepare_value(field, self.pre_save_val(field, obj)) for field in fields]
  File "/usr/local/lib/python3.7/site-packages/django/db/models/sql/compiler.py", line 1275, in prepare_value
    value = field.get_db_prep_save(value, connection=self.connection)
  File "/usr/local/lib/python3.7/site-packages/django/db/models/fields/__init__.py", line 821, in get_db_prep_save
    return self.get_db_prep_value(value, connection=connection, prepared=False)
  File "/usr/local/lib/python3.7/site-packages/django/db/models/fields/__init__.py", line 816, in get_db_prep_value
    value = self.get_prep_value(value)
  File "/usr/local/lib/python3.7/site-packages/django/db/models/fields/__init__.py", line 1776, in get_prep_value
    ) from e
TypeError: Field 'useful_life' expected a number but got <attribute 'day' of 'datetime.date' objects>.

During handling of the above exception, another exception occurred:

Traceback (most recent call last):
  File "/usr/local/lib/python3.7/site-packages/django/core/handlers/exception.py", line 34, in inner
    response = get_response(request)
  File "/usr/local/lib/python3.7/site-packages/django/core/handlers/base.py", line 115, in _get_response
    response = self.process_exception_by_middleware(e, request)
  File "/usr/local/lib/python3.7/site-packages/django/core/handlers/base.py", line 113, in _get_response
    response = wrapped_callback(request, *callback_args, **callback_kwargs)
  File "/usr/local/lib/python3.7/site-packages/django/views/decorators/csrf.py", line 54, in wrapped_view
    return view_func(*args, **kwargs)
  File "/usr/local/lib/python3.7/site-packages/rest_framework/viewsets.py", line 114, in view
    return self.dispatch(request, *args, **kwargs)
  File "/usr/local/lib/python3.7/site-packages/rest_framework/views.py", line 505, in dispatch
    response = self.handle_exception(exc)
  File "/usr/local/lib/python3.7/site-packages/rest_framework/views.py", line 465, in handle_exception
    self.raise_uncaught_exception(exc)
  File "/usr/local/lib/python3.7/site-packages/rest_framework/views.py", line 476, in raise_uncaught_exception
    raise exc
  File "/usr/local/lib/python3.7/site-packages/rest_framework/views.py", line 502, in dispatch
    response = handler(request, *args, **kwargs)
  File "/usr/local/lib/python3.7/site-packages/rest_framework/mixins.py", line 19, in create
    self.perform_create(serializer)
  File "/usr/local/lib/python3.7/site-packages/rest_framework/mixins.py", line 24, in perform_create
    serializer.save()
  File "/usr/local/lib/python3.7/site-packages/rest_framework/serializers.py", line 213, in save
    self.instance = self.create(validated_data)
  File "/usr/local/lib/python3.7/site-packages/rest_framework/serializers.py", line 951, in create
    raise TypeError(msg)
TypeError: Got a `TypeError` when calling `OrderModel.objects.create()`. This may be because you have a writable field on the serializer class that is not a valid argument to `OrderModel.objects.create()`. You may need to make the field read-only, or override the OrderModelsSerializer.create() method to handle this correctly.
Original exception was:
 Traceback (most recent call last):
  File "/usr/local/lib/python3.7/site-packages/django/db/models/fields/__init__.py", line 1772, in get_prep_value
    return int(value)
TypeError: int() argument must be a string, a bytes-like object or a number, not 'getset_descriptor'

The above exception was the direct cause of the following exception:

Traceback (most recent call last):
  File "/usr/local/lib/python3.7/site-packages/rest_framework/serializers.py", line 932, in create
    instance = ModelClass._default_manager.create(**validated_data)
  File "/usr/local/lib/python3.7/site-packages/django/db/models/manager.py", line 82, in manager_method
    return getattr(self.get_queryset(), name)(*args, **kwargs)
  File "/usr/local/lib/python3.7/site-packages/django/db/models/query.py", line 433, in create
    obj.save(force_insert=True, using=self.db)
  File "/usr/local/lib/python3.7/site-packages/django/db/models/base.py", line 746, in save
    force_update=force_update, update_fields=update_fields)
  File "/usr/local/lib/python3.7/site-packages/django/db/models/base.py", line 784, in save_base
    force_update, using, update_fields,
  File "/usr/local/lib/python3.7/site-packages/django/db/models/base.py", line 887, in _save_table
    results = self._do_insert(cls._base_manager, using, fields, returning_fields, raw)
  File "/usr/local/lib/python3.7/site-packages/django/db/models/base.py", line 926, in _do_insert
    using=using, raw=raw,
  File "/usr/local/lib/python3.7/site-packages/django/db/models/manager.py", line 82, in manager_method
    return getattr(self.get_queryset(), name)(*args, **kwargs)
  File "/usr/local/lib/python3.7/site-packages/django/db/models/query.py", line 1204, in _insert
    return query.get_compiler(using=using).execute_sql(returning_fields)
  File "/usr/local/lib/python3.7/site-packages/django/db/models/sql/compiler.py", line 1390, in execute_sql
    for sql, params in self.as_sql():
  File "/usr/local/lib/python3.7/site-packages/django/db/models/sql/compiler.py", line 1335, in as_sql
    for obj in self.query.objs
  File "/usr/local/lib/python3.7/site-packages/django/db/models/sql/compiler.py", line 1335, in <listcomp>
    for obj in self.query.objs
  File "/usr/local/lib/python3.7/site-packages/django/db/models/sql/compiler.py", line 1334, in <listcomp>
    [self.prepare_value(field, self.pre_save_val(field, obj)) for field in fields]
  File "/usr/local/lib/python3.7/site-packages/django/db/models/sql/compiler.py", line 1275, in prepare_value
    value = field.get_db_prep_save(value, connection=self.connection)
  File "/usr/local/lib/python3.7/site-packages/django/db/models/fields/__init__.py", line 821, in get_db_prep_save
    return self.get_db_prep_value(value, connection=connection, prepared=False)
  File "/usr/local/lib/python3.7/site-packages/django/db/models/fields/__init__.py", line 816, in get_db_prep_value
    value = self.get_prep_value(value)
  File "/usr/local/lib/python3.7/site-packages/django/db/models/fields/__init__.py", line 1776, in get_prep_value
    ) from e
TypeError: Field 'useful_life' expected a number but got <attribute 'day' of 'datetime.date' objects>.

[2020-09-21 06:37:46,186][MainThread:139693965966664][task_id:django.utils.autoreload][autoreload.py:222][INFO][/usr/src/api/api/models.py changed, reloading.]
[2020-09-21 06:37:46,814][MainThread:139626910715208][task_id:django.utils.autoreload][autoreload.py:598][INFO][Watching for file changes with StatReloader]
[2020-09-21 06:37:58,867][Thread-1:139626864032544][task_id:django.request][log.py:228][ERROR][Internal Server Error: /api/order_model/]
Traceback (most recent call last):
  File "/usr/local/lib/python3.7/site-packages/django/core/handlers/exception.py", line 34, in inner
    response = get_response(request)
  File "/usr/local/lib/python3.7/site-packages/django/core/handlers/base.py", line 115, in _get_response
    response = self.process_exception_by_middleware(e, request)
  File "/usr/local/lib/python3.7/site-packages/django/core/handlers/base.py", line 113, in _get_response
    response = wrapped_callback(request, *callback_args, **callback_kwargs)
  File "/usr/local/lib/python3.7/site-packages/django/views/decorators/csrf.py", line 54, in wrapped_view
    return view_func(*args, **kwargs)
  File "/usr/local/lib/python3.7/site-packages/rest_framework/viewsets.py", line 114, in view
    return self.dispatch(request, *args, **kwargs)
  File "/usr/local/lib/python3.7/site-packages/rest_framework/views.py", line 505, in dispatch
    response = self.handle_exception(exc)
  File "/usr/local/lib/python3.7/site-packages/rest_framework/views.py", line 465, in handle_exception
    self.raise_uncaught_exception(exc)
  File "/usr/local/lib/python3.7/site-packages/rest_framework/views.py", line 476, in raise_uncaught_exception
    raise exc
  File "/usr/local/lib/python3.7/site-packages/rest_framework/views.py", line 502, in dispatch
    response = handler(request, *args, **kwargs)
  File "/usr/local/lib/python3.7/site-packages/rest_framework/mixins.py", line 20, in create
    headers = self.get_success_headers(serializer.data)
  File "/usr/local/lib/python3.7/site-packages/rest_framework/serializers.py", line 559, in data
    ret = super().data
  File "/usr/local/lib/python3.7/site-packages/rest_framework/serializers.py", line 261, in data
    self._data = self.to_representation(self.instance)
  File "/usr/local/lib/python3.7/site-packages/rest_framework/serializers.py", line 526, in to_representation
    ret[field.field_name] = field.to_representation(attribute)
  File "/usr/local/lib/python3.7/site-packages/rest_framework/fields.py", line 1289, in to_representation
    'Expected a `date`, but got a `datetime`. Refusing to coerce, '
AssertionError: Expected a `date`, but got a `datetime`. Refusing to coerce, as this may mean losing timezone information. Use a custom read-only field and deal with timezone issues explicitly.
[2020-09-21 06:38:34,882][MainThread:139626910715208][task_id:django.utils.autoreload][autoreload.py:222][INFO][/usr/src/api/api/models.py changed, reloading.]
[2020-09-21 06:38:35,497][MainThread:139738615442760][task_id:django.utils.autoreload][autoreload.py:598][INFO][Watching for file changes with StatReloader]
[2020-09-21 06:38:40,502][Thread-1:139738568760096][task_id:django.request][log.py:228][ERROR][Internal Server Error: /api/order_model/]
Traceback (most recent call last):
  File "/usr/local/lib/python3.7/site-packages/django/db/models/base.py", line 466, in __init__
    val = kwargs.pop(field.attname)
KeyError: 'pro_date'

During handling of the above exception, another exception occurred:

Traceback (most recent call last):
  File "/usr/local/lib/python3.7/site-packages/rest_framework/serializers.py", line 932, in create
    instance = ModelClass._default_manager.create(**validated_data)
  File "/usr/local/lib/python3.7/site-packages/django/db/models/manager.py", line 82, in manager_method
    return getattr(self.get_queryset(), name)(*args, **kwargs)
  File "/usr/local/lib/python3.7/site-packages/django/db/models/query.py", line 431, in create
    obj = self.model(**kwargs)
  File "/usr/local/lib/python3.7/site-packages/django/db/models/base.py", line 472, in __init__
    val = field.get_default()
  File "/usr/local/lib/python3.7/site-packages/django/db/models/fields/__init__.py", line 829, in get_default
    return self._get_default()
TypeError: descriptor 'date' of 'datetime.datetime' object needs an argument

During handling of the above exception, another exception occurred:

Traceback (most recent call last):
  File "/usr/local/lib/python3.7/site-packages/django/core/handlers/exception.py", line 34, in inner
    response = get_response(request)
  File "/usr/local/lib/python3.7/site-packages/django/core/handlers/base.py", line 115, in _get_response
    response = self.process_exception_by_middleware(e, request)
  File "/usr/local/lib/python3.7/site-packages/django/core/handlers/base.py", line 113, in _get_response
    response = wrapped_callback(request, *callback_args, **callback_kwargs)
  File "/usr/local/lib/python3.7/site-packages/django/views/decorators/csrf.py", line 54, in wrapped_view
    return view_func(*args, **kwargs)
  File "/usr/local/lib/python3.7/site-packages/rest_framework/viewsets.py", line 114, in view
    return self.dispatch(request, *args, **kwargs)
  File "/usr/local/lib/python3.7/site-packages/rest_framework/views.py", line 505, in dispatch
    response = self.handle_exception(exc)
  File "/usr/local/lib/python3.7/site-packages/rest_framework/views.py", line 465, in handle_exception
    self.raise_uncaught_exception(exc)
  File "/usr/local/lib/python3.7/site-packages/rest_framework/views.py", line 476, in raise_uncaught_exception
    raise exc
  File "/usr/local/lib/python3.7/site-packages/rest_framework/views.py", line 502, in dispatch
    response = handler(request, *args, **kwargs)
  File "/usr/local/lib/python3.7/site-packages/rest_framework/mixins.py", line 19, in create
    self.perform_create(serializer)
  File "/usr/local/lib/python3.7/site-packages/rest_framework/mixins.py", line 24, in perform_create
    serializer.save()
  File "/usr/local/lib/python3.7/site-packages/rest_framework/serializers.py", line 213, in save
    self.instance = self.create(validated_data)
  File "/usr/local/lib/python3.7/site-packages/rest_framework/serializers.py", line 951, in create
    raise TypeError(msg)
TypeError: Got a `TypeError` when calling `OrderModel.objects.create()`. This may be because you have a writable field on the serializer class that is not a valid argument to `OrderModel.objects.create()`. You may need to make the field read-only, or override the OrderModelsSerializer.create() method to handle this correctly.
Original exception was:
 Traceback (most recent call last):
  File "/usr/local/lib/python3.7/site-packages/django/db/models/base.py", line 466, in __init__
    val = kwargs.pop(field.attname)
KeyError: 'pro_date'

During handling of the above exception, another exception occurred:

Traceback (most recent call last):
  File "/usr/local/lib/python3.7/site-packages/rest_framework/serializers.py", line 932, in create
    instance = ModelClass._default_manager.create(**validated_data)
  File "/usr/local/lib/python3.7/site-packages/django/db/models/manager.py", line 82, in manager_method
    return getattr(self.get_queryset(), name)(*args, **kwargs)
  File "/usr/local/lib/python3.7/site-packages/django/db/models/query.py", line 431, in create
    obj = self.model(**kwargs)
  File "/usr/local/lib/python3.7/site-packages/django/db/models/base.py", line 472, in __init__
    val = field.get_default()
  File "/usr/local/lib/python3.7/site-packages/django/db/models/fields/__init__.py", line 829, in get_default
    return self._get_default()
TypeError: descriptor 'date' of 'datetime.datetime' object needs an argument

[2020-09-21 06:41:39,148][MainThread:139738615442760][task_id:django.utils.autoreload][autoreload.py:222][INFO][/usr/src/api/api/models.py changed, reloading.]
[2020-09-21 06:41:39,747][MainThread:139728164871496][task_id:django.utils.autoreload][autoreload.py:598][INFO][Watching for file changes with StatReloader]
[2020-09-21 06:41:46,630][Thread-1:139728118188832][task_id:django.request][log.py:228][WARNING][Bad Request: /api/order_model/]
[2020-09-21 06:43:04,222][MainThread:139728164871496][task_id:django.utils.autoreload][autoreload.py:222][INFO][/usr/src/api/api/models.py changed, reloading.]
[2020-09-21 06:43:04,960][MainThread:139806261521736][task_id:django.utils.autoreload][autoreload.py:598][INFO][Watching for file changes with StatReloader]
[2020-09-21 06:43:12,162][Thread-1:139806214839072][task_id:django.request][log.py:228][ERROR][Internal Server Error: /api/order_model/]
Traceback (most recent call last):
  File "/usr/local/lib/python3.7/site-packages/django/core/handlers/exception.py", line 34, in inner
    response = get_response(request)
  File "/usr/local/lib/python3.7/site-packages/django/core/handlers/base.py", line 115, in _get_response
    response = self.process_exception_by_middleware(e, request)
  File "/usr/local/lib/python3.7/site-packages/django/core/handlers/base.py", line 113, in _get_response
    response = wrapped_callback(request, *callback_args, **callback_kwargs)
  File "/usr/local/lib/python3.7/site-packages/django/views/decorators/csrf.py", line 54, in wrapped_view
    return view_func(*args, **kwargs)
  File "/usr/local/lib/python3.7/site-packages/rest_framework/viewsets.py", line 114, in view
    return self.dispatch(request, *args, **kwargs)
  File "/usr/local/lib/python3.7/site-packages/rest_framework/views.py", line 505, in dispatch
    response = self.handle_exception(exc)
  File "/usr/local/lib/python3.7/site-packages/rest_framework/views.py", line 465, in handle_exception
    self.raise_uncaught_exception(exc)
  File "/usr/local/lib/python3.7/site-packages/rest_framework/views.py", line 476, in raise_uncaught_exception
    raise exc
  File "/usr/local/lib/python3.7/site-packages/rest_framework/views.py", line 502, in dispatch
    response = handler(request, *args, **kwargs)
  File "/usr/local/lib/python3.7/site-packages/rest_framework/mixins.py", line 20, in create
    headers = self.get_success_headers(serializer.data)
  File "/usr/local/lib/python3.7/site-packages/rest_framework/serializers.py", line 559, in data
    ret = super().data
  File "/usr/local/lib/python3.7/site-packages/rest_framework/serializers.py", line 261, in data
    self._data = self.to_representation(self.instance)
  File "/usr/local/lib/python3.7/site-packages/rest_framework/serializers.py", line 526, in to_representation
    ret[field.field_name] = field.to_representation(attribute)
  File "/usr/local/lib/python3.7/site-packages/rest_framework/fields.py", line 1289, in to_representation
    'Expected a `date`, but got a `datetime`. Refusing to coerce, '
AssertionError: Expected a `date`, but got a `datetime`. Refusing to coerce, as this may mean losing timezone information. Use a custom read-only field and deal with timezone issues explicitly.
[2020-09-21 06:43:48,396][Thread-1:139806214839072][task_id:django.request][log.py:228][ERROR][Internal Server Error: /api/order_model/]
Traceback (most recent call last):
  File "/usr/local/lib/python3.7/site-packages/django/core/handlers/exception.py", line 34, in inner
    response = get_response(request)
  File "/usr/local/lib/python3.7/site-packages/django/core/handlers/base.py", line 115, in _get_response
    response = self.process_exception_by_middleware(e, request)
  File "/usr/local/lib/python3.7/site-packages/django/core/handlers/base.py", line 113, in _get_response
    response = wrapped_callback(request, *callback_args, **callback_kwargs)
  File "/usr/local/lib/python3.7/site-packages/django/views/decorators/csrf.py", line 54, in wrapped_view
    return view_func(*args, **kwargs)
  File "/usr/local/lib/python3.7/site-packages/rest_framework/viewsets.py", line 114, in view
    return self.dispatch(request, *args, **kwargs)
  File "/usr/local/lib/python3.7/site-packages/rest_framework/views.py", line 505, in dispatch
    response = self.handle_exception(exc)
  File "/usr/local/lib/python3.7/site-packages/rest_framework/views.py", line 465, in handle_exception
    self.raise_uncaught_exception(exc)
  File "/usr/local/lib/python3.7/site-packages/rest_framework/views.py", line 476, in raise_uncaught_exception
    raise exc
  File "/usr/local/lib/python3.7/site-packages/rest_framework/views.py", line 502, in dispatch
    response = handler(request, *args, **kwargs)
  File "/usr/local/lib/python3.7/site-packages/rest_framework/mixins.py", line 20, in create
    headers = self.get_success_headers(serializer.data)
  File "/usr/local/lib/python3.7/site-packages/rest_framework/serializers.py", line 559, in data
    ret = super().data
  File "/usr/local/lib/python3.7/site-packages/rest_framework/serializers.py", line 261, in data
    self._data = self.to_representation(self.instance)
  File "/usr/local/lib/python3.7/site-packages/rest_framework/serializers.py", line 526, in to_representation
    ret[field.field_name] = field.to_representation(attribute)
  File "/usr/local/lib/python3.7/site-packages/rest_framework/fields.py", line 1289, in to_representation
    'Expected a `date`, but got a `datetime`. Refusing to coerce, '
AssertionError: Expected a `date`, but got a `datetime`. Refusing to coerce, as this may mean losing timezone information. Use a custom read-only field and deal with timezone issues explicitly.
[2020-09-21 06:44:16,480][MainThread:139806261521736][task_id:django.utils.autoreload][autoreload.py:222][INFO][/usr/src/api/api/models.py changed, reloading.]
[2020-09-21 06:44:17,148][MainThread:140697198153032][task_id:django.utils.autoreload][autoreload.py:598][INFO][Watching for file changes with StatReloader]
[2020-09-21 06:44:28,607][Thread-1:140697151470368][task_id:django.request][log.py:228][ERROR][Internal Server Error: /api/order_model/]
Traceback (most recent call last):
  File "/usr/local/lib/python3.7/site-packages/django/core/handlers/exception.py", line 34, in inner
    response = get_response(request)
  File "/usr/local/lib/python3.7/site-packages/django/core/handlers/base.py", line 115, in _get_response
    response = self.process_exception_by_middleware(e, request)
  File "/usr/local/lib/python3.7/site-packages/django/core/handlers/base.py", line 113, in _get_response
    response = wrapped_callback(request, *callback_args, **callback_kwargs)
  File "/usr/local/lib/python3.7/site-packages/django/views/decorators/csrf.py", line 54, in wrapped_view
    return view_func(*args, **kwargs)
  File "/usr/local/lib/python3.7/site-packages/rest_framework/viewsets.py", line 114, in view
    return self.dispatch(request, *args, **kwargs)
  File "/usr/local/lib/python3.7/site-packages/rest_framework/views.py", line 505, in dispatch
    response = self.handle_exception(exc)
  File "/usr/local/lib/python3.7/site-packages/rest_framework/views.py", line 465, in handle_exception
    self.raise_uncaught_exception(exc)
  File "/usr/local/lib/python3.7/site-packages/rest_framework/views.py", line 476, in raise_uncaught_exception
    raise exc
  File "/usr/local/lib/python3.7/site-packages/rest_framework/views.py", line 502, in dispatch
    response = handler(request, *args, **kwargs)
  File "/usr/local/lib/python3.7/site-packages/rest_framework/mixins.py", line 20, in create
    headers = self.get_success_headers(serializer.data)
  File "/usr/local/lib/python3.7/site-packages/rest_framework/serializers.py", line 559, in data
    ret = super().data
  File "/usr/local/lib/python3.7/site-packages/rest_framework/serializers.py", line 261, in data
    self._data = self.to_representation(self.instance)
  File "/usr/local/lib/python3.7/site-packages/rest_framework/serializers.py", line 526, in to_representation
    ret[field.field_name] = field.to_representation(attribute)
  File "/usr/local/lib/python3.7/site-packages/rest_framework/fields.py", line 1289, in to_representation
    'Expected a `date`, but got a `datetime`. Refusing to coerce, '
AssertionError: Expected a `date`, but got a `datetime`. Refusing to coerce, as this may mean losing timezone information. Use a custom read-only field and deal with timezone issues explicitly.
[2020-09-21 06:45:02,912][MainThread:140697198153032][task_id:django.utils.autoreload][autoreload.py:222][INFO][/usr/src/api/api/models.py changed, reloading.]
[2020-09-21 06:45:03,515][MainThread:140113986714952][task_id:django.utils.autoreload][autoreload.py:598][INFO][Watching for file changes with StatReloader]
[2020-09-21 06:45:52,571][Thread-1:140113940032288][task_id:django.request][log.py:228][WARNING][Bad Request: /api/order_model/]
[2020-09-21 06:47:13,786][Thread-1:140113940032288][task_id:django.request][log.py:228][WARNING][Bad Request: /api/order_model/]
[2020-09-21 06:48:56,218][Thread-1:140113940032288][task_id:django.request][log.py:228][WARNING][Bad Request: /api/order_model/]
[2020-09-21 06:49:17,984][Thread-1:140113940032288][task_id:django.request][log.py:228][WARNING][Bad Request: /api/order_model/]
[2020-09-21 08:22:23,397][MainThread:140581983767880][task_id:django.utils.autoreload][autoreload.py:598][INFO][Watching for file changes with StatReloader]
[2020-09-21 08:22:26,986][Thread-1:140581937085216][task_id:django.request][log.py:228][ERROR][Internal Server Error: /api/order_model/]
Traceback (most recent call last):
  File "/usr/local/lib/python3.7/site-packages/django/core/handlers/exception.py", line 34, in inner
    response = get_response(request)
  File "/usr/local/lib/python3.7/site-packages/django/core/handlers/base.py", line 115, in _get_response
    response = self.process_exception_by_middleware(e, request)
  File "/usr/local/lib/python3.7/site-packages/django/core/handlers/base.py", line 113, in _get_response
    response = wrapped_callback(request, *callback_args, **callback_kwargs)
  File "/usr/local/lib/python3.7/site-packages/django/views/decorators/csrf.py", line 54, in wrapped_view
    return view_func(*args, **kwargs)
  File "/usr/local/lib/python3.7/site-packages/rest_framework/viewsets.py", line 114, in view
    return self.dispatch(request, *args, **kwargs)
  File "/usr/local/lib/python3.7/site-packages/rest_framework/views.py", line 505, in dispatch
    response = self.handle_exception(exc)
  File "/usr/local/lib/python3.7/site-packages/rest_framework/views.py", line 465, in handle_exception
    self.raise_uncaught_exception(exc)
  File "/usr/local/lib/python3.7/site-packages/rest_framework/views.py", line 476, in raise_uncaught_exception
    raise exc
  File "/usr/local/lib/python3.7/site-packages/rest_framework/views.py", line 502, in dispatch
    response = handler(request, *args, **kwargs)
  File "/usr/local/lib/python3.7/site-packages/rest_framework/mixins.py", line 43, in list
    return self.get_paginated_response(serializer.data)
  File "/usr/local/lib/python3.7/site-packages/rest_framework/serializers.py", line 757, in data
    ret = super().data
  File "/usr/local/lib/python3.7/site-packages/rest_framework/serializers.py", line 261, in data
    self._data = self.to_representation(self.instance)
  File "/usr/local/lib/python3.7/site-packages/rest_framework/serializers.py", line 675, in to_representation
    self.child.to_representation(item) for item in iterable
  File "/usr/local/lib/python3.7/site-packages/rest_framework/serializers.py", line 675, in <listcomp>
    self.child.to_representation(item) for item in iterable
  File "/usr/local/lib/python3.7/site-packages/rest_framework/serializers.py", line 526, in to_representation
    ret[field.field_name] = field.to_representation(attribute)
  File "/usr/local/lib/python3.7/site-packages/rest_framework/fields.py", line 1289, in to_representation
    'Expected a `date`, but got a `datetime`. Refusing to coerce, '
AssertionError: Expected a `date`, but got a `datetime`. Refusing to coerce, as this may mean losing timezone information. Use a custom read-only field and deal with timezone issues explicitly.
[2020-09-21 08:24:24,542][MainThread:139894687276360][task_id:django.utils.autoreload][autoreload.py:598][INFO][Watching for file changes with StatReloader]
[2020-09-21 08:36:09,663][Thread-2:139894638484256][task_id:django.request][log.py:228][WARNING][Bad Request: /api/order_model/]
[2020-09-21 08:37:25,134][MainThread:139894687276360][task_id:django.utils.autoreload][autoreload.py:222][INFO][/usr/src/api/api/views.py changed, reloading.]
[2020-09-21 08:37:26,127][MainThread:140629826313544][task_id:django.utils.autoreload][autoreload.py:598][INFO][Watching for file changes with StatReloader]
[2020-09-21 08:37:33,195][Thread-1:140629779630880][task_id:django.request][log.py:228][WARNING][Bad Request: /api/order_model/]
[2020-09-21 08:39:06,446][MainThread:140629826313544][task_id:django.utils.autoreload][autoreload.py:222][INFO][/usr/src/api/api/views.py changed, reloading.]
[2020-09-21 08:39:07,400][MainThread:140707699658056][task_id:django.utils.autoreload][autoreload.py:598][INFO][Watching for file changes with StatReloader]
[2020-09-21 08:39:12,440][Thread-1:140707652975392][task_id:django.request][log.py:228][WARNING][Bad Request: /api/order_model/]
[2020-09-21 10:16:05,048][Thread-2:140707652975392][task_id:django.request][log.py:228][WARNING][Bad Request: /api/order_model/]
[2020-09-21 10:17:34,999][Thread-2:140707652975392][task_id:django.request][log.py:228][WARNING][Bad Request: /api/order_model/]
[2020-09-21 10:18:51,251][Thread-2:140707652975392][task_id:django.request][log.py:228][WARNING][Bad Request: /api/order_model/]
[2020-09-21 10:19:45,106][Thread-2:140707652975392][task_id:django.request][log.py:228][WARNING][Bad Request: /api/order_model/]
[2020-09-21 10:25:55,445][Thread-3:140707652975392][task_id:django.request][log.py:228][WARNING][Bad Request: /api/order_model/]
[2020-09-21 10:41:05,345][MainThread:140707699658056][task_id:django.utils.autoreload][autoreload.py:222][INFO][/usr/src/api/api/models.py changed, reloading.]
[2020-09-21 10:41:06,344][MainThread:140168779967816][task_id:django.utils.autoreload][autoreload.py:598][INFO][Watching for file changes with StatReloader]
[2020-09-21 13:42:25,673][MainThread:140168779967816][task_id:django.utils.autoreload][autoreload.py:222][INFO][/usr/src/api/api/views.py changed, reloading.]
[2020-09-21 13:42:26,610][MainThread:139929302469960][task_id:django.utils.autoreload][autoreload.py:598][INFO][Watching for file changes with StatReloader]
[2020-09-21 13:42:39,934][MainThread:139929302469960][task_id:django.utils.autoreload][autoreload.py:222][INFO][/usr/src/api/api/models.py changed, reloading.]
[2020-09-21 13:42:40,901][MainThread:140441365171528][task_id:django.utils.autoreload][autoreload.py:598][INFO][Watching for file changes with StatReloader]
[2020-09-21 13:48:53,854][MainThread:140441365171528][task_id:django.utils.autoreload][autoreload.py:222][INFO][/usr/src/api/api/models.py changed, reloading.]
[2020-09-21 13:48:54,776][MainThread:140611938086216][task_id:django.utils.autoreload][autoreload.py:598][INFO][Watching for file changes with StatReloader]
[2020-09-21 13:49:10,384][MainThread:140611938086216][task_id:django.utils.autoreload][autoreload.py:222][INFO][/usr/src/api/api/views.py changed, reloading.]
[2020-09-21 13:49:11,390][MainThread:139644465720648][task_id:django.utils.autoreload][autoreload.py:598][INFO][Watching for file changes with StatReloader]
[2020-09-21 13:50:51,547][Thread-1:139644419037984][task_id:django.request][log.py:228][ERROR][Internal Server Error: /api/order_model/]
Traceback (most recent call last):
  File "/usr/local/lib/python3.7/site-packages/django/db/models/base.py", line 466, in __init__
    val = kwargs.pop(field.attname)
KeyError: 'number'

During handling of the above exception, another exception occurred:

Traceback (most recent call last):
  File "/usr/local/lib/python3.7/site-packages/django/core/handlers/exception.py", line 34, in inner
    response = get_response(request)
  File "/usr/local/lib/python3.7/site-packages/django/core/handlers/base.py", line 115, in _get_response
    response = self.process_exception_by_middleware(e, request)
  File "/usr/local/lib/python3.7/site-packages/django/core/handlers/base.py", line 113, in _get_response
    response = wrapped_callback(request, *callback_args, **callback_kwargs)
  File "/usr/local/lib/python3.7/site-packages/django/views/decorators/csrf.py", line 54, in wrapped_view
    return view_func(*args, **kwargs)
  File "/usr/local/lib/python3.7/site-packages/rest_framework/viewsets.py", line 114, in view
    return self.dispatch(request, *args, **kwargs)
  File "/usr/local/lib/python3.7/site-packages/rest_framework/views.py", line 505, in dispatch
    response = self.handle_exception(exc)
  File "/usr/local/lib/python3.7/site-packages/rest_framework/views.py", line 465, in handle_exception
    self.raise_uncaught_exception(exc)
  File "/usr/local/lib/python3.7/site-packages/rest_framework/views.py", line 476, in raise_uncaught_exception
    raise exc
  File "/usr/local/lib/python3.7/site-packages/rest_framework/views.py", line 502, in dispatch
    response = handler(request, *args, **kwargs)
  File "/usr/local/lib/python3.7/site-packages/rest_framework/mixins.py", line 19, in create
    self.perform_create(serializer)
  File "/usr/local/lib/python3.7/site-packages/rest_framework/mixins.py", line 24, in perform_create
    serializer.save()
  File "/usr/local/lib/python3.7/site-packages/rest_framework/serializers.py", line 213, in save
    self.instance = self.create(validated_data)
  File "/usr/local/lib/python3.7/site-packages/rest_framework/serializers.py", line 932, in create
    instance = ModelClass._default_manager.create(**validated_data)
  File "/usr/local/lib/python3.7/site-packages/django/db/models/manager.py", line 82, in manager_method
    return getattr(self.get_queryset(), name)(*args, **kwargs)
  File "/usr/local/lib/python3.7/site-packages/django/db/models/query.py", line 431, in create
    obj = self.model(**kwargs)
  File "/usr/local/lib/python3.7/site-packages/django/db/models/base.py", line 472, in __init__
    val = field.get_default()
  File "/usr/local/lib/python3.7/site-packages/django/db/models/fields/__init__.py", line 829, in get_default
    return self._get_default()
  File "/usr/src/api/api/models.py", line 161, in make_model_number
    now_id = OrderModel.objects.last().id + 1
AttributeError: 'NoneType' object has no attribute 'id'
[2020-09-21 13:52:04,143][MainThread:139644465720648][task_id:django.utils.autoreload][autoreload.py:222][INFO][/usr/src/api/api/models.py changed, reloading.]
[2020-09-21 13:52:05,006][MainThread:140650715819336][task_id:django.utils.autoreload][autoreload.py:598][INFO][Watching for file changes with StatReloader]
[2020-09-21 13:54:58,721][MainThread:140650715819336][task_id:django.utils.autoreload][autoreload.py:222][INFO][/usr/src/api/api/models.py changed, reloading.]
[2020-09-21 13:54:59,627][MainThread:139902439361864][task_id:django.utils.autoreload][autoreload.py:598][INFO][Watching for file changes with StatReloader]
[2020-09-21 13:55:49,081][Thread-1:139902392679200][task_id:django.request][log.py:228][ERROR][Internal Server Error: /api/order_model/]
Traceback (most recent call last):
  File "/usr/local/lib/python3.7/site-packages/django/db/backends/utils.py", line 86, in _execute
    return self.cursor.execute(sql, params)
psycopg2.errors.NotNullViolation: null value in column "number" violates not-null constraint
DETAIL:  Failing row contains (8, null, 1, , , 2020-09-15, null, 1000.00, , 0, alibaba, 1).


The above exception was the direct cause of the following exception:

Traceback (most recent call last):
  File "/usr/local/lib/python3.7/site-packages/django/core/handlers/exception.py", line 34, in inner
    response = get_response(request)
  File "/usr/local/lib/python3.7/site-packages/django/core/handlers/base.py", line 115, in _get_response
    response = self.process_exception_by_middleware(e, request)
  File "/usr/local/lib/python3.7/site-packages/django/core/handlers/base.py", line 113, in _get_response
    response = wrapped_callback(request, *callback_args, **callback_kwargs)
  File "/usr/local/lib/python3.7/site-packages/django/views/decorators/csrf.py", line 54, in wrapped_view
    return view_func(*args, **kwargs)
  File "/usr/local/lib/python3.7/site-packages/rest_framework/viewsets.py", line 114, in view
    return self.dispatch(request, *args, **kwargs)
  File "/usr/local/lib/python3.7/site-packages/rest_framework/views.py", line 505, in dispatch
    response = self.handle_exception(exc)
  File "/usr/local/lib/python3.7/site-packages/rest_framework/views.py", line 465, in handle_exception
    self.raise_uncaught_exception(exc)
  File "/usr/local/lib/python3.7/site-packages/rest_framework/views.py", line 476, in raise_uncaught_exception
    raise exc
  File "/usr/local/lib/python3.7/site-packages/rest_framework/views.py", line 502, in dispatch
    response = handler(request, *args, **kwargs)
  File "/usr/local/lib/python3.7/site-packages/rest_framework/mixins.py", line 19, in create
    self.perform_create(serializer)
  File "/usr/local/lib/python3.7/site-packages/rest_framework/mixins.py", line 24, in perform_create
    serializer.save()
  File "/usr/local/lib/python3.7/site-packages/rest_framework/serializers.py", line 213, in save
    self.instance = self.create(validated_data)
  File "/usr/local/lib/python3.7/site-packages/rest_framework/serializers.py", line 932, in create
    instance = ModelClass._default_manager.create(**validated_data)
  File "/usr/local/lib/python3.7/site-packages/django/db/models/manager.py", line 82, in manager_method
    return getattr(self.get_queryset(), name)(*args, **kwargs)
  File "/usr/local/lib/python3.7/site-packages/django/db/models/query.py", line 433, in create
    obj.save(force_insert=True, using=self.db)
  File "/usr/local/lib/python3.7/site-packages/django/db/models/base.py", line 746, in save
    force_update=force_update, update_fields=update_fields)
  File "/usr/local/lib/python3.7/site-packages/django/db/models/base.py", line 784, in save_base
    force_update, using, update_fields,
  File "/usr/local/lib/python3.7/site-packages/django/db/models/base.py", line 887, in _save_table
    results = self._do_insert(cls._base_manager, using, fields, returning_fields, raw)
  File "/usr/local/lib/python3.7/site-packages/django/db/models/base.py", line 926, in _do_insert
    using=using, raw=raw,
  File "/usr/local/lib/python3.7/site-packages/django/db/models/manager.py", line 82, in manager_method
    return getattr(self.get_queryset(), name)(*args, **kwargs)
  File "/usr/local/lib/python3.7/site-packages/django/db/models/query.py", line 1204, in _insert
    return query.get_compiler(using=using).execute_sql(returning_fields)
  File "/usr/local/lib/python3.7/site-packages/django/db/models/sql/compiler.py", line 1391, in execute_sql
    cursor.execute(sql, params)
  File "/usr/local/lib/python3.7/site-packages/django/db/backends/utils.py", line 100, in execute
    return super().execute(sql, params)
  File "/usr/local/lib/python3.7/site-packages/django/db/backends/utils.py", line 68, in execute
    return self._execute_with_wrappers(sql, params, many=False, executor=self._execute)
  File "/usr/local/lib/python3.7/site-packages/django/db/backends/utils.py", line 77, in _execute_with_wrappers
    return executor(sql, params, many, context)
  File "/usr/local/lib/python3.7/site-packages/django/db/backends/utils.py", line 86, in _execute
    return self.cursor.execute(sql, params)
  File "/usr/local/lib/python3.7/site-packages/django/db/utils.py", line 90, in __exit__
    raise dj_exc_value.with_traceback(traceback) from exc_value
  File "/usr/local/lib/python3.7/site-packages/django/db/backends/utils.py", line 86, in _execute
    return self.cursor.execute(sql, params)
django.db.utils.IntegrityError: null value in column "number" violates not-null constraint
DETAIL:  Failing row contains (8, null, 1, , , 2020-09-15, null, 1000.00, , 0, alibaba, 1).

[2020-09-21 13:56:05,444][MainThread:139902439361864][task_id:django.utils.autoreload][autoreload.py:222][INFO][/usr/src/api/api/models.py changed, reloading.]
[2020-09-21 13:56:06,409][MainThread:140348418477384][task_id:django.utils.autoreload][autoreload.py:598][INFO][Watching for file changes with StatReloader]
[2020-09-21 14:08:15,412][MainThread:140348418477384][task_id:django.utils.autoreload][autoreload.py:222][INFO][/usr/src/api/api/models.py changed, reloading.]
[2020-09-21 14:08:16,418][MainThread:139687535033672][task_id:django.utils.autoreload][autoreload.py:598][INFO][Watching for file changes with StatReloader]
[2020-09-21 14:09:59,947][MainThread:139687535033672][task_id:django.utils.autoreload][autoreload.py:222][INFO][/usr/src/api/api/models.py changed, reloading.]
[2020-09-21 14:10:00,857][MainThread:139790986935624][task_id:django.utils.autoreload][autoreload.py:598][INFO][Watching for file changes with StatReloader]
