[2020-09-17 12:37:47,536][Thread-6:140657602558752][task_id:django.request][log.py:228][ERROR][Internal Server Error: /api/staffs/1/]
Traceback (most recent call last):
  File "/usr/local/lib/python3.7/site-packages/django/core/handlers/exception.py", line 34, in inner
    response = get_response(request)
  File "/usr/local/lib/python3.7/site-packages/django/core/handlers/base.py", line 115, in _get_response
    response = self.process_exception_by_middleware(e, request)
  File "/usr/local/lib/python3.7/site-packages/django/core/handlers/base.py", line 113, in _get_response
    response = wrapped_callback(request, *callback_args, **callback_kwargs)
  File "/usr/local/lib/python3.7/site-packages/django/views/decorators/csrf.py", line 54, in wrapped_view
    return view_func(*args, **kwargs)
  File "/usr/local/lib/python3.7/site-packages/rest_framework/viewsets.py", line 114, in view
    return self.dispatch(request, *args, **kwargs)
  File "/usr/local/lib/python3.7/site-packages/rest_framework/views.py", line 505, in dispatch
    response = self.handle_exception(exc)
  File "/usr/local/lib/python3.7/site-packages/rest_framework/views.py", line 465, in handle_exception
    self.raise_uncaught_exception(exc)
  File "/usr/local/lib/python3.7/site-packages/rest_framework/views.py", line 476, in raise_uncaught_exception
    raise exc
  File "/usr/local/lib/python3.7/site-packages/rest_framework/views.py", line 493, in dispatch
    self.initial(request, *args, **kwargs)
  File "/usr/local/lib/python3.7/site-packages/rest_framework/views.py", line 410, in initial
    self.perform_authentication(request)
  File "/usr/local/lib/python3.7/site-packages/rest_framework/views.py", line 324, in perform_authentication
    request.user
  File "/usr/local/lib/python3.7/site-packages/rest_framework/request.py", line 220, in user
    self._authenticate()
  File "/usr/local/lib/python3.7/site-packages/rest_framework/request.py", line 373, in _authenticate
    user_auth_tuple = authenticator.authenticate(self)
  File "/usr/src/api/user/authentications.py", line 23, in authenticate
    token = request.headers['authorization']
  File "/usr/local/lib/python3.7/site-packages/django/http/request.py", line 388, in __getitem__
    return super().__getitem__(key.replace('_', '-'))
  File "/usr/local/lib/python3.7/site-packages/django/utils/datastructures.py", line 320, in __getitem__
    return self._store[key.lower()][1]
KeyError: 'authorization'
[2020-09-17 14:32:47,501][Thread-1:140128423938848][task_id:django.request][log.py:228][ERROR][Internal Server Error: /api/orders/ali202000002/]
Traceback (most recent call last):
  File "/usr/local/lib/python3.7/site-packages/django/core/handlers/exception.py", line 34, in inner
    response = get_response(request)
  File "/usr/local/lib/python3.7/site-packages/django/core/handlers/base.py", line 115, in _get_response
    response = self.process_exception_by_middleware(e, request)
  File "/usr/local/lib/python3.7/site-packages/django/core/handlers/base.py", line 113, in _get_response
    response = wrapped_callback(request, *callback_args, **callback_kwargs)
  File "/usr/local/lib/python3.7/site-packages/django/views/decorators/csrf.py", line 54, in wrapped_view
    return view_func(*args, **kwargs)
  File "/usr/local/lib/python3.7/site-packages/rest_framework/viewsets.py", line 114, in view
    return self.dispatch(request, *args, **kwargs)
  File "/usr/local/lib/python3.7/site-packages/rest_framework/views.py", line 505, in dispatch
    response = self.handle_exception(exc)
  File "/usr/local/lib/python3.7/site-packages/rest_framework/views.py", line 465, in handle_exception
    self.raise_uncaught_exception(exc)
  File "/usr/local/lib/python3.7/site-packages/rest_framework/views.py", line 476, in raise_uncaught_exception
    raise exc
  File "/usr/local/lib/python3.7/site-packages/rest_framework/views.py", line 502, in dispatch
    response = handler(request, *args, **kwargs)
  File "/usr/local/lib/python3.7/site-packages/rest_framework/mixins.py", line 82, in partial_update
    return self.update(request, *args, **kwargs)
  File "/usr/local/lib/python3.7/site-packages/rest_framework/mixins.py", line 67, in update
    serializer.is_valid(raise_exception=True)
  File "/usr/local/lib/python3.7/site-packages/rest_framework/serializers.py", line 235, in is_valid
    self._validated_data = self.run_validation(self.initial_data)
  File "/usr/local/lib/python3.7/site-packages/rest_framework/serializers.py", line 430, in run_validation
    value = self.to_internal_value(data)
  File "/usr/local/lib/python3.7/site-packages/rest_framework/serializers.py", line 483, in to_internal_value
    for field in fields:
  File "/usr/local/lib/python3.7/site-packages/rest_framework/serializers.py", line 366, in _writable_fields
    for field in self.fields.values():
  File "/usr/local/lib/python3.7/site-packages/django/utils/functional.py", line 48, in __get__
    res = instance.__dict__[self.name] = self.func(instance)
  File "/usr/local/lib/python3.7/site-packages/rest_framework/serializers.py", line 360, in fields
    for key, value in self.get_fields().items():
  File "/usr/local/lib/python3.7/site-packages/rest_framework/serializers.py", line 1022, in get_fields
    field_names = self.get_field_names(declared_fields, info)
  File "/usr/local/lib/python3.7/site-packages/rest_framework/serializers.py", line 1099, in get_field_names
    serializer_class=self.__class__.__name__
AssertionError: ("Creating a ModelSerializer without either the 'fields' attribute or the 'exclude' attribute has been deprecated since 3.3.0, and is now disallowed. Add an explicit fields = '__all__' to the OrdersSerializer serializer.",)
[2020-09-18 07:12:40,336][Thread-1:139740484573984][task_id:django.request][log.py:228][ERROR][Internal Server Error: /api/orders/]
Traceback (most recent call last):
  File "/usr/local/lib/python3.7/site-packages/django/core/handlers/exception.py", line 34, in inner
    response = get_response(request)
  File "/usr/local/lib/python3.7/site-packages/django/core/handlers/base.py", line 115, in _get_response
    response = self.process_exception_by_middleware(e, request)
  File "/usr/local/lib/python3.7/site-packages/django/core/handlers/base.py", line 113, in _get_response
    response = wrapped_callback(request, *callback_args, **callback_kwargs)
  File "/usr/local/lib/python3.7/site-packages/django/views/decorators/csrf.py", line 54, in wrapped_view
    return view_func(*args, **kwargs)
  File "/usr/local/lib/python3.7/site-packages/rest_framework/viewsets.py", line 114, in view
    return self.dispatch(request, *args, **kwargs)
  File "/usr/local/lib/python3.7/site-packages/rest_framework/views.py", line 505, in dispatch
    response = self.handle_exception(exc)
  File "/usr/local/lib/python3.7/site-packages/rest_framework/views.py", line 465, in handle_exception
    self.raise_uncaught_exception(exc)
  File "/usr/local/lib/python3.7/site-packages/rest_framework/views.py", line 476, in raise_uncaught_exception
    raise exc
  File "/usr/local/lib/python3.7/site-packages/rest_framework/views.py", line 502, in dispatch
    response = handler(request, *args, **kwargs)
  File "/usr/src/api/api/views.py", line 47, in list
    queryset = self.filter_queryset(self.get_queryset())
  File "/usr/src/api/api/views.py", line 43, in get_queryset
    self.queryset['test'] = 'test'
TypeError: 'QuerySet' object does not support item assignment
[2020-09-18 07:13:46,906][Thread-1:139998398122784][task_id:django.request][log.py:228][ERROR][Internal Server Error: /api/orders/]
Traceback (most recent call last):
  File "/usr/local/lib/python3.7/site-packages/django/core/handlers/exception.py", line 34, in inner
    response = get_response(request)
  File "/usr/local/lib/python3.7/site-packages/django/core/handlers/base.py", line 115, in _get_response
    response = self.process_exception_by_middleware(e, request)
  File "/usr/local/lib/python3.7/site-packages/django/core/handlers/base.py", line 113, in _get_response
    response = wrapped_callback(request, *callback_args, **callback_kwargs)
  File "/usr/local/lib/python3.7/site-packages/django/views/decorators/csrf.py", line 54, in wrapped_view
    return view_func(*args, **kwargs)
  File "/usr/local/lib/python3.7/site-packages/rest_framework/viewsets.py", line 114, in view
    return self.dispatch(request, *args, **kwargs)
  File "/usr/local/lib/python3.7/site-packages/rest_framework/views.py", line 505, in dispatch
    response = self.handle_exception(exc)
  File "/usr/local/lib/python3.7/site-packages/rest_framework/views.py", line 465, in handle_exception
    self.raise_uncaught_exception(exc)
  File "/usr/local/lib/python3.7/site-packages/rest_framework/views.py", line 476, in raise_uncaught_exception
    raise exc
  File "/usr/local/lib/python3.7/site-packages/rest_framework/views.py", line 502, in dispatch
    response = handler(request, *args, **kwargs)
  File "/usr/src/api/api/views.py", line 60, in list
    serializer.data['test'] = 'test'
TypeError: list indices must be integers or slices, not str
[2020-09-18 07:16:00,012][Thread-1:140428087601952][task_id:django.request][log.py:228][ERROR][Internal Server Error: /api/orders/]
Traceback (most recent call last):
  File "/usr/local/lib/python3.7/site-packages/django/core/handlers/exception.py", line 34, in inner
    response = get_response(request)
  File "/usr/local/lib/python3.7/site-packages/django/core/handlers/base.py", line 115, in _get_response
    response = self.process_exception_by_middleware(e, request)
  File "/usr/local/lib/python3.7/site-packages/django/core/handlers/base.py", line 113, in _get_response
    response = wrapped_callback(request, *callback_args, **callback_kwargs)
  File "/usr/local/lib/python3.7/site-packages/django/views/decorators/csrf.py", line 54, in wrapped_view
    return view_func(*args, **kwargs)
  File "/usr/local/lib/python3.7/site-packages/rest_framework/viewsets.py", line 114, in view
    return self.dispatch(request, *args, **kwargs)
  File "/usr/local/lib/python3.7/site-packages/rest_framework/views.py", line 505, in dispatch
    response = self.handle_exception(exc)
  File "/usr/local/lib/python3.7/site-packages/rest_framework/views.py", line 465, in handle_exception
    self.raise_uncaught_exception(exc)
  File "/usr/local/lib/python3.7/site-packages/rest_framework/views.py", line 476, in raise_uncaught_exception
    raise exc
  File "/usr/local/lib/python3.7/site-packages/rest_framework/views.py", line 502, in dispatch
    response = handler(request, *args, **kwargs)
  File "/usr/src/api/api/views.py", line 60, in list
    return self.get_paginated_response(serializer.data)
  File "/usr/local/lib/python3.7/site-packages/rest_framework/serializers.py", line 757, in data
    ret = super().data
  File "/usr/local/lib/python3.7/site-packages/rest_framework/serializers.py", line 261, in data
    self._data = self.to_representation(self.instance)
  File "/usr/local/lib/python3.7/site-packages/rest_framework/serializers.py", line 675, in to_representation
    self.child.to_representation(item) for item in iterable
  File "/usr/local/lib/python3.7/site-packages/rest_framework/serializers.py", line 675, in <listcomp>
    self.child.to_representation(item) for item in iterable
  File "/usr/local/lib/python3.7/site-packages/rest_framework/serializers.py", line 513, in to_representation
    attribute = field.get_attribute(instance)
  File "/usr/local/lib/python3.7/site-packages/rest_framework/relations.py", line 529, in get_attribute
    relationship = get_attribute(instance, self.source_attrs)
  File "/usr/local/lib/python3.7/site-packages/rest_framework/fields.py", line 93, in get_attribute
    instance = getattr(instance, attr)
AttributeError: 'OrderCatalog' object has no attribute 'sub_order'
[2020-09-18 07:17:19,243][Thread-1:140222996794144][task_id:django.request][log.py:228][ERROR][Internal Server Error: /api/orders/]
Traceback (most recent call last):
  File "/usr/local/lib/python3.7/site-packages/django/core/handlers/exception.py", line 34, in inner
    response = get_response(request)
  File "/usr/local/lib/python3.7/site-packages/django/core/handlers/base.py", line 115, in _get_response
    response = self.process_exception_by_middleware(e, request)
  File "/usr/local/lib/python3.7/site-packages/django/core/handlers/base.py", line 113, in _get_response
    response = wrapped_callback(request, *callback_args, **callback_kwargs)
  File "/usr/local/lib/python3.7/site-packages/django/views/decorators/csrf.py", line 54, in wrapped_view
    return view_func(*args, **kwargs)
  File "/usr/local/lib/python3.7/site-packages/rest_framework/viewsets.py", line 114, in view
    return self.dispatch(request, *args, **kwargs)
  File "/usr/local/lib/python3.7/site-packages/rest_framework/views.py", line 505, in dispatch
    response = self.handle_exception(exc)
  File "/usr/local/lib/python3.7/site-packages/rest_framework/views.py", line 465, in handle_exception
    self.raise_uncaught_exception(exc)
  File "/usr/local/lib/python3.7/site-packages/rest_framework/views.py", line 476, in raise_uncaught_exception
    raise exc
  File "/usr/local/lib/python3.7/site-packages/rest_framework/views.py", line 502, in dispatch
    response = handler(request, *args, **kwargs)
  File "/usr/src/api/api/views.py", line 60, in list
    return self.get_paginated_response(serializer.data)
  File "/usr/local/lib/python3.7/site-packages/rest_framework/serializers.py", line 757, in data
    ret = super().data
  File "/usr/local/lib/python3.7/site-packages/rest_framework/serializers.py", line 261, in data
    self._data = self.to_representation(self.instance)
  File "/usr/local/lib/python3.7/site-packages/rest_framework/serializers.py", line 675, in to_representation
    self.child.to_representation(item) for item in iterable
  File "/usr/local/lib/python3.7/site-packages/rest_framework/serializers.py", line 675, in <listcomp>
    self.child.to_representation(item) for item in iterable
  File "/usr/local/lib/python3.7/site-packages/rest_framework/serializers.py", line 526, in to_representation
    ret[field.field_name] = field.to_representation(attribute)
  File "/usr/local/lib/python3.7/site-packages/rest_framework/relations.py", line 535, in to_representation
    for value in iterable
  File "/usr/local/lib/python3.7/site-packages/rest_framework/relations.py", line 535, in <listcomp>
    for value in iterable
  File "/usr/local/lib/python3.7/site-packages/rest_framework/relations.py", line 460, in to_representation
    return getattr(obj, self.slug_field)
TypeError: getattr(): attribute name must be string
[2020-09-18 17:59:46,281][Thread-1:139743623605024][task_id:django.request][log.py:228][ERROR][Internal Server Error: /api/customer_addr/]
Traceback (most recent call last):
  File "/usr/local/lib/python3.7/site-packages/django/core/handlers/exception.py", line 34, in inner
    response = get_response(request)
  File "/usr/local/lib/python3.7/site-packages/django/core/handlers/base.py", line 115, in _get_response
    response = self.process_exception_by_middleware(e, request)
  File "/usr/local/lib/python3.7/site-packages/django/core/handlers/base.py", line 113, in _get_response
    response = wrapped_callback(request, *callback_args, **callback_kwargs)
  File "/usr/local/lib/python3.7/site-packages/django/views/decorators/csrf.py", line 54, in wrapped_view
    return view_func(*args, **kwargs)
  File "/usr/local/lib/python3.7/site-packages/rest_framework/viewsets.py", line 114, in view
    return self.dispatch(request, *args, **kwargs)
  File "/usr/local/lib/python3.7/site-packages/rest_framework/views.py", line 505, in dispatch
    response = self.handle_exception(exc)
  File "/usr/local/lib/python3.7/site-packages/rest_framework/views.py", line 465, in handle_exception
    self.raise_uncaught_exception(exc)
  File "/usr/local/lib/python3.7/site-packages/rest_framework/views.py", line 476, in raise_uncaught_exception
    raise exc
  File "/usr/local/lib/python3.7/site-packages/rest_framework/views.py", line 502, in dispatch
    response = handler(request, *args, **kwargs)
  File "/usr/local/lib/python3.7/site-packages/rest_framework/mixins.py", line 43, in list
    return self.get_paginated_response(serializer.data)
  File "/usr/local/lib/python3.7/site-packages/rest_framework/serializers.py", line 757, in data
    ret = super().data
  File "/usr/local/lib/python3.7/site-packages/rest_framework/serializers.py", line 261, in data
    self._data = self.to_representation(self.instance)
  File "/usr/local/lib/python3.7/site-packages/rest_framework/serializers.py", line 675, in to_representation
    self.child.to_representation(item) for item in iterable
  File "/usr/local/lib/python3.7/site-packages/rest_framework/serializers.py", line 675, in <listcomp>
    self.child.to_representation(item) for item in iterable
  File "/usr/local/lib/python3.7/site-packages/rest_framework/serializers.py", line 526, in to_representation
    ret[field.field_name] = field.to_representation(attribute)
  File "/usr/local/lib/python3.7/site-packages/rest_framework/fields.py", line 1289, in to_representation
    'Expected a `date`, but got a `datetime`. Refusing to coerce, '
AssertionError: Expected a `date`, but got a `datetime`. Refusing to coerce, as this may mean losing timezone information. Use a custom read-only field and deal with timezone issues explicitly.
[2020-09-20 08:24:20,482][Thread-10:139810435676960][task_id:django.request][log.py:228][ERROR][Internal Server Error: /api/order_model/]
Traceback (most recent call last):
  File "/usr/local/lib/python3.7/site-packages/django/db/backends/utils.py", line 86, in _execute
    return self.cursor.execute(sql, params)
psycopg2.errors.UndefinedColumn: column api_ordermodel.material does not exist
LINE 1: ...api_ordermodel"."number", "api_ordermodel"."atr", "api_order...
                                                             ^


The above exception was the direct cause of the following exception:

Traceback (most recent call last):
  File "/usr/local/lib/python3.7/site-packages/django/core/handlers/exception.py", line 34, in inner
    response = get_response(request)
  File "/usr/local/lib/python3.7/site-packages/django/core/handlers/base.py", line 115, in _get_response
    response = self.process_exception_by_middleware(e, request)
  File "/usr/local/lib/python3.7/site-packages/django/core/handlers/base.py", line 113, in _get_response
    response = wrapped_callback(request, *callback_args, **callback_kwargs)
  File "/usr/local/lib/python3.7/site-packages/django/views/decorators/csrf.py", line 54, in wrapped_view
    return view_func(*args, **kwargs)
  File "/usr/local/lib/python3.7/site-packages/rest_framework/viewsets.py", line 114, in view
    return self.dispatch(request, *args, **kwargs)
  File "/usr/local/lib/python3.7/site-packages/rest_framework/views.py", line 505, in dispatch
    response = self.handle_exception(exc)
  File "/usr/local/lib/python3.7/site-packages/rest_framework/views.py", line 465, in handle_exception
    self.raise_uncaught_exception(exc)
  File "/usr/local/lib/python3.7/site-packages/rest_framework/views.py", line 476, in raise_uncaught_exception
    raise exc
  File "/usr/local/lib/python3.7/site-packages/rest_framework/views.py", line 502, in dispatch
    response = handler(request, *args, **kwargs)
  File "/usr/local/lib/python3.7/site-packages/rest_framework/mixins.py", line 40, in list
    page = self.paginate_queryset(queryset)
  File "/usr/local/lib/python3.7/site-packages/rest_framework/generics.py", line 171, in paginate_queryset
    return self.paginator.paginate_queryset(queryset, self.request, view=self)
  File "/usr/local/lib/python3.7/site-packages/rest_framework/pagination.py", line 218, in paginate_queryset
    return list(self.page)
  File "/usr/local/lib/python3.7/site-packages/django/core/paginator.py", line 150, in __len__
    return len(self.object_list)
  File "/usr/local/lib/python3.7/site-packages/django/db/models/query.py", line 258, in __len__
    self._fetch_all()
  File "/usr/local/lib/python3.7/site-packages/django/db/models/query.py", line 1261, in _fetch_all
    self._result_cache = list(self._iterable_class(self))
  File "/usr/local/lib/python3.7/site-packages/django/db/models/query.py", line 57, in __iter__
    results = compiler.execute_sql(chunked_fetch=self.chunked_fetch, chunk_size=self.chunk_size)
  File "/usr/local/lib/python3.7/site-packages/django/db/models/sql/compiler.py", line 1151, in execute_sql
    cursor.execute(sql, params)
  File "/usr/local/lib/python3.7/site-packages/django/db/backends/utils.py", line 100, in execute
    return super().execute(sql, params)
  File "/usr/local/lib/python3.7/site-packages/django/db/backends/utils.py", line 68, in execute
    return self._execute_with_wrappers(sql, params, many=False, executor=self._execute)
  File "/usr/local/lib/python3.7/site-packages/django/db/backends/utils.py", line 77, in _execute_with_wrappers
    return executor(sql, params, many, context)
  File "/usr/local/lib/python3.7/site-packages/django/db/backends/utils.py", line 86, in _execute
    return self.cursor.execute(sql, params)
  File "/usr/local/lib/python3.7/site-packages/django/db/utils.py", line 90, in __exit__
    raise dj_exc_value.with_traceback(traceback) from exc_value
  File "/usr/local/lib/python3.7/site-packages/django/db/backends/utils.py", line 86, in _execute
    return self.cursor.execute(sql, params)
django.db.utils.ProgrammingError: column api_ordermodel.material does not exist
LINE 1: ...api_ordermodel"."number", "api_ordermodel"."atr", "api_order...
                                                             ^

[2020-09-21 04:52:44,588][Thread-1:139892196641568][task_id:django.request][log.py:228][ERROR][Internal Server Error: /api/staffs/null/]
Traceback (most recent call last):
  File "/usr/local/lib/python3.7/site-packages/rest_framework/request.py", line 74, in wrap_attributeerrors
    yield
  File "/usr/local/lib/python3.7/site-packages/rest_framework/request.py", line 220, in user
    self._authenticate()
  File "/usr/local/lib/python3.7/site-packages/rest_framework/request.py", line 373, in _authenticate
    user_auth_tuple = authenticator.authenticate(self)
  File "/usr/src/api/user/authentications.py", line 25, in authenticate
    if token and user.is_use == 1:
AttributeError: 'NoneType' object has no attribute 'is_use'

During handling of the above exception, another exception occurred:

Traceback (most recent call last):
  File "/usr/local/lib/python3.7/site-packages/django/core/handlers/exception.py", line 34, in inner
    response = get_response(request)
  File "/usr/local/lib/python3.7/site-packages/django/core/handlers/base.py", line 115, in _get_response
    response = self.process_exception_by_middleware(e, request)
  File "/usr/local/lib/python3.7/site-packages/django/core/handlers/base.py", line 113, in _get_response
    response = wrapped_callback(request, *callback_args, **callback_kwargs)
  File "/usr/local/lib/python3.7/site-packages/django/views/decorators/csrf.py", line 54, in wrapped_view
    return view_func(*args, **kwargs)
  File "/usr/local/lib/python3.7/site-packages/rest_framework/viewsets.py", line 114, in view
    return self.dispatch(request, *args, **kwargs)
  File "/usr/local/lib/python3.7/site-packages/rest_framework/views.py", line 505, in dispatch
    response = self.handle_exception(exc)
  File "/usr/local/lib/python3.7/site-packages/rest_framework/views.py", line 465, in handle_exception
    self.raise_uncaught_exception(exc)
  File "/usr/local/lib/python3.7/site-packages/rest_framework/views.py", line 476, in raise_uncaught_exception
    raise exc
  File "/usr/local/lib/python3.7/site-packages/rest_framework/views.py", line 493, in dispatch
    self.initial(request, *args, **kwargs)
  File "/usr/local/lib/python3.7/site-packages/rest_framework/views.py", line 410, in initial
    self.perform_authentication(request)
  File "/usr/local/lib/python3.7/site-packages/rest_framework/views.py", line 324, in perform_authentication
    request.user
  File "/usr/local/lib/python3.7/site-packages/rest_framework/request.py", line 220, in user
    self._authenticate()
  File "/usr/local/lib/python3.7/contextlib.py", line 130, in __exit__
    self.gen.throw(type, value, traceback)
  File "/usr/local/lib/python3.7/site-packages/rest_framework/request.py", line 78, in wrap_attributeerrors
    raise exc.with_traceback(info[2])
  File "/usr/local/lib/python3.7/site-packages/rest_framework/request.py", line 74, in wrap_attributeerrors
    yield
  File "/usr/local/lib/python3.7/site-packages/rest_framework/request.py", line 220, in user
    self._authenticate()
  File "/usr/local/lib/python3.7/site-packages/rest_framework/request.py", line 373, in _authenticate
    user_auth_tuple = authenticator.authenticate(self)
  File "/usr/src/api/user/authentications.py", line 25, in authenticate
    if token and user.is_use == 1:
rest_framework.request.WrappedAttributeError: 'NoneType' object has no attribute 'is_use'
[2020-09-21 04:53:39,800][Thread-1:139892196641568][task_id:django.request][log.py:228][ERROR][Internal Server Error: /api/staffs/null/]
Traceback (most recent call last):
  File "/usr/local/lib/python3.7/site-packages/rest_framework/request.py", line 74, in wrap_attributeerrors
    yield
  File "/usr/local/lib/python3.7/site-packages/rest_framework/request.py", line 220, in user
    self._authenticate()
  File "/usr/local/lib/python3.7/site-packages/rest_framework/request.py", line 373, in _authenticate
    user_auth_tuple = authenticator.authenticate(self)
  File "/usr/src/api/user/authentications.py", line 25, in authenticate
    if token and user.is_use == 1:
AttributeError: 'NoneType' object has no attribute 'is_use'

During handling of the above exception, another exception occurred:

Traceback (most recent call last):
  File "/usr/local/lib/python3.7/site-packages/django/core/handlers/exception.py", line 34, in inner
    response = get_response(request)
  File "/usr/local/lib/python3.7/site-packages/django/core/handlers/base.py", line 115, in _get_response
    response = self.process_exception_by_middleware(e, request)
  File "/usr/local/lib/python3.7/site-packages/django/core/handlers/base.py", line 113, in _get_response
    response = wrapped_callback(request, *callback_args, **callback_kwargs)
  File "/usr/local/lib/python3.7/site-packages/django/views/decorators/csrf.py", line 54, in wrapped_view
    return view_func(*args, **kwargs)
  File "/usr/local/lib/python3.7/site-packages/rest_framework/viewsets.py", line 114, in view
    return self.dispatch(request, *args, **kwargs)
  File "/usr/local/lib/python3.7/site-packages/rest_framework/views.py", line 505, in dispatch
    response = self.handle_exception(exc)
  File "/usr/local/lib/python3.7/site-packages/rest_framework/views.py", line 465, in handle_exception
    self.raise_uncaught_exception(exc)
  File "/usr/local/lib/python3.7/site-packages/rest_framework/views.py", line 476, in raise_uncaught_exception
    raise exc
  File "/usr/local/lib/python3.7/site-packages/rest_framework/views.py", line 493, in dispatch
    self.initial(request, *args, **kwargs)
  File "/usr/local/lib/python3.7/site-packages/rest_framework/views.py", line 410, in initial
    self.perform_authentication(request)
  File "/usr/local/lib/python3.7/site-packages/rest_framework/views.py", line 324, in perform_authentication
    request.user
  File "/usr/local/lib/python3.7/site-packages/rest_framework/request.py", line 220, in user
    self._authenticate()
  File "/usr/local/lib/python3.7/contextlib.py", line 130, in __exit__
    self.gen.throw(type, value, traceback)
  File "/usr/local/lib/python3.7/site-packages/rest_framework/request.py", line 78, in wrap_attributeerrors
    raise exc.with_traceback(info[2])
  File "/usr/local/lib/python3.7/site-packages/rest_framework/request.py", line 74, in wrap_attributeerrors
    yield
  File "/usr/local/lib/python3.7/site-packages/rest_framework/request.py", line 220, in user
    self._authenticate()
  File "/usr/local/lib/python3.7/site-packages/rest_framework/request.py", line 373, in _authenticate
    user_auth_tuple = authenticator.authenticate(self)
  File "/usr/src/api/user/authentications.py", line 25, in authenticate
    if token and user.is_use == 1:
rest_framework.request.WrappedAttributeError: 'NoneType' object has no attribute 'is_use'
[2020-09-21 04:54:39,317][Thread-1:139892196641568][task_id:django.request][log.py:228][ERROR][Internal Server Error: /api/customer_addr/]
Traceback (most recent call last):
  File "/usr/local/lib/python3.7/site-packages/django/db/backends/utils.py", line 86, in _execute
    return self.cursor.execute(sql, params)
psycopg2.errors.UndefinedTable: relation "api_customeraddr" does not exist
LINE 1: SELECT COUNT(*) AS "__count" FROM "api_customeraddr" WHERE "...
                                          ^


The above exception was the direct cause of the following exception:

Traceback (most recent call last):
  File "/usr/local/lib/python3.7/site-packages/django/core/handlers/exception.py", line 34, in inner
    response = get_response(request)
  File "/usr/local/lib/python3.7/site-packages/django/core/handlers/base.py", line 115, in _get_response
    response = self.process_exception_by_middleware(e, request)
  File "/usr/local/lib/python3.7/site-packages/django/core/handlers/base.py", line 113, in _get_response
    response = wrapped_callback(request, *callback_args, **callback_kwargs)
  File "/usr/local/lib/python3.7/site-packages/django/views/decorators/csrf.py", line 54, in wrapped_view
    return view_func(*args, **kwargs)
  File "/usr/local/lib/python3.7/site-packages/rest_framework/viewsets.py", line 114, in view
    return self.dispatch(request, *args, **kwargs)
  File "/usr/local/lib/python3.7/site-packages/rest_framework/views.py", line 505, in dispatch
    response = self.handle_exception(exc)
  File "/usr/local/lib/python3.7/site-packages/rest_framework/views.py", line 465, in handle_exception
    self.raise_uncaught_exception(exc)
  File "/usr/local/lib/python3.7/site-packages/rest_framework/views.py", line 476, in raise_uncaught_exception
    raise exc
  File "/usr/local/lib/python3.7/site-packages/rest_framework/views.py", line 502, in dispatch
    response = handler(request, *args, **kwargs)
  File "/usr/local/lib/python3.7/site-packages/rest_framework/mixins.py", line 40, in list
    page = self.paginate_queryset(queryset)
  File "/usr/local/lib/python3.7/site-packages/rest_framework/generics.py", line 171, in paginate_queryset
    return self.paginator.paginate_queryset(queryset, self.request, view=self)
  File "/usr/local/lib/python3.7/site-packages/rest_framework/pagination.py", line 206, in paginate_queryset
    self.page = paginator.page(page_number)
  File "/usr/local/lib/python3.7/site-packages/django/core/paginator.py", line 70, in page
    number = self.validate_number(number)
  File "/usr/local/lib/python3.7/site-packages/django/core/paginator.py", line 48, in validate_number
    if number > self.num_pages:
  File "/usr/local/lib/python3.7/site-packages/django/utils/functional.py", line 48, in __get__
    res = instance.__dict__[self.name] = self.func(instance)
  File "/usr/local/lib/python3.7/site-packages/django/core/paginator.py", line 97, in num_pages
    if self.count == 0 and not self.allow_empty_first_page:
  File "/usr/local/lib/python3.7/site-packages/django/utils/functional.py", line 48, in __get__
    res = instance.__dict__[self.name] = self.func(instance)
  File "/usr/local/lib/python3.7/site-packages/django/core/paginator.py", line 91, in count
    return c()
  File "/usr/local/lib/python3.7/site-packages/django/db/models/query.py", line 397, in count
    return self.query.get_count(using=self.db)
  File "/usr/local/lib/python3.7/site-packages/django/db/models/sql/query.py", line 517, in get_count
    number = obj.get_aggregation(using, ['__count'])['__count']
  File "/usr/local/lib/python3.7/site-packages/django/db/models/sql/query.py", line 502, in get_aggregation
    result = compiler.execute_sql(SINGLE)
  File "/usr/local/lib/python3.7/site-packages/django/db/models/sql/compiler.py", line 1151, in execute_sql
    cursor.execute(sql, params)
  File "/usr/local/lib/python3.7/site-packages/django/db/backends/utils.py", line 100, in execute
    return super().execute(sql, params)
  File "/usr/local/lib/python3.7/site-packages/django/db/backends/utils.py", line 68, in execute
    return self._execute_with_wrappers(sql, params, many=False, executor=self._execute)
  File "/usr/local/lib/python3.7/site-packages/django/db/backends/utils.py", line 77, in _execute_with_wrappers
    return executor(sql, params, many, context)
  File "/usr/local/lib/python3.7/site-packages/django/db/backends/utils.py", line 86, in _execute
    return self.cursor.execute(sql, params)
  File "/usr/local/lib/python3.7/site-packages/django/db/utils.py", line 90, in __exit__
    raise dj_exc_value.with_traceback(traceback) from exc_value
  File "/usr/local/lib/python3.7/site-packages/django/db/backends/utils.py", line 86, in _execute
    return self.cursor.execute(sql, params)
django.db.utils.ProgrammingError: relation "api_customeraddr" does not exist
LINE 1: SELECT COUNT(*) AS "__count" FROM "api_customeraddr" WHERE "...
                                          ^

[2020-09-21 04:54:51,929][Thread-1:139892196641568][task_id:django.request][log.py:228][ERROR][Internal Server Error: /api/customer_addr/]
Traceback (most recent call last):
  File "/usr/local/lib/python3.7/site-packages/django/db/backends/utils.py", line 86, in _execute
    return self.cursor.execute(sql, params)
psycopg2.errors.UndefinedTable: relation "api_customeraddr" does not exist
LINE 1: SELECT COUNT(*) AS "__count" FROM "api_customeraddr" WHERE "...
                                          ^


The above exception was the direct cause of the following exception:

Traceback (most recent call last):
  File "/usr/local/lib/python3.7/site-packages/django/core/handlers/exception.py", line 34, in inner
    response = get_response(request)
  File "/usr/local/lib/python3.7/site-packages/django/core/handlers/base.py", line 115, in _get_response
    response = self.process_exception_by_middleware(e, request)
  File "/usr/local/lib/python3.7/site-packages/django/core/handlers/base.py", line 113, in _get_response
    response = wrapped_callback(request, *callback_args, **callback_kwargs)
  File "/usr/local/lib/python3.7/site-packages/django/views/decorators/csrf.py", line 54, in wrapped_view
    return view_func(*args, **kwargs)
  File "/usr/local/lib/python3.7/site-packages/rest_framework/viewsets.py", line 114, in view
    return self.dispatch(request, *args, **kwargs)
  File "/usr/local/lib/python3.7/site-packages/rest_framework/views.py", line 505, in dispatch
    response = self.handle_exception(exc)
  File "/usr/local/lib/python3.7/site-packages/rest_framework/views.py", line 465, in handle_exception
    self.raise_uncaught_exception(exc)
  File "/usr/local/lib/python3.7/site-packages/rest_framework/views.py", line 476, in raise_uncaught_exception
    raise exc
  File "/usr/local/lib/python3.7/site-packages/rest_framework/views.py", line 502, in dispatch
    response = handler(request, *args, **kwargs)
  File "/usr/local/lib/python3.7/site-packages/rest_framework/mixins.py", line 40, in list
    page = self.paginate_queryset(queryset)
  File "/usr/local/lib/python3.7/site-packages/rest_framework/generics.py", line 171, in paginate_queryset
    return self.paginator.paginate_queryset(queryset, self.request, view=self)
  File "/usr/local/lib/python3.7/site-packages/rest_framework/pagination.py", line 206, in paginate_queryset
    self.page = paginator.page(page_number)
  File "/usr/local/lib/python3.7/site-packages/django/core/paginator.py", line 70, in page
    number = self.validate_number(number)
  File "/usr/local/lib/python3.7/site-packages/django/core/paginator.py", line 48, in validate_number
    if number > self.num_pages:
  File "/usr/local/lib/python3.7/site-packages/django/utils/functional.py", line 48, in __get__
    res = instance.__dict__[self.name] = self.func(instance)
  File "/usr/local/lib/python3.7/site-packages/django/core/paginator.py", line 97, in num_pages
    if self.count == 0 and not self.allow_empty_first_page:
  File "/usr/local/lib/python3.7/site-packages/django/utils/functional.py", line 48, in __get__
    res = instance.__dict__[self.name] = self.func(instance)
  File "/usr/local/lib/python3.7/site-packages/django/core/paginator.py", line 91, in count
    return c()
  File "/usr/local/lib/python3.7/site-packages/django/db/models/query.py", line 397, in count
    return self.query.get_count(using=self.db)
  File "/usr/local/lib/python3.7/site-packages/django/db/models/sql/query.py", line 517, in get_count
    number = obj.get_aggregation(using, ['__count'])['__count']
  File "/usr/local/lib/python3.7/site-packages/django/db/models/sql/query.py", line 502, in get_aggregation
    result = compiler.execute_sql(SINGLE)
  File "/usr/local/lib/python3.7/site-packages/django/db/models/sql/compiler.py", line 1151, in execute_sql
    cursor.execute(sql, params)
  File "/usr/local/lib/python3.7/site-packages/django/db/backends/utils.py", line 100, in execute
    return super().execute(sql, params)
  File "/usr/local/lib/python3.7/site-packages/django/db/backends/utils.py", line 68, in execute
    return self._execute_with_wrappers(sql, params, many=False, executor=self._execute)
  File "/usr/local/lib/python3.7/site-packages/django/db/backends/utils.py", line 77, in _execute_with_wrappers
    return executor(sql, params, many, context)
  File "/usr/local/lib/python3.7/site-packages/django/db/backends/utils.py", line 86, in _execute
    return self.cursor.execute(sql, params)
  File "/usr/local/lib/python3.7/site-packages/django/db/utils.py", line 90, in __exit__
    raise dj_exc_value.with_traceback(traceback) from exc_value
  File "/usr/local/lib/python3.7/site-packages/django/db/backends/utils.py", line 86, in _execute
    return self.cursor.execute(sql, params)
django.db.utils.ProgrammingError: relation "api_customeraddr" does not exist
LINE 1: SELECT COUNT(*) AS "__count" FROM "api_customeraddr" WHERE "...
                                          ^

[2020-09-21 05:48:12,318][Thread-2:140067346877216][task_id:django.request][log.py:228][ERROR][Internal Server Error: /api/order_model/]
Traceback (most recent call last):
  File "/usr/local/lib/python3.7/site-packages/django/db/models/base.py", line 466, in __init__
    val = kwargs.pop(field.attname)
KeyError: 'number'

During handling of the above exception, another exception occurred:

Traceback (most recent call last):
  File "/usr/local/lib/python3.7/site-packages/django/core/handlers/exception.py", line 34, in inner
    response = get_response(request)
  File "/usr/local/lib/python3.7/site-packages/django/core/handlers/base.py", line 115, in _get_response
    response = self.process_exception_by_middleware(e, request)
  File "/usr/local/lib/python3.7/site-packages/django/core/handlers/base.py", line 113, in _get_response
    response = wrapped_callback(request, *callback_args, **callback_kwargs)
  File "/usr/local/lib/python3.7/site-packages/django/views/decorators/csrf.py", line 54, in wrapped_view
    return view_func(*args, **kwargs)
  File "/usr/local/lib/python3.7/site-packages/rest_framework/viewsets.py", line 114, in view
    return self.dispatch(request, *args, **kwargs)
  File "/usr/local/lib/python3.7/site-packages/rest_framework/views.py", line 505, in dispatch
    response = self.handle_exception(exc)
  File "/usr/local/lib/python3.7/site-packages/rest_framework/views.py", line 465, in handle_exception
    self.raise_uncaught_exception(exc)
  File "/usr/local/lib/python3.7/site-packages/rest_framework/views.py", line 476, in raise_uncaught_exception
    raise exc
  File "/usr/local/lib/python3.7/site-packages/rest_framework/views.py", line 502, in dispatch
    response = handler(request, *args, **kwargs)
  File "/usr/local/lib/python3.7/site-packages/rest_framework/mixins.py", line 19, in create
    self.perform_create(serializer)
  File "/usr/local/lib/python3.7/site-packages/rest_framework/mixins.py", line 24, in perform_create
    serializer.save()
  File "/usr/local/lib/python3.7/site-packages/rest_framework/serializers.py", line 213, in save
    self.instance = self.create(validated_data)
  File "/usr/local/lib/python3.7/site-packages/rest_framework/serializers.py", line 932, in create
    instance = ModelClass._default_manager.create(**validated_data)
  File "/usr/local/lib/python3.7/site-packages/django/db/models/manager.py", line 82, in manager_method
    return getattr(self.get_queryset(), name)(*args, **kwargs)
  File "/usr/local/lib/python3.7/site-packages/django/db/models/query.py", line 431, in create
    obj = self.model(**kwargs)
  File "/usr/local/lib/python3.7/site-packages/django/db/models/base.py", line 472, in __init__
    val = field.get_default()
  File "/usr/local/lib/python3.7/site-packages/django/db/models/fields/__init__.py", line 829, in get_default
    return self._get_default()
  File "/usr/src/api/api/models.py", line 157, in make_model_number
    now_id = OrderModel.objects.latest().id + 1
  File "/usr/local/lib/python3.7/site-packages/django/db/models/manager.py", line 82, in manager_method
    return getattr(self.get_queryset(), name)(*args, **kwargs)
  File "/usr/local/lib/python3.7/site-packages/django/db/models/query.py", line 660, in latest
    return self.reverse()._earliest(*fields)
  File "/usr/local/lib/python3.7/site-packages/django/db/models/query.py", line 644, in _earliest
    "earliest() and latest() require either fields as positional "
ValueError: earliest() and latest() require either fields as positional arguments or 'get_latest_by' in the model's Meta.
[2020-09-21 05:51:07,671][Thread-1:139866264955680][task_id:django.request][log.py:228][ERROR][Internal Server Error: /api/order_model/]
Traceback (most recent call last):
  File "/usr/local/lib/python3.7/site-packages/django/db/models/base.py", line 466, in __init__
    val = kwargs.pop(field.attname)
KeyError: 'number'

During handling of the above exception, another exception occurred:

Traceback (most recent call last):
  File "/usr/local/lib/python3.7/site-packages/django/core/handlers/exception.py", line 34, in inner
    response = get_response(request)
  File "/usr/local/lib/python3.7/site-packages/django/core/handlers/base.py", line 115, in _get_response
    response = self.process_exception_by_middleware(e, request)
  File "/usr/local/lib/python3.7/site-packages/django/core/handlers/base.py", line 113, in _get_response
    response = wrapped_callback(request, *callback_args, **callback_kwargs)
  File "/usr/local/lib/python3.7/site-packages/django/views/decorators/csrf.py", line 54, in wrapped_view
    return view_func(*args, **kwargs)
  File "/usr/local/lib/python3.7/site-packages/rest_framework/viewsets.py", line 114, in view
    return self.dispatch(request, *args, **kwargs)
  File "/usr/local/lib/python3.7/site-packages/rest_framework/views.py", line 505, in dispatch
    response = self.handle_exception(exc)
  File "/usr/local/lib/python3.7/site-packages/rest_framework/views.py", line 465, in handle_exception
    self.raise_uncaught_exception(exc)
  File "/usr/local/lib/python3.7/site-packages/rest_framework/views.py", line 476, in raise_uncaught_exception
    raise exc
  File "/usr/local/lib/python3.7/site-packages/rest_framework/views.py", line 502, in dispatch
    response = handler(request, *args, **kwargs)
  File "/usr/local/lib/python3.7/site-packages/rest_framework/mixins.py", line 19, in create
    self.perform_create(serializer)
  File "/usr/local/lib/python3.7/site-packages/rest_framework/mixins.py", line 24, in perform_create
    serializer.save()
  File "/usr/local/lib/python3.7/site-packages/rest_framework/serializers.py", line 213, in save
    self.instance = self.create(validated_data)
  File "/usr/local/lib/python3.7/site-packages/rest_framework/serializers.py", line 932, in create
    instance = ModelClass._default_manager.create(**validated_data)
  File "/usr/local/lib/python3.7/site-packages/django/db/models/manager.py", line 82, in manager_method
    return getattr(self.get_queryset(), name)(*args, **kwargs)
  File "/usr/local/lib/python3.7/site-packages/django/db/models/query.py", line 431, in create
    obj = self.model(**kwargs)
  File "/usr/local/lib/python3.7/site-packages/django/db/models/base.py", line 472, in __init__
    val = field.get_default()
  File "/usr/local/lib/python3.7/site-packages/django/db/models/fields/__init__.py", line 829, in get_default
    return self._get_default()
  File "/usr/src/api/api/models.py", line 157, in make_model_number
    now_id = OrderModel.objects.latest().id + 1
  File "/usr/local/lib/python3.7/site-packages/django/db/models/manager.py", line 82, in manager_method
    return getattr(self.get_queryset(), name)(*args, **kwargs)
  File "/usr/local/lib/python3.7/site-packages/django/db/models/query.py", line 660, in latest
    return self.reverse()._earliest(*fields)
  File "/usr/local/lib/python3.7/site-packages/django/db/models/query.py", line 644, in _earliest
    "earliest() and latest() require either fields as positional "
ValueError: earliest() and latest() require either fields as positional arguments or 'get_latest_by' in the model's Meta.
[2020-09-21 05:52:00,414][Thread-1:139755590810400][task_id:django.request][log.py:228][ERROR][Internal Server Error: /api/order_model/]
Traceback (most recent call last):
  File "/usr/local/lib/python3.7/site-packages/django/db/models/base.py", line 466, in __init__
    val = kwargs.pop(field.attname)
KeyError: 'number'

During handling of the above exception, another exception occurred:

Traceback (most recent call last):
  File "/usr/local/lib/python3.7/site-packages/django/core/handlers/exception.py", line 34, in inner
    response = get_response(request)
  File "/usr/local/lib/python3.7/site-packages/django/core/handlers/base.py", line 115, in _get_response
    response = self.process_exception_by_middleware(e, request)
  File "/usr/local/lib/python3.7/site-packages/django/core/handlers/base.py", line 113, in _get_response
    response = wrapped_callback(request, *callback_args, **callback_kwargs)
  File "/usr/local/lib/python3.7/site-packages/django/views/decorators/csrf.py", line 54, in wrapped_view
    return view_func(*args, **kwargs)
  File "/usr/local/lib/python3.7/site-packages/rest_framework/viewsets.py", line 114, in view
    return self.dispatch(request, *args, **kwargs)
  File "/usr/local/lib/python3.7/site-packages/rest_framework/views.py", line 505, in dispatch
    response = self.handle_exception(exc)
  File "/usr/local/lib/python3.7/site-packages/rest_framework/views.py", line 465, in handle_exception
    self.raise_uncaught_exception(exc)
  File "/usr/local/lib/python3.7/site-packages/rest_framework/views.py", line 476, in raise_uncaught_exception
    raise exc
  File "/usr/local/lib/python3.7/site-packages/rest_framework/views.py", line 502, in dispatch
    response = handler(request, *args, **kwargs)
  File "/usr/local/lib/python3.7/site-packages/rest_framework/mixins.py", line 19, in create
    self.perform_create(serializer)
  File "/usr/local/lib/python3.7/site-packages/rest_framework/mixins.py", line 24, in perform_create
    serializer.save()
  File "/usr/local/lib/python3.7/site-packages/rest_framework/serializers.py", line 213, in save
    self.instance = self.create(validated_data)
  File "/usr/local/lib/python3.7/site-packages/rest_framework/serializers.py", line 932, in create
    instance = ModelClass._default_manager.create(**validated_data)
  File "/usr/local/lib/python3.7/site-packages/django/db/models/manager.py", line 82, in manager_method
    return getattr(self.get_queryset(), name)(*args, **kwargs)
  File "/usr/local/lib/python3.7/site-packages/django/db/models/query.py", line 431, in create
    obj = self.model(**kwargs)
  File "/usr/local/lib/python3.7/site-packages/django/db/models/base.py", line 472, in __init__
    val = field.get_default()
  File "/usr/local/lib/python3.7/site-packages/django/db/models/fields/__init__.py", line 829, in get_default
    return self._get_default()
  File "/usr/src/api/api/models.py", line 157, in make_model_number
    now_id = OrderModel.objects.last().id + 1
AttributeError: 'NoneType' object has no attribute 'id'
[2020-09-21 05:52:23,348][Thread-1:139879077395232][task_id:django.request][log.py:228][ERROR][Internal Server Error: /api/order_model/]
Traceback (most recent call last):
  File "/usr/local/lib/python3.7/site-packages/django/db/models/base.py", line 466, in __init__
    val = kwargs.pop(field.attname)
KeyError: 'number'

During handling of the above exception, another exception occurred:

Traceback (most recent call last):
  File "/usr/local/lib/python3.7/site-packages/django/core/handlers/exception.py", line 34, in inner
    response = get_response(request)
  File "/usr/local/lib/python3.7/site-packages/django/core/handlers/base.py", line 115, in _get_response
    response = self.process_exception_by_middleware(e, request)
  File "/usr/local/lib/python3.7/site-packages/django/core/handlers/base.py", line 113, in _get_response
    response = wrapped_callback(request, *callback_args, **callback_kwargs)
  File "/usr/local/lib/python3.7/site-packages/django/views/decorators/csrf.py", line 54, in wrapped_view
    return view_func(*args, **kwargs)
  File "/usr/local/lib/python3.7/site-packages/rest_framework/viewsets.py", line 114, in view
    return self.dispatch(request, *args, **kwargs)
  File "/usr/local/lib/python3.7/site-packages/rest_framework/views.py", line 505, in dispatch
    response = self.handle_exception(exc)
  File "/usr/local/lib/python3.7/site-packages/rest_framework/views.py", line 465, in handle_exception
    self.raise_uncaught_exception(exc)
  File "/usr/local/lib/python3.7/site-packages/rest_framework/views.py", line 476, in raise_uncaught_exception
    raise exc
  File "/usr/local/lib/python3.7/site-packages/rest_framework/views.py", line 502, in dispatch
    response = handler(request, *args, **kwargs)
  File "/usr/local/lib/python3.7/site-packages/rest_framework/mixins.py", line 19, in create
    self.perform_create(serializer)
  File "/usr/local/lib/python3.7/site-packages/rest_framework/mixins.py", line 24, in perform_create
    serializer.save()
  File "/usr/local/lib/python3.7/site-packages/rest_framework/serializers.py", line 213, in save
    self.instance = self.create(validated_data)
  File "/usr/local/lib/python3.7/site-packages/rest_framework/serializers.py", line 932, in create
    instance = ModelClass._default_manager.create(**validated_data)
  File "/usr/local/lib/python3.7/site-packages/django/db/models/manager.py", line 82, in manager_method
    return getattr(self.get_queryset(), name)(*args, **kwargs)
  File "/usr/local/lib/python3.7/site-packages/django/db/models/query.py", line 431, in create
    obj = self.model(**kwargs)
  File "/usr/local/lib/python3.7/site-packages/django/db/models/base.py", line 472, in __init__
    val = field.get_default()
  File "/usr/local/lib/python3.7/site-packages/django/db/models/fields/__init__.py", line 829, in get_default
    return self._get_default()
  File "/usr/src/api/api/models.py", line 157, in make_model_number
    now_id = OrderModel.objects.last().id + 1
AttributeError: 'NoneType' object has no attribute 'id'
[2020-09-21 06:04:09,494][Thread-1:140593648626464][task_id:django.request][log.py:228][ERROR][Internal Server Error: /api/order_model/]
Traceback (most recent call last):
  File "/usr/local/lib/python3.7/site-packages/django/core/handlers/exception.py", line 34, in inner
    response = get_response(request)
  File "/usr/local/lib/python3.7/site-packages/django/core/handlers/base.py", line 115, in _get_response
    response = self.process_exception_by_middleware(e, request)
  File "/usr/local/lib/python3.7/site-packages/django/core/handlers/base.py", line 113, in _get_response
    response = wrapped_callback(request, *callback_args, **callback_kwargs)
  File "/usr/local/lib/python3.7/site-packages/django/views/decorators/csrf.py", line 54, in wrapped_view
    return view_func(*args, **kwargs)
  File "/usr/local/lib/python3.7/site-packages/rest_framework/viewsets.py", line 114, in view
    return self.dispatch(request, *args, **kwargs)
  File "/usr/local/lib/python3.7/site-packages/rest_framework/views.py", line 505, in dispatch
    response = self.handle_exception(exc)
  File "/usr/local/lib/python3.7/site-packages/rest_framework/views.py", line 465, in handle_exception
    self.raise_uncaught_exception(exc)
  File "/usr/local/lib/python3.7/site-packages/rest_framework/views.py", line 476, in raise_uncaught_exception
    raise exc
  File "/usr/local/lib/python3.7/site-packages/rest_framework/views.py", line 502, in dispatch
    response = handler(request, *args, **kwargs)
  File "/usr/local/lib/python3.7/site-packages/rest_framework/mixins.py", line 43, in list
    return self.get_paginated_response(serializer.data)
  File "/usr/local/lib/python3.7/site-packages/rest_framework/serializers.py", line 757, in data
    ret = super().data
  File "/usr/local/lib/python3.7/site-packages/rest_framework/serializers.py", line 261, in data
    self._data = self.to_representation(self.instance)
  File "/usr/local/lib/python3.7/site-packages/rest_framework/serializers.py", line 675, in to_representation
    self.child.to_representation(item) for item in iterable
  File "/usr/local/lib/python3.7/site-packages/rest_framework/serializers.py", line 675, in <listcomp>
    self.child.to_representation(item) for item in iterable
  File "/usr/local/lib/python3.7/site-packages/rest_framework/serializers.py", line 526, in to_representation
    ret[field.field_name] = field.to_representation(attribute)
  File "/usr/local/lib/python3.7/site-packages/rest_framework/fields.py", line 1289, in to_representation
    'Expected a `date`, but got a `datetime`. Refusing to coerce, '
AssertionError: Expected a `date`, but got a `datetime`. Refusing to coerce, as this may mean losing timezone information. Use a custom read-only field and deal with timezone issues explicitly.
[2020-09-21 06:08:26,814][Thread-1:140500096674592][task_id:django.request][log.py:228][ERROR][Internal Server Error: /api/order_model/]
Traceback (most recent call last):
  File "/usr/local/lib/python3.7/site-packages/django/core/handlers/exception.py", line 34, in inner
    response = get_response(request)
  File "/usr/local/lib/python3.7/site-packages/django/core/handlers/base.py", line 115, in _get_response
    response = self.process_exception_by_middleware(e, request)
  File "/usr/local/lib/python3.7/site-packages/django/core/handlers/base.py", line 113, in _get_response
    response = wrapped_callback(request, *callback_args, **callback_kwargs)
  File "/usr/local/lib/python3.7/site-packages/django/views/decorators/csrf.py", line 54, in wrapped_view
    return view_func(*args, **kwargs)
  File "/usr/local/lib/python3.7/site-packages/rest_framework/viewsets.py", line 114, in view
    return self.dispatch(request, *args, **kwargs)
  File "/usr/local/lib/python3.7/site-packages/rest_framework/views.py", line 505, in dispatch
    response = self.handle_exception(exc)
  File "/usr/local/lib/python3.7/site-packages/rest_framework/views.py", line 465, in handle_exception
    self.raise_uncaught_exception(exc)
  File "/usr/local/lib/python3.7/site-packages/rest_framework/views.py", line 476, in raise_uncaught_exception
    raise exc
  File "/usr/local/lib/python3.7/site-packages/rest_framework/views.py", line 502, in dispatch
    response = handler(request, *args, **kwargs)
  File "/usr/local/lib/python3.7/site-packages/rest_framework/mixins.py", line 43, in list
    return self.get_paginated_response(serializer.data)
  File "/usr/local/lib/python3.7/site-packages/rest_framework/serializers.py", line 757, in data
    ret = super().data
  File "/usr/local/lib/python3.7/site-packages/rest_framework/serializers.py", line 261, in data
    self._data = self.to_representation(self.instance)
  File "/usr/local/lib/python3.7/site-packages/rest_framework/serializers.py", line 675, in to_representation
    self.child.to_representation(item) for item in iterable
  File "/usr/local/lib/python3.7/site-packages/rest_framework/serializers.py", line 675, in <listcomp>
    self.child.to_representation(item) for item in iterable
  File "/usr/local/lib/python3.7/site-packages/rest_framework/serializers.py", line 526, in to_representation
    ret[field.field_name] = field.to_representation(attribute)
  File "/usr/local/lib/python3.7/site-packages/rest_framework/fields.py", line 1289, in to_representation
    'Expected a `date`, but got a `datetime`. Refusing to coerce, '
AssertionError: Expected a `date`, but got a `datetime`. Refusing to coerce, as this may mean losing timezone information. Use a custom read-only field and deal with timezone issues explicitly.
[2020-09-21 06:34:54,471][Thread-1:140168210037536][task_id:django.request][log.py:228][ERROR][Internal Server Error: /api/order_model/]
Traceback (most recent call last):
  File "/usr/local/lib/python3.7/site-packages/django/db/backends/utils.py", line 86, in _execute
    return self.cursor.execute(sql, params)
psycopg2.errors.NotNullViolation: null value in column "pro_date" violates not-null constraint
DETAIL:  Failing row contains (3, ct-model-1, 1, 1, , , null, null, 100.00, test, 0, alibaba).


The above exception was the direct cause of the following exception:

Traceback (most recent call last):
  File "/usr/local/lib/python3.7/site-packages/django/core/handlers/exception.py", line 34, in inner
    response = get_response(request)
  File "/usr/local/lib/python3.7/site-packages/django/core/handlers/base.py", line 115, in _get_response
    response = self.process_exception_by_middleware(e, request)
  File "/usr/local/lib/python3.7/site-packages/django/core/handlers/base.py", line 113, in _get_response
    response = wrapped_callback(request, *callback_args, **callback_kwargs)
  File "/usr/local/lib/python3.7/site-packages/django/views/decorators/csrf.py", line 54, in wrapped_view
    return view_func(*args, **kwargs)
  File "/usr/local/lib/python3.7/site-packages/rest_framework/viewsets.py", line 114, in view
    return self.dispatch(request, *args, **kwargs)
  File "/usr/local/lib/python3.7/site-packages/rest_framework/views.py", line 505, in dispatch
    response = self.handle_exception(exc)
  File "/usr/local/lib/python3.7/site-packages/rest_framework/views.py", line 465, in handle_exception
    self.raise_uncaught_exception(exc)
  File "/usr/local/lib/python3.7/site-packages/rest_framework/views.py", line 476, in raise_uncaught_exception
    raise exc
  File "/usr/local/lib/python3.7/site-packages/rest_framework/views.py", line 502, in dispatch
    response = handler(request, *args, **kwargs)
  File "/usr/local/lib/python3.7/site-packages/rest_framework/mixins.py", line 19, in create
    self.perform_create(serializer)
  File "/usr/local/lib/python3.7/site-packages/rest_framework/mixins.py", line 24, in perform_create
    serializer.save()
  File "/usr/local/lib/python3.7/site-packages/rest_framework/serializers.py", line 213, in save
    self.instance = self.create(validated_data)
  File "/usr/local/lib/python3.7/site-packages/rest_framework/serializers.py", line 932, in create
    instance = ModelClass._default_manager.create(**validated_data)
  File "/usr/local/lib/python3.7/site-packages/django/db/models/manager.py", line 82, in manager_method
    return getattr(self.get_queryset(), name)(*args, **kwargs)
  File "/usr/local/lib/python3.7/site-packages/django/db/models/query.py", line 433, in create
    obj.save(force_insert=True, using=self.db)
  File "/usr/local/lib/python3.7/site-packages/django/db/models/base.py", line 746, in save
    force_update=force_update, update_fields=update_fields)
  File "/usr/local/lib/python3.7/site-packages/django/db/models/base.py", line 784, in save_base
    force_update, using, update_fields,
  File "/usr/local/lib/python3.7/site-packages/django/db/models/base.py", line 887, in _save_table
    results = self._do_insert(cls._base_manager, using, fields, returning_fields, raw)
  File "/usr/local/lib/python3.7/site-packages/django/db/models/base.py", line 926, in _do_insert
    using=using, raw=raw,
  File "/usr/local/lib/python3.7/site-packages/django/db/models/manager.py", line 82, in manager_method
    return getattr(self.get_queryset(), name)(*args, **kwargs)
  File "/usr/local/lib/python3.7/site-packages/django/db/models/query.py", line 1204, in _insert
    return query.get_compiler(using=using).execute_sql(returning_fields)
  File "/usr/local/lib/python3.7/site-packages/django/db/models/sql/compiler.py", line 1391, in execute_sql
    cursor.execute(sql, params)
  File "/usr/local/lib/python3.7/site-packages/django/db/backends/utils.py", line 100, in execute
    return super().execute(sql, params)
  File "/usr/local/lib/python3.7/site-packages/django/db/backends/utils.py", line 68, in execute
    return self._execute_with_wrappers(sql, params, many=False, executor=self._execute)
  File "/usr/local/lib/python3.7/site-packages/django/db/backends/utils.py", line 77, in _execute_with_wrappers
    return executor(sql, params, many, context)
  File "/usr/local/lib/python3.7/site-packages/django/db/backends/utils.py", line 86, in _execute
    return self.cursor.execute(sql, params)
  File "/usr/local/lib/python3.7/site-packages/django/db/utils.py", line 90, in __exit__
    raise dj_exc_value.with_traceback(traceback) from exc_value
  File "/usr/local/lib/python3.7/site-packages/django/db/backends/utils.py", line 86, in _execute
    return self.cursor.execute(sql, params)
django.db.utils.IntegrityError: null value in column "pro_date" violates not-null constraint
DETAIL:  Failing row contains (3, ct-model-1, 1, 1, , , null, null, 100.00, test, 0, alibaba).

[2020-09-21 06:36:16,566][Thread-1:139693919284000][task_id:django.request][log.py:228][ERROR][Internal Server Error: /api/order_model/]
Traceback (most recent call last):
  File "/usr/local/lib/python3.7/site-packages/django/db/models/fields/__init__.py", line 1772, in get_prep_value
    return int(value)
TypeError: int() argument must be a string, a bytes-like object or a number, not 'getset_descriptor'

The above exception was the direct cause of the following exception:

Traceback (most recent call last):
  File "/usr/local/lib/python3.7/site-packages/rest_framework/serializers.py", line 932, in create
    instance = ModelClass._default_manager.create(**validated_data)
  File "/usr/local/lib/python3.7/site-packages/django/db/models/manager.py", line 82, in manager_method
    return getattr(self.get_queryset(), name)(*args, **kwargs)
  File "/usr/local/lib/python3.7/site-packages/django/db/models/query.py", line 433, in create
    obj.save(force_insert=True, using=self.db)
  File "/usr/local/lib/python3.7/site-packages/django/db/models/base.py", line 746, in save
    force_update=force_update, update_fields=update_fields)
  File "/usr/local/lib/python3.7/site-packages/django/db/models/base.py", line 784, in save_base
    force_update, using, update_fields,
  File "/usr/local/lib/python3.7/site-packages/django/db/models/base.py", line 887, in _save_table
    results = self._do_insert(cls._base_manager, using, fields, returning_fields, raw)
  File "/usr/local/lib/python3.7/site-packages/django/db/models/base.py", line 926, in _do_insert
    using=using, raw=raw,
  File "/usr/local/lib/python3.7/site-packages/django/db/models/manager.py", line 82, in manager_method
    return getattr(self.get_queryset(), name)(*args, **kwargs)
  File "/usr/local/lib/python3.7/site-packages/django/db/models/query.py", line 1204, in _insert
    return query.get_compiler(using=using).execute_sql(returning_fields)
  File "/usr/local/lib/python3.7/site-packages/django/db/models/sql/compiler.py", line 1390, in execute_sql
    for sql, params in self.as_sql():
  File "/usr/local/lib/python3.7/site-packages/django/db/models/sql/compiler.py", line 1335, in as_sql
    for obj in self.query.objs
  File "/usr/local/lib/python3.7/site-packages/django/db/models/sql/compiler.py", line 1335, in <listcomp>
    for obj in self.query.objs
  File "/usr/local/lib/python3.7/site-packages/django/db/models/sql/compiler.py", line 1334, in <listcomp>
    [self.prepare_value(field, self.pre_save_val(field, obj)) for field in fields]
  File "/usr/local/lib/python3.7/site-packages/django/db/models/sql/compiler.py", line 1275, in prepare_value
    value = field.get_db_prep_save(value, connection=self.connection)
  File "/usr/local/lib/python3.7/site-packages/django/db/models/fields/__init__.py", line 821, in get_db_prep_save
    return self.get_db_prep_value(value, connection=connection, prepared=False)
  File "/usr/local/lib/python3.7/site-packages/django/db/models/fields/__init__.py", line 816, in get_db_prep_value
    value = self.get_prep_value(value)
  File "/usr/local/lib/python3.7/site-packages/django/db/models/fields/__init__.py", line 1776, in get_prep_value
    ) from e
TypeError: Field 'useful_life' expected a number but got <attribute 'day' of 'datetime.date' objects>.

During handling of the above exception, another exception occurred:

Traceback (most recent call last):
  File "/usr/local/lib/python3.7/site-packages/django/core/handlers/exception.py", line 34, in inner
    response = get_response(request)
  File "/usr/local/lib/python3.7/site-packages/django/core/handlers/base.py", line 115, in _get_response
    response = self.process_exception_by_middleware(e, request)
  File "/usr/local/lib/python3.7/site-packages/django/core/handlers/base.py", line 113, in _get_response
    response = wrapped_callback(request, *callback_args, **callback_kwargs)
  File "/usr/local/lib/python3.7/site-packages/django/views/decorators/csrf.py", line 54, in wrapped_view
    return view_func(*args, **kwargs)
  File "/usr/local/lib/python3.7/site-packages/rest_framework/viewsets.py", line 114, in view
    return self.dispatch(request, *args, **kwargs)
  File "/usr/local/lib/python3.7/site-packages/rest_framework/views.py", line 505, in dispatch
    response = self.handle_exception(exc)
  File "/usr/local/lib/python3.7/site-packages/rest_framework/views.py", line 465, in handle_exception
    self.raise_uncaught_exception(exc)
  File "/usr/local/lib/python3.7/site-packages/rest_framework/views.py", line 476, in raise_uncaught_exception
    raise exc
  File "/usr/local/lib/python3.7/site-packages/rest_framework/views.py", line 502, in dispatch
    response = handler(request, *args, **kwargs)
  File "/usr/local/lib/python3.7/site-packages/rest_framework/mixins.py", line 19, in create
    self.perform_create(serializer)
  File "/usr/local/lib/python3.7/site-packages/rest_framework/mixins.py", line 24, in perform_create
    serializer.save()
  File "/usr/local/lib/python3.7/site-packages/rest_framework/serializers.py", line 213, in save
    self.instance = self.create(validated_data)
  File "/usr/local/lib/python3.7/site-packages/rest_framework/serializers.py", line 951, in create
    raise TypeError(msg)
TypeError: Got a `TypeError` when calling `OrderModel.objects.create()`. This may be because you have a writable field on the serializer class that is not a valid argument to `OrderModel.objects.create()`. You may need to make the field read-only, or override the OrderModelsSerializer.create() method to handle this correctly.
Original exception was:
 Traceback (most recent call last):
  File "/usr/local/lib/python3.7/site-packages/django/db/models/fields/__init__.py", line 1772, in get_prep_value
    return int(value)
TypeError: int() argument must be a string, a bytes-like object or a number, not 'getset_descriptor'

The above exception was the direct cause of the following exception:

Traceback (most recent call last):
  File "/usr/local/lib/python3.7/site-packages/rest_framework/serializers.py", line 932, in create
    instance = ModelClass._default_manager.create(**validated_data)
  File "/usr/local/lib/python3.7/site-packages/django/db/models/manager.py", line 82, in manager_method
    return getattr(self.get_queryset(), name)(*args, **kwargs)
  File "/usr/local/lib/python3.7/site-packages/django/db/models/query.py", line 433, in create
    obj.save(force_insert=True, using=self.db)
  File "/usr/local/lib/python3.7/site-packages/django/db/models/base.py", line 746, in save
    force_update=force_update, update_fields=update_fields)
  File "/usr/local/lib/python3.7/site-packages/django/db/models/base.py", line 784, in save_base
    force_update, using, update_fields,
  File "/usr/local/lib/python3.7/site-packages/django/db/models/base.py", line 887, in _save_table
    results = self._do_insert(cls._base_manager, using, fields, returning_fields, raw)
  File "/usr/local/lib/python3.7/site-packages/django/db/models/base.py", line 926, in _do_insert
    using=using, raw=raw,
  File "/usr/local/lib/python3.7/site-packages/django/db/models/manager.py", line 82, in manager_method
    return getattr(self.get_queryset(), name)(*args, **kwargs)
  File "/usr/local/lib/python3.7/site-packages/django/db/models/query.py", line 1204, in _insert
    return query.get_compiler(using=using).execute_sql(returning_fields)
  File "/usr/local/lib/python3.7/site-packages/django/db/models/sql/compiler.py", line 1390, in execute_sql
    for sql, params in self.as_sql():
  File "/usr/local/lib/python3.7/site-packages/django/db/models/sql/compiler.py", line 1335, in as_sql
    for obj in self.query.objs
  File "/usr/local/lib/python3.7/site-packages/django/db/models/sql/compiler.py", line 1335, in <listcomp>
    for obj in self.query.objs
  File "/usr/local/lib/python3.7/site-packages/django/db/models/sql/compiler.py", line 1334, in <listcomp>
    [self.prepare_value(field, self.pre_save_val(field, obj)) for field in fields]
  File "/usr/local/lib/python3.7/site-packages/django/db/models/sql/compiler.py", line 1275, in prepare_value
    value = field.get_db_prep_save(value, connection=self.connection)
  File "/usr/local/lib/python3.7/site-packages/django/db/models/fields/__init__.py", line 821, in get_db_prep_save
    return self.get_db_prep_value(value, connection=connection, prepared=False)
  File "/usr/local/lib/python3.7/site-packages/django/db/models/fields/__init__.py", line 816, in get_db_prep_value
    value = self.get_prep_value(value)
  File "/usr/local/lib/python3.7/site-packages/django/db/models/fields/__init__.py", line 1776, in get_prep_value
    ) from e
TypeError: Field 'useful_life' expected a number but got <attribute 'day' of 'datetime.date' objects>.

[2020-09-21 06:37:58,867][Thread-1:139626864032544][task_id:django.request][log.py:228][ERROR][Internal Server Error: /api/order_model/]
Traceback (most recent call last):
  File "/usr/local/lib/python3.7/site-packages/django/core/handlers/exception.py", line 34, in inner
    response = get_response(request)
  File "/usr/local/lib/python3.7/site-packages/django/core/handlers/base.py", line 115, in _get_response
    response = self.process_exception_by_middleware(e, request)
  File "/usr/local/lib/python3.7/site-packages/django/core/handlers/base.py", line 113, in _get_response
    response = wrapped_callback(request, *callback_args, **callback_kwargs)
  File "/usr/local/lib/python3.7/site-packages/django/views/decorators/csrf.py", line 54, in wrapped_view
    return view_func(*args, **kwargs)
  File "/usr/local/lib/python3.7/site-packages/rest_framework/viewsets.py", line 114, in view
    return self.dispatch(request, *args, **kwargs)
  File "/usr/local/lib/python3.7/site-packages/rest_framework/views.py", line 505, in dispatch
    response = self.handle_exception(exc)
  File "/usr/local/lib/python3.7/site-packages/rest_framework/views.py", line 465, in handle_exception
    self.raise_uncaught_exception(exc)
  File "/usr/local/lib/python3.7/site-packages/rest_framework/views.py", line 476, in raise_uncaught_exception
    raise exc
  File "/usr/local/lib/python3.7/site-packages/rest_framework/views.py", line 502, in dispatch
    response = handler(request, *args, **kwargs)
  File "/usr/local/lib/python3.7/site-packages/rest_framework/mixins.py", line 20, in create
    headers = self.get_success_headers(serializer.data)
  File "/usr/local/lib/python3.7/site-packages/rest_framework/serializers.py", line 559, in data
    ret = super().data
  File "/usr/local/lib/python3.7/site-packages/rest_framework/serializers.py", line 261, in data
    self._data = self.to_representation(self.instance)
  File "/usr/local/lib/python3.7/site-packages/rest_framework/serializers.py", line 526, in to_representation
    ret[field.field_name] = field.to_representation(attribute)
  File "/usr/local/lib/python3.7/site-packages/rest_framework/fields.py", line 1289, in to_representation
    'Expected a `date`, but got a `datetime`. Refusing to coerce, '
AssertionError: Expected a `date`, but got a `datetime`. Refusing to coerce, as this may mean losing timezone information. Use a custom read-only field and deal with timezone issues explicitly.
[2020-09-21 06:38:40,502][Thread-1:139738568760096][task_id:django.request][log.py:228][ERROR][Internal Server Error: /api/order_model/]
Traceback (most recent call last):
  File "/usr/local/lib/python3.7/site-packages/django/db/models/base.py", line 466, in __init__
    val = kwargs.pop(field.attname)
KeyError: 'pro_date'

During handling of the above exception, another exception occurred:

Traceback (most recent call last):
  File "/usr/local/lib/python3.7/site-packages/rest_framework/serializers.py", line 932, in create
    instance = ModelClass._default_manager.create(**validated_data)
  File "/usr/local/lib/python3.7/site-packages/django/db/models/manager.py", line 82, in manager_method
    return getattr(self.get_queryset(), name)(*args, **kwargs)
  File "/usr/local/lib/python3.7/site-packages/django/db/models/query.py", line 431, in create
    obj = self.model(**kwargs)
  File "/usr/local/lib/python3.7/site-packages/django/db/models/base.py", line 472, in __init__
    val = field.get_default()
  File "/usr/local/lib/python3.7/site-packages/django/db/models/fields/__init__.py", line 829, in get_default
    return self._get_default()
TypeError: descriptor 'date' of 'datetime.datetime' object needs an argument

During handling of the above exception, another exception occurred:

Traceback (most recent call last):
  File "/usr/local/lib/python3.7/site-packages/django/core/handlers/exception.py", line 34, in inner
    response = get_response(request)
  File "/usr/local/lib/python3.7/site-packages/django/core/handlers/base.py", line 115, in _get_response
    response = self.process_exception_by_middleware(e, request)
  File "/usr/local/lib/python3.7/site-packages/django/core/handlers/base.py", line 113, in _get_response
    response = wrapped_callback(request, *callback_args, **callback_kwargs)
  File "/usr/local/lib/python3.7/site-packages/django/views/decorators/csrf.py", line 54, in wrapped_view
    return view_func(*args, **kwargs)
  File "/usr/local/lib/python3.7/site-packages/rest_framework/viewsets.py", line 114, in view
    return self.dispatch(request, *args, **kwargs)
  File "/usr/local/lib/python3.7/site-packages/rest_framework/views.py", line 505, in dispatch
    response = self.handle_exception(exc)
  File "/usr/local/lib/python3.7/site-packages/rest_framework/views.py", line 465, in handle_exception
    self.raise_uncaught_exception(exc)
  File "/usr/local/lib/python3.7/site-packages/rest_framework/views.py", line 476, in raise_uncaught_exception
    raise exc
  File "/usr/local/lib/python3.7/site-packages/rest_framework/views.py", line 502, in dispatch
    response = handler(request, *args, **kwargs)
  File "/usr/local/lib/python3.7/site-packages/rest_framework/mixins.py", line 19, in create
    self.perform_create(serializer)
  File "/usr/local/lib/python3.7/site-packages/rest_framework/mixins.py", line 24, in perform_create
    serializer.save()
  File "/usr/local/lib/python3.7/site-packages/rest_framework/serializers.py", line 213, in save
    self.instance = self.create(validated_data)
  File "/usr/local/lib/python3.7/site-packages/rest_framework/serializers.py", line 951, in create
    raise TypeError(msg)
TypeError: Got a `TypeError` when calling `OrderModel.objects.create()`. This may be because you have a writable field on the serializer class that is not a valid argument to `OrderModel.objects.create()`. You may need to make the field read-only, or override the OrderModelsSerializer.create() method to handle this correctly.
Original exception was:
 Traceback (most recent call last):
  File "/usr/local/lib/python3.7/site-packages/django/db/models/base.py", line 466, in __init__
    val = kwargs.pop(field.attname)
KeyError: 'pro_date'

During handling of the above exception, another exception occurred:

Traceback (most recent call last):
  File "/usr/local/lib/python3.7/site-packages/rest_framework/serializers.py", line 932, in create
    instance = ModelClass._default_manager.create(**validated_data)
  File "/usr/local/lib/python3.7/site-packages/django/db/models/manager.py", line 82, in manager_method
    return getattr(self.get_queryset(), name)(*args, **kwargs)
  File "/usr/local/lib/python3.7/site-packages/django/db/models/query.py", line 431, in create
    obj = self.model(**kwargs)
  File "/usr/local/lib/python3.7/site-packages/django/db/models/base.py", line 472, in __init__
    val = field.get_default()
  File "/usr/local/lib/python3.7/site-packages/django/db/models/fields/__init__.py", line 829, in get_default
    return self._get_default()
TypeError: descriptor 'date' of 'datetime.datetime' object needs an argument

[2020-09-21 06:43:12,162][Thread-1:139806214839072][task_id:django.request][log.py:228][ERROR][Internal Server Error: /api/order_model/]
Traceback (most recent call last):
  File "/usr/local/lib/python3.7/site-packages/django/core/handlers/exception.py", line 34, in inner
    response = get_response(request)
  File "/usr/local/lib/python3.7/site-packages/django/core/handlers/base.py", line 115, in _get_response
    response = self.process_exception_by_middleware(e, request)
  File "/usr/local/lib/python3.7/site-packages/django/core/handlers/base.py", line 113, in _get_response
    response = wrapped_callback(request, *callback_args, **callback_kwargs)
  File "/usr/local/lib/python3.7/site-packages/django/views/decorators/csrf.py", line 54, in wrapped_view
    return view_func(*args, **kwargs)
  File "/usr/local/lib/python3.7/site-packages/rest_framework/viewsets.py", line 114, in view
    return self.dispatch(request, *args, **kwargs)
  File "/usr/local/lib/python3.7/site-packages/rest_framework/views.py", line 505, in dispatch
    response = self.handle_exception(exc)
  File "/usr/local/lib/python3.7/site-packages/rest_framework/views.py", line 465, in handle_exception
    self.raise_uncaught_exception(exc)
  File "/usr/local/lib/python3.7/site-packages/rest_framework/views.py", line 476, in raise_uncaught_exception
    raise exc
  File "/usr/local/lib/python3.7/site-packages/rest_framework/views.py", line 502, in dispatch
    response = handler(request, *args, **kwargs)
  File "/usr/local/lib/python3.7/site-packages/rest_framework/mixins.py", line 20, in create
    headers = self.get_success_headers(serializer.data)
  File "/usr/local/lib/python3.7/site-packages/rest_framework/serializers.py", line 559, in data
    ret = super().data
  File "/usr/local/lib/python3.7/site-packages/rest_framework/serializers.py", line 261, in data
    self._data = self.to_representation(self.instance)
  File "/usr/local/lib/python3.7/site-packages/rest_framework/serializers.py", line 526, in to_representation
    ret[field.field_name] = field.to_representation(attribute)
  File "/usr/local/lib/python3.7/site-packages/rest_framework/fields.py", line 1289, in to_representation
    'Expected a `date`, but got a `datetime`. Refusing to coerce, '
AssertionError: Expected a `date`, but got a `datetime`. Refusing to coerce, as this may mean losing timezone information. Use a custom read-only field and deal with timezone issues explicitly.
[2020-09-21 06:43:48,396][Thread-1:139806214839072][task_id:django.request][log.py:228][ERROR][Internal Server Error: /api/order_model/]
Traceback (most recent call last):
  File "/usr/local/lib/python3.7/site-packages/django/core/handlers/exception.py", line 34, in inner
    response = get_response(request)
  File "/usr/local/lib/python3.7/site-packages/django/core/handlers/base.py", line 115, in _get_response
    response = self.process_exception_by_middleware(e, request)
  File "/usr/local/lib/python3.7/site-packages/django/core/handlers/base.py", line 113, in _get_response
    response = wrapped_callback(request, *callback_args, **callback_kwargs)
  File "/usr/local/lib/python3.7/site-packages/django/views/decorators/csrf.py", line 54, in wrapped_view
    return view_func(*args, **kwargs)
  File "/usr/local/lib/python3.7/site-packages/rest_framework/viewsets.py", line 114, in view
    return self.dispatch(request, *args, **kwargs)
  File "/usr/local/lib/python3.7/site-packages/rest_framework/views.py", line 505, in dispatch
    response = self.handle_exception(exc)
  File "/usr/local/lib/python3.7/site-packages/rest_framework/views.py", line 465, in handle_exception
    self.raise_uncaught_exception(exc)
  File "/usr/local/lib/python3.7/site-packages/rest_framework/views.py", line 476, in raise_uncaught_exception
    raise exc
  File "/usr/local/lib/python3.7/site-packages/rest_framework/views.py", line 502, in dispatch
    response = handler(request, *args, **kwargs)
  File "/usr/local/lib/python3.7/site-packages/rest_framework/mixins.py", line 20, in create
    headers = self.get_success_headers(serializer.data)
  File "/usr/local/lib/python3.7/site-packages/rest_framework/serializers.py", line 559, in data
    ret = super().data
  File "/usr/local/lib/python3.7/site-packages/rest_framework/serializers.py", line 261, in data
    self._data = self.to_representation(self.instance)
  File "/usr/local/lib/python3.7/site-packages/rest_framework/serializers.py", line 526, in to_representation
    ret[field.field_name] = field.to_representation(attribute)
  File "/usr/local/lib/python3.7/site-packages/rest_framework/fields.py", line 1289, in to_representation
    'Expected a `date`, but got a `datetime`. Refusing to coerce, '
AssertionError: Expected a `date`, but got a `datetime`. Refusing to coerce, as this may mean losing timezone information. Use a custom read-only field and deal with timezone issues explicitly.
[2020-09-21 06:44:28,607][Thread-1:140697151470368][task_id:django.request][log.py:228][ERROR][Internal Server Error: /api/order_model/]
Traceback (most recent call last):
  File "/usr/local/lib/python3.7/site-packages/django/core/handlers/exception.py", line 34, in inner
    response = get_response(request)
  File "/usr/local/lib/python3.7/site-packages/django/core/handlers/base.py", line 115, in _get_response
    response = self.process_exception_by_middleware(e, request)
  File "/usr/local/lib/python3.7/site-packages/django/core/handlers/base.py", line 113, in _get_response
    response = wrapped_callback(request, *callback_args, **callback_kwargs)
  File "/usr/local/lib/python3.7/site-packages/django/views/decorators/csrf.py", line 54, in wrapped_view
    return view_func(*args, **kwargs)
  File "/usr/local/lib/python3.7/site-packages/rest_framework/viewsets.py", line 114, in view
    return self.dispatch(request, *args, **kwargs)
  File "/usr/local/lib/python3.7/site-packages/rest_framework/views.py", line 505, in dispatch
    response = self.handle_exception(exc)
  File "/usr/local/lib/python3.7/site-packages/rest_framework/views.py", line 465, in handle_exception
    self.raise_uncaught_exception(exc)
  File "/usr/local/lib/python3.7/site-packages/rest_framework/views.py", line 476, in raise_uncaught_exception
    raise exc
  File "/usr/local/lib/python3.7/site-packages/rest_framework/views.py", line 502, in dispatch
    response = handler(request, *args, **kwargs)
  File "/usr/local/lib/python3.7/site-packages/rest_framework/mixins.py", line 20, in create
    headers = self.get_success_headers(serializer.data)
  File "/usr/local/lib/python3.7/site-packages/rest_framework/serializers.py", line 559, in data
    ret = super().data
  File "/usr/local/lib/python3.7/site-packages/rest_framework/serializers.py", line 261, in data
    self._data = self.to_representation(self.instance)
  File "/usr/local/lib/python3.7/site-packages/rest_framework/serializers.py", line 526, in to_representation
    ret[field.field_name] = field.to_representation(attribute)
  File "/usr/local/lib/python3.7/site-packages/rest_framework/fields.py", line 1289, in to_representation
    'Expected a `date`, but got a `datetime`. Refusing to coerce, '
AssertionError: Expected a `date`, but got a `datetime`. Refusing to coerce, as this may mean losing timezone information. Use a custom read-only field and deal with timezone issues explicitly.
[2020-09-21 08:22:26,986][Thread-1:140581937085216][task_id:django.request][log.py:228][ERROR][Internal Server Error: /api/order_model/]
Traceback (most recent call last):
  File "/usr/local/lib/python3.7/site-packages/django/core/handlers/exception.py", line 34, in inner
    response = get_response(request)
  File "/usr/local/lib/python3.7/site-packages/django/core/handlers/base.py", line 115, in _get_response
    response = self.process_exception_by_middleware(e, request)
  File "/usr/local/lib/python3.7/site-packages/django/core/handlers/base.py", line 113, in _get_response
    response = wrapped_callback(request, *callback_args, **callback_kwargs)
  File "/usr/local/lib/python3.7/site-packages/django/views/decorators/csrf.py", line 54, in wrapped_view
    return view_func(*args, **kwargs)
  File "/usr/local/lib/python3.7/site-packages/rest_framework/viewsets.py", line 114, in view
    return self.dispatch(request, *args, **kwargs)
  File "/usr/local/lib/python3.7/site-packages/rest_framework/views.py", line 505, in dispatch
    response = self.handle_exception(exc)
  File "/usr/local/lib/python3.7/site-packages/rest_framework/views.py", line 465, in handle_exception
    self.raise_uncaught_exception(exc)
  File "/usr/local/lib/python3.7/site-packages/rest_framework/views.py", line 476, in raise_uncaught_exception
    raise exc
  File "/usr/local/lib/python3.7/site-packages/rest_framework/views.py", line 502, in dispatch
    response = handler(request, *args, **kwargs)
  File "/usr/local/lib/python3.7/site-packages/rest_framework/mixins.py", line 43, in list
    return self.get_paginated_response(serializer.data)
  File "/usr/local/lib/python3.7/site-packages/rest_framework/serializers.py", line 757, in data
    ret = super().data
  File "/usr/local/lib/python3.7/site-packages/rest_framework/serializers.py", line 261, in data
    self._data = self.to_representation(self.instance)
  File "/usr/local/lib/python3.7/site-packages/rest_framework/serializers.py", line 675, in to_representation
    self.child.to_representation(item) for item in iterable
  File "/usr/local/lib/python3.7/site-packages/rest_framework/serializers.py", line 675, in <listcomp>
    self.child.to_representation(item) for item in iterable
  File "/usr/local/lib/python3.7/site-packages/rest_framework/serializers.py", line 526, in to_representation
    ret[field.field_name] = field.to_representation(attribute)
  File "/usr/local/lib/python3.7/site-packages/rest_framework/fields.py", line 1289, in to_representation
    'Expected a `date`, but got a `datetime`. Refusing to coerce, '
AssertionError: Expected a `date`, but got a `datetime`. Refusing to coerce, as this may mean losing timezone information. Use a custom read-only field and deal with timezone issues explicitly.
