[ERROR][2020-10-20 10:24:43,187][log.py:228]Internal Server Error: /send_mail/
Traceback (most recent call last):
  File "/usr/local/lib/python3.7/smtplib.py", line 387, in getreply
    line = self.file.readline(_MAXLINE + 1)
  File "/usr/local/lib/python3.7/socket.py", line 589, in readinto
    return self._sock.recv_into(b)
  File "/usr/local/lib/python3.7/ssl.py", line 1071, in recv_into
    return self.read(nbytes, buffer)
  File "/usr/local/lib/python3.7/ssl.py", line 929, in read
    return self._sslobj.read(len, buffer)
socket.timeout: The read operation timed out

During handling of the above exception, another exception occurred:

Traceback (most recent call last):
  File "/usr/local/lib/python3.7/site-packages/django/core/handlers/exception.py", line 34, in inner
    response = get_response(request)
  File "/usr/local/lib/python3.7/site-packages/django/core/handlers/base.py", line 115, in _get_response
    response = self.process_exception_by_middleware(e, request)
  File "/usr/local/lib/python3.7/site-packages/django/core/handlers/base.py", line 113, in _get_response
    response = wrapped_callback(request, *callback_args, **callback_kwargs)
  File "/usr/local/lib/python3.7/site-packages/django/views/decorators/csrf.py", line 54, in wrapped_view
    return view_func(*args, **kwargs)
  File "/usr/local/lib/python3.7/site-packages/django/views/generic/base.py", line 71, in view
    return self.dispatch(request, *args, **kwargs)
  File "/usr/local/lib/python3.7/site-packages/rest_framework/views.py", line 505, in dispatch
    response = self.handle_exception(exc)
  File "/usr/local/lib/python3.7/site-packages/rest_framework/views.py", line 465, in handle_exception
    self.raise_uncaught_exception(exc)
  File "/usr/local/lib/python3.7/site-packages/rest_framework/views.py", line 476, in raise_uncaught_exception
    raise exc
  File "/usr/local/lib/python3.7/site-packages/rest_framework/views.py", line 502, in dispatch
    response = handler(request, *args, **kwargs)
  File "/usr/src/api/webapi/views.py", line 170, in get
    send_mail(subject, message, from_email, ['hanjiwen31@163.com'])
  File "/usr/local/lib/python3.7/site-packages/django/core/mail/__init__.py", line 60, in send_mail
    return mail.send()
  File "/usr/local/lib/python3.7/site-packages/django/core/mail/message.py", line 276, in send
    return self.get_connection(fail_silently).send_messages([self])
  File "/usr/local/lib/python3.7/site-packages/django/core/mail/backends/smtp.py", line 102, in send_messages
    new_conn_created = self.open()
  File "/usr/local/lib/python3.7/site-packages/django/core/mail/backends/smtp.py", line 62, in open
    self.connection = self.connection_class(self.host, self.port, **connection_params)
  File "/usr/local/lib/python3.7/smtplib.py", line 1031, in __init__
    source_address)
  File "/usr/local/lib/python3.7/smtplib.py", line 251, in __init__
    (code, msg) = self.connect(host, port)
  File "/usr/local/lib/python3.7/smtplib.py", line 338, in connect
    (code, msg) = self.getreply()
  File "/usr/local/lib/python3.7/smtplib.py", line 391, in getreply
    + str(e))
smtplib.SMTPServerDisconnected: Connection unexpectedly closed: The read operation timed out
