[ERROR][2020-10-15 02:24:45,029][log.py:228]Internal Server Error: /
Traceback (most recent call last):
  File "/usr/local/lib/python3.7/site-packages/django/core/handlers/exception.py", line 34, in inner
    response = get_response(request)
  File "/usr/local/lib/python3.7/site-packages/django/core/handlers/base.py", line 115, in _get_response
    response = self.process_exception_by_middleware(e, request)
  File "/usr/local/lib/python3.7/site-packages/django/core/handlers/base.py", line 113, in _get_response
    response = wrapped_callback(request, *callback_args, **callback_kwargs)
  File "/usr/local/lib/python3.7/site-packages/django/views/generic/base.py", line 71, in view
    return self.dispatch(request, *args, **kwargs)
  File "/usr/local/lib/python3.7/site-packages/django/views/generic/base.py", line 97, in dispatch
    return handler(request, *args, **kwargs)
  File "/usr/local/lib/python3.7/site-packages/django/views/generic/base.py", line 158, in get
    context = self.get_context_data(**kwargs)
  File "/usr/src/api/webapi/views.py", line 123, in get_context_data
    context = super().get_context_data(**kwargs)
  File "/usr/local/lib/python3.7/site-packages/django/views/generic/list.py", line 115, in get_context_data
    queryset = object_list if object_list is not None else self.object_list
AttributeError: 'HomeIndexView' object has no attribute 'object_list'
[ERROR][2020-10-15 02:25:27,856][log.py:228]Internal Server Error: /
Traceback (most recent call last):
  File "/usr/local/lib/python3.7/site-packages/django/core/handlers/exception.py", line 34, in inner
    response = get_response(request)
  File "/usr/local/lib/python3.7/site-packages/django/core/handlers/base.py", line 115, in _get_response
    response = self.process_exception_by_middleware(e, request)
  File "/usr/local/lib/python3.7/site-packages/django/core/handlers/base.py", line 113, in _get_response
    response = wrapped_callback(request, *callback_args, **callback_kwargs)
  File "/usr/local/lib/python3.7/site-packages/django/views/generic/base.py", line 71, in view
    return self.dispatch(request, *args, **kwargs)
  File "/usr/local/lib/python3.7/site-packages/django/views/generic/base.py", line 97, in dispatch
    return handler(request, *args, **kwargs)
  File "/usr/local/lib/python3.7/site-packages/django/views/generic/base.py", line 158, in get
    context = self.get_context_data(**kwargs)
  File "/usr/src/api/webapi/views.py", line 123, in get_context_data
  File "/usr/local/lib/python3.7/site-packages/django/views/generic/list.py", line 115, in get_context_data
    queryset = object_list if object_list is not None else self.object_list
AttributeError: 'HomeIndexView' object has no attribute 'object_list'
[ERROR][2020-10-15 02:25:31,148][log.py:228]Internal Server Error: /
Traceback (most recent call last):
  File "/usr/local/lib/python3.7/site-packages/django/core/handlers/exception.py", line 34, in inner
    response = get_response(request)
  File "/usr/local/lib/python3.7/site-packages/django/core/handlers/base.py", line 115, in _get_response
    response = self.process_exception_by_middleware(e, request)
  File "/usr/local/lib/python3.7/site-packages/django/core/handlers/base.py", line 113, in _get_response
    response = wrapped_callback(request, *callback_args, **callback_kwargs)
  File "/usr/local/lib/python3.7/site-packages/django/views/generic/base.py", line 71, in view
    return self.dispatch(request, *args, **kwargs)
  File "/usr/local/lib/python3.7/site-packages/django/views/generic/base.py", line 97, in dispatch
    return handler(request, *args, **kwargs)
  File "/usr/local/lib/python3.7/site-packages/django/views/generic/base.py", line 158, in get
    context = self.get_context_data(**kwargs)
  File "/usr/src/api/webapi/views.py", line 125, in get_context_data
    context = super().get_context_data(**kwargs)
  File "/usr/local/lib/python3.7/site-packages/django/views/generic/list.py", line 115, in get_context_data
    queryset = object_list if object_list is not None else self.object_list
AttributeError: 'HomeIndexView' object has no attribute 'object_list'
[ERROR][2020-10-15 02:25:53,586][log.py:228]Internal Server Error: /
Traceback (most recent call last):
  File "/usr/local/lib/python3.7/site-packages/django/core/handlers/exception.py", line 34, in inner
    response = get_response(request)
  File "/usr/local/lib/python3.7/site-packages/django/core/handlers/base.py", line 115, in _get_response
    response = self.process_exception_by_middleware(e, request)
  File "/usr/local/lib/python3.7/site-packages/django/core/handlers/base.py", line 113, in _get_response
    response = wrapped_callback(request, *callback_args, **callback_kwargs)
  File "/usr/local/lib/python3.7/site-packages/django/views/generic/base.py", line 71, in view
    return self.dispatch(request, *args, **kwargs)
  File "/usr/local/lib/python3.7/site-packages/django/views/generic/base.py", line 97, in dispatch
    return handler(request, *args, **kwargs)
  File "/usr/local/lib/python3.7/site-packages/django/views/generic/base.py", line 158, in get
    context = self.get_context_data(**kwargs)
  File "/usr/src/api/webapi/views.py", line 125, in get_context_data
    context['is_home'] = Image.objects.filter(is_home=1)
  File "/usr/local/lib/python3.7/site-packages/django/views/generic/list.py", line 115, in get_context_data
    queryset = object_list if object_list is not None else self.object_list
AttributeError: 'HomeIndexView' object has no attribute 'object_list'
[ERROR][2020-10-15 03:39:49,946][log.py:228]Internal Server Error: /
Traceback (most recent call last):
  File "/usr/local/lib/python3.7/site-packages/django/core/handlers/exception.py", line 34, in inner
    response = get_response(request)
  File "/usr/local/lib/python3.7/site-packages/django/core/handlers/base.py", line 115, in _get_response
    response = self.process_exception_by_middleware(e, request)
  File "/usr/local/lib/python3.7/site-packages/django/core/handlers/base.py", line 113, in _get_response
    response = wrapped_callback(request, *callback_args, **callback_kwargs)
  File "/usr/local/lib/python3.7/site-packages/django/views/generic/base.py", line 71, in view
    return self.dispatch(request, *args, **kwargs)
  File "/usr/local/lib/python3.7/site-packages/django/views/generic/base.py", line 97, in dispatch
    return handler(request, *args, **kwargs)
  File "/usr/local/lib/python3.7/site-packages/django/views/generic/base.py", line 158, in get
    context = self.get_context_data(**kwargs)
  File "/usr/src/api/webapi/views.py", line 127, in get_context_data
    context['hots'] = ProductsSerializer.pro_image
AttributeError: type object 'ProductsSerializer' has no attribute 'pro_image'
[ERROR][2020-10-15 03:40:54,180][log.py:228]Internal Server Error: /
Traceback (most recent call last):
  File "/usr/local/lib/python3.7/site-packages/django/core/handlers/exception.py", line 34, in inner
    response = get_response(request)
  File "/usr/local/lib/python3.7/site-packages/django/core/handlers/base.py", line 115, in _get_response
    response = self.process_exception_by_middleware(e, request)
  File "/usr/local/lib/python3.7/site-packages/django/core/handlers/base.py", line 113, in _get_response
    response = wrapped_callback(request, *callback_args, **callback_kwargs)
  File "/usr/local/lib/python3.7/site-packages/django/views/generic/base.py", line 71, in view
    return self.dispatch(request, *args, **kwargs)
  File "/usr/local/lib/python3.7/site-packages/django/views/generic/base.py", line 97, in dispatch
    return handler(request, *args, **kwargs)
  File "/usr/local/lib/python3.7/site-packages/django/views/generic/base.py", line 158, in get
    context = self.get_context_data(**kwargs)
  File "/usr/src/api/webapi/views.py", line 127, in get_context_data
    context['hots'] = ProductsSerializer.id
AttributeError: type object 'ProductsSerializer' has no attribute 'id'
[ERROR][2020-10-15 03:41:12,555][log.py:228]Internal Server Error: /
Traceback (most recent call last):
  File "/usr/local/lib/python3.7/site-packages/django/core/handlers/exception.py", line 34, in inner
    response = get_response(request)
  File "/usr/local/lib/python3.7/site-packages/django/core/handlers/base.py", line 115, in _get_response
    response = self.process_exception_by_middleware(e, request)
  File "/usr/local/lib/python3.7/site-packages/django/core/handlers/base.py", line 113, in _get_response
    response = wrapped_callback(request, *callback_args, **callback_kwargs)
  File "/usr/local/lib/python3.7/site-packages/django/views/generic/base.py", line 71, in view
    return self.dispatch(request, *args, **kwargs)
  File "/usr/local/lib/python3.7/site-packages/django/views/generic/base.py", line 97, in dispatch
    return handler(request, *args, **kwargs)
  File "/usr/local/lib/python3.7/site-packages/django/views/generic/base.py", line 158, in get
    context = self.get_context_data(**kwargs)
  File "/usr/src/api/webapi/views.py", line 127, in get_context_data
    context['hots'] = ProductsSerializer['id']
TypeError: 'SerializerMetaclass' object is not subscriptable
[ERROR][2020-10-15 03:42:16,646][log.py:228]Internal Server Error: /
Traceback (most recent call last):
  File "/usr/local/lib/python3.7/site-packages/django/core/handlers/exception.py", line 34, in inner
    response = get_response(request)
  File "/usr/local/lib/python3.7/site-packages/django/core/handlers/base.py", line 115, in _get_response
    response = self.process_exception_by_middleware(e, request)
  File "/usr/local/lib/python3.7/site-packages/django/core/handlers/base.py", line 113, in _get_response
    response = wrapped_callback(request, *callback_args, **callback_kwargs)
  File "/usr/local/lib/python3.7/site-packages/django/views/generic/base.py", line 71, in view
    return self.dispatch(request, *args, **kwargs)
  File "/usr/local/lib/python3.7/site-packages/django/views/generic/base.py", line 97, in dispatch
    return handler(request, *args, **kwargs)
  File "/usr/local/lib/python3.7/site-packages/django/views/generic/base.py", line 158, in get
    context = self.get_context_data(**kwargs)
  File "/usr/src/api/webapi/views.py", line 127, in get_context_data
    context['hots'] = ProductsSerializer.data.id
AttributeError: 'property' object has no attribute 'id'
[ERROR][2020-10-15 03:44:33,646][log.py:228]Internal Server Error: /
Traceback (most recent call last):
  File "/usr/local/lib/python3.7/site-packages/django/core/handlers/exception.py", line 34, in inner
    response = get_response(request)
  File "/usr/local/lib/python3.7/site-packages/django/core/handlers/base.py", line 115, in _get_response
    response = self.process_exception_by_middleware(e, request)
  File "/usr/local/lib/python3.7/site-packages/django/core/handlers/base.py", line 113, in _get_response
    response = wrapped_callback(request, *callback_args, **callback_kwargs)
  File "/usr/local/lib/python3.7/site-packages/django/views/generic/base.py", line 71, in view
    return self.dispatch(request, *args, **kwargs)
  File "/usr/local/lib/python3.7/site-packages/django/views/generic/base.py", line 97, in dispatch
    return handler(request, *args, **kwargs)
  File "/usr/local/lib/python3.7/site-packages/django/views/generic/base.py", line 158, in get
    context = self.get_context_data(**kwargs)
  File "/usr/src/api/webapi/views.py", line 124, in get_context_data
    context = super().get_context_data(**kwargs)
  File "/usr/local/lib/python3.7/site-packages/django/views/generic/list.py", line 115, in get_context_data
    queryset = object_list if object_list is not None else self.object_list
AttributeError: 'HomeIndexView' object has no attribute 'object_list'
[ERROR][2020-10-15 03:45:08,934][log.py:228]Internal Server Error: /
Traceback (most recent call last):
  File "/usr/local/lib/python3.7/site-packages/django/core/handlers/exception.py", line 34, in inner
    response = get_response(request)
  File "/usr/local/lib/python3.7/site-packages/django/core/handlers/base.py", line 115, in _get_response
    response = self.process_exception_by_middleware(e, request)
  File "/usr/local/lib/python3.7/site-packages/django/core/handlers/base.py", line 113, in _get_response
    response = wrapped_callback(request, *callback_args, **callback_kwargs)
  File "/usr/local/lib/python3.7/site-packages/django/views/generic/base.py", line 71, in view
    return self.dispatch(request, *args, **kwargs)
  File "/usr/local/lib/python3.7/site-packages/django/views/generic/base.py", line 97, in dispatch
    return handler(request, *args, **kwargs)
  File "/usr/local/lib/python3.7/site-packages/django/views/generic/base.py", line 158, in get
    context = self.get_context_data(**kwargs)
  File "/usr/src/api/webapi/views.py", line 124, in get_context_data
    context = super().get_context_data(**kwargs)
  File "/usr/local/lib/python3.7/site-packages/django/views/generic/list.py", line 115, in get_context_data
    queryset = object_list if object_list is not None else self.object_list
AttributeError: 'HomeIndexView' object has no attribute 'object_list'
[ERROR][2020-10-15 03:45:51,731][log.py:228]Internal Server Error: /
Traceback (most recent call last):
  File "/usr/local/lib/python3.7/site-packages/django/core/handlers/exception.py", line 34, in inner
    response = get_response(request)
  File "/usr/local/lib/python3.7/site-packages/django/core/handlers/base.py", line 115, in _get_response
    response = self.process_exception_by_middleware(e, request)
  File "/usr/local/lib/python3.7/site-packages/django/core/handlers/base.py", line 113, in _get_response
    response = wrapped_callback(request, *callback_args, **callback_kwargs)
  File "/usr/local/lib/python3.7/site-packages/django/views/generic/base.py", line 71, in view
    return self.dispatch(request, *args, **kwargs)
  File "/usr/local/lib/python3.7/site-packages/django/views/generic/base.py", line 97, in dispatch
    return handler(request, *args, **kwargs)
  File "/usr/local/lib/python3.7/site-packages/django/views/generic/base.py", line 158, in get
    context = self.get_context_data(**kwargs)
  File "/usr/src/api/webapi/views.py", line 125, in get_context_data
    context = super().get_context_data(**kwargs)
  File "/usr/local/lib/python3.7/site-packages/django/views/generic/list.py", line 115, in get_context_data
    queryset = object_list if object_list is not None else self.object_list
AttributeError: 'HomeIndexView' object has no attribute 'object_list'
[ERROR][2020-10-15 03:46:28,676][log.py:228]Internal Server Error: /
Traceback (most recent call last):
  File "/usr/local/lib/python3.7/site-packages/django/core/handlers/exception.py", line 34, in inner
    response = get_response(request)
  File "/usr/local/lib/python3.7/site-packages/django/core/handlers/base.py", line 115, in _get_response
    response = self.process_exception_by_middleware(e, request)
  File "/usr/local/lib/python3.7/site-packages/django/core/handlers/base.py", line 113, in _get_response
    response = wrapped_callback(request, *callback_args, **callback_kwargs)
  File "/usr/local/lib/python3.7/site-packages/django/views/generic/base.py", line 71, in view
    return self.dispatch(request, *args, **kwargs)
  File "/usr/local/lib/python3.7/site-packages/django/views/generic/base.py", line 97, in dispatch
    return handler(request, *args, **kwargs)
  File "/usr/local/lib/python3.7/site-packages/django/views/generic/base.py", line 158, in get
    context = self.get_context_data(**kwargs)
  File "/usr/src/api/webapi/views.py", line 126, in get_context_data
    context = super().get_context_data(**kwargs)
  File "/usr/local/lib/python3.7/site-packages/django/views/generic/list.py", line 115, in get_context_data
    queryset = object_list if object_list is not None else self.object_list
AttributeError: 'HomeIndexView' object has no attribute 'object_list'
[ERROR][2020-10-15 03:46:29,829][log.py:228]Internal Server Error: /
Traceback (most recent call last):
  File "/usr/local/lib/python3.7/site-packages/django/core/handlers/exception.py", line 34, in inner
    response = get_response(request)
  File "/usr/local/lib/python3.7/site-packages/django/core/handlers/base.py", line 115, in _get_response
    response = self.process_exception_by_middleware(e, request)
  File "/usr/local/lib/python3.7/site-packages/django/core/handlers/base.py", line 113, in _get_response
    response = wrapped_callback(request, *callback_args, **callback_kwargs)
  File "/usr/local/lib/python3.7/site-packages/django/views/generic/base.py", line 71, in view
    return self.dispatch(request, *args, **kwargs)
  File "/usr/local/lib/python3.7/site-packages/django/views/generic/base.py", line 97, in dispatch
    return handler(request, *args, **kwargs)
  File "/usr/local/lib/python3.7/site-packages/django/views/generic/base.py", line 158, in get
    context = self.get_context_data(**kwargs)
  File "/usr/src/api/webapi/views.py", line 126, in get_context_data
    context = super().get_context_data(**kwargs)
  File "/usr/local/lib/python3.7/site-packages/django/views/generic/list.py", line 115, in get_context_data
    queryset = object_list if object_list is not None else self.object_list
AttributeError: 'HomeIndexView' object has no attribute 'object_list'
[ERROR][2020-10-15 03:46:46,808][log.py:228]Internal Server Error: /
Traceback (most recent call last):
  File "/usr/local/lib/python3.7/site-packages/django/core/handlers/exception.py", line 34, in inner
    response = get_response(request)
  File "/usr/local/lib/python3.7/site-packages/django/core/handlers/base.py", line 115, in _get_response
    response = self.process_exception_by_middleware(e, request)
  File "/usr/local/lib/python3.7/site-packages/django/core/handlers/base.py", line 113, in _get_response
    response = wrapped_callback(request, *callback_args, **callback_kwargs)
  File "/usr/local/lib/python3.7/site-packages/django/views/generic/base.py", line 71, in view
    return self.dispatch(request, *args, **kwargs)
  File "/usr/local/lib/python3.7/site-packages/django/views/generic/base.py", line 97, in dispatch
    return handler(request, *args, **kwargs)
  File "/usr/local/lib/python3.7/site-packages/django/views/generic/base.py", line 158, in get
    context = self.get_context_data(**kwargs)
  File "/usr/local/lib/python3.7/site-packages/django/views/generic/list.py", line 115, in get_context_data
    queryset = object_list if object_list is not None else self.object_list
AttributeError: 'HomeIndexView' object has no attribute 'object_list'
[ERROR][2020-10-15 03:46:48,401][log.py:228]Internal Server Error: /
Traceback (most recent call last):
  File "/usr/local/lib/python3.7/site-packages/django/core/handlers/exception.py", line 34, in inner
    response = get_response(request)
  File "/usr/local/lib/python3.7/site-packages/django/core/handlers/base.py", line 115, in _get_response
    response = self.process_exception_by_middleware(e, request)
  File "/usr/local/lib/python3.7/site-packages/django/core/handlers/base.py", line 113, in _get_response
    response = wrapped_callback(request, *callback_args, **callback_kwargs)
  File "/usr/local/lib/python3.7/site-packages/django/views/generic/base.py", line 71, in view
    return self.dispatch(request, *args, **kwargs)
  File "/usr/local/lib/python3.7/site-packages/django/views/generic/base.py", line 97, in dispatch
    return handler(request, *args, **kwargs)
  File "/usr/local/lib/python3.7/site-packages/django/views/generic/base.py", line 158, in get
    context = self.get_context_data(**kwargs)
  File "/usr/local/lib/python3.7/site-packages/django/views/generic/list.py", line 115, in get_context_data
    queryset = object_list if object_list is not None else self.object_list
AttributeError: 'HomeIndexView' object has no attribute 'object_list'
[ERROR][2020-10-15 03:46:49,425][log.py:228]Internal Server Error: /
Traceback (most recent call last):
  File "/usr/local/lib/python3.7/site-packages/django/core/handlers/exception.py", line 34, in inner
    response = get_response(request)
  File "/usr/local/lib/python3.7/site-packages/django/core/handlers/base.py", line 115, in _get_response
    response = self.process_exception_by_middleware(e, request)
  File "/usr/local/lib/python3.7/site-packages/django/core/handlers/base.py", line 113, in _get_response
    response = wrapped_callback(request, *callback_args, **callback_kwargs)
  File "/usr/local/lib/python3.7/site-packages/django/views/generic/base.py", line 71, in view
    return self.dispatch(request, *args, **kwargs)
  File "/usr/local/lib/python3.7/site-packages/django/views/generic/base.py", line 97, in dispatch
    return handler(request, *args, **kwargs)
  File "/usr/local/lib/python3.7/site-packages/django/views/generic/base.py", line 158, in get
    context = self.get_context_data(**kwargs)
  File "/usr/local/lib/python3.7/site-packages/django/views/generic/list.py", line 115, in get_context_data
    queryset = object_list if object_list is not None else self.object_list
AttributeError: 'HomeIndexView' object has no attribute 'object_list'
[ERROR][2020-10-15 04:21:33,395][log.py:228]Internal Server Error: /
Traceback (most recent call last):
  File "/usr/local/lib/python3.7/site-packages/django/template/base.py", line 828, in _resolve_lookup
    current = current[bit]
TypeError: 'Products' object is not subscriptable

During handling of the above exception, another exception occurred:

Traceback (most recent call last):
  File "/usr/local/lib/python3.7/site-packages/django/core/handlers/exception.py", line 34, in inner
    response = get_response(request)
  File "/usr/local/lib/python3.7/site-packages/django/core/handlers/base.py", line 145, in _get_response
    response = self.process_exception_by_middleware(e, request)
  File "/usr/local/lib/python3.7/site-packages/django/core/handlers/base.py", line 143, in _get_response
    response = response.render()
  File "/usr/local/lib/python3.7/site-packages/django/template/response.py", line 105, in render
    self.content = self.rendered_content
  File "/usr/local/lib/python3.7/site-packages/django/template/response.py", line 83, in rendered_content
    return template.render(context, self._request)
  File "/usr/local/lib/python3.7/site-packages/django/template/backends/django.py", line 61, in render
    return self.template.render(context)
  File "/usr/local/lib/python3.7/site-packages/django/template/base.py", line 171, in render
    return self._render(context)
  File "/usr/local/lib/python3.7/site-packages/django/template/base.py", line 163, in _render
    return self.nodelist.render(context)
  File "/usr/local/lib/python3.7/site-packages/django/template/base.py", line 936, in render
    bit = node.render_annotated(context)
  File "/usr/local/lib/python3.7/site-packages/django/template/base.py", line 903, in render_annotated
    return self.render(context)
  File "/usr/local/lib/python3.7/site-packages/django/template/loader_tags.py", line 150, in render
    return compiled_parent._render(context)
  File "/usr/local/lib/python3.7/site-packages/django/template/base.py", line 163, in _render
    return self.nodelist.render(context)
  File "/usr/local/lib/python3.7/site-packages/django/template/base.py", line 936, in render
    bit = node.render_annotated(context)
  File "/usr/local/lib/python3.7/site-packages/django/template/base.py", line 903, in render_annotated
    return self.render(context)
  File "/usr/local/lib/python3.7/site-packages/django/template/loader_tags.py", line 62, in render
    result = block.nodelist.render(context)
  File "/usr/local/lib/python3.7/site-packages/django/template/base.py", line 936, in render
    bit = node.render_annotated(context)
  File "/usr/local/lib/python3.7/site-packages/django/template/base.py", line 903, in render_annotated
    return self.render(context)
  File "/usr/local/lib/python3.7/site-packages/django/template/defaulttags.py", line 209, in render
    nodelist.append(node.render_annotated(context))
  File "/usr/local/lib/python3.7/site-packages/django/template/base.py", line 903, in render_annotated
    return self.render(context)
  File "/usr/local/lib/python3.7/site-packages/django/template/base.py", line 986, in render
    output = self.filter_expression.resolve(context)
  File "/usr/local/lib/python3.7/site-packages/django/template/base.py", line 670, in resolve
    obj = self.var.resolve(context)
  File "/usr/local/lib/python3.7/site-packages/django/template/base.py", line 795, in resolve
    value = self._resolve_lookup(context)
  File "/usr/local/lib/python3.7/site-packages/django/template/base.py", line 836, in _resolve_lookup
    current = getattr(current, bit)
  File "/usr/src/api/webapi/models.py", line 58, in pro_url
    return settings.WEB_BASE_URL + 'products/' + self.id + '/'
AttributeError: module 'vuebackend.settings' has no attribute 'WEB_BASE_URL'
[ERROR][2020-10-15 04:22:18,517][log.py:228]Internal Server Error: /
Traceback (most recent call last):
  File "/usr/local/lib/python3.7/site-packages/django/template/base.py", line 828, in _resolve_lookup
    current = current[bit]
TypeError: 'Products' object is not subscriptable

During handling of the above exception, another exception occurred:

Traceback (most recent call last):
  File "/usr/local/lib/python3.7/site-packages/django/core/handlers/exception.py", line 34, in inner
    response = get_response(request)
  File "/usr/local/lib/python3.7/site-packages/django/core/handlers/base.py", line 145, in _get_response
    response = self.process_exception_by_middleware(e, request)
  File "/usr/local/lib/python3.7/site-packages/django/core/handlers/base.py", line 143, in _get_response
    response = response.render()
  File "/usr/local/lib/python3.7/site-packages/django/template/response.py", line 105, in render
    self.content = self.rendered_content
  File "/usr/local/lib/python3.7/site-packages/django/template/response.py", line 83, in rendered_content
    return template.render(context, self._request)
  File "/usr/local/lib/python3.7/site-packages/django/template/backends/django.py", line 61, in render
    return self.template.render(context)
  File "/usr/local/lib/python3.7/site-packages/django/template/base.py", line 171, in render
    return self._render(context)
  File "/usr/local/lib/python3.7/site-packages/django/template/base.py", line 163, in _render
    return self.nodelist.render(context)
  File "/usr/local/lib/python3.7/site-packages/django/template/base.py", line 936, in render
    bit = node.render_annotated(context)
  File "/usr/local/lib/python3.7/site-packages/django/template/base.py", line 903, in render_annotated
    return self.render(context)
  File "/usr/local/lib/python3.7/site-packages/django/template/loader_tags.py", line 150, in render
    return compiled_parent._render(context)
  File "/usr/local/lib/python3.7/site-packages/django/template/base.py", line 163, in _render
    return self.nodelist.render(context)
  File "/usr/local/lib/python3.7/site-packages/django/template/base.py", line 936, in render
    bit = node.render_annotated(context)
  File "/usr/local/lib/python3.7/site-packages/django/template/base.py", line 903, in render_annotated
    return self.render(context)
  File "/usr/local/lib/python3.7/site-packages/django/template/loader_tags.py", line 62, in render
    result = block.nodelist.render(context)
  File "/usr/local/lib/python3.7/site-packages/django/template/base.py", line 936, in render
    bit = node.render_annotated(context)
  File "/usr/local/lib/python3.7/site-packages/django/template/base.py", line 903, in render_annotated
    return self.render(context)
  File "/usr/local/lib/python3.7/site-packages/django/template/defaulttags.py", line 209, in render
    nodelist.append(node.render_annotated(context))
  File "/usr/local/lib/python3.7/site-packages/django/template/base.py", line 903, in render_annotated
    return self.render(context)
  File "/usr/local/lib/python3.7/site-packages/django/template/base.py", line 986, in render
    output = self.filter_expression.resolve(context)
  File "/usr/local/lib/python3.7/site-packages/django/template/base.py", line 670, in resolve
    obj = self.var.resolve(context)
  File "/usr/local/lib/python3.7/site-packages/django/template/base.py", line 795, in resolve
    value = self._resolve_lookup(context)
  File "/usr/local/lib/python3.7/site-packages/django/template/base.py", line 836, in _resolve_lookup
    current = getattr(current, bit)
  File "/usr/src/api/webapi/models.py", line 58, in pro_url
    return settings.WEB_BASE_URL + 'products/' + self.id + '/'
TypeError: can only concatenate str (not "int") to str
[ERROR][2020-10-15 04:22:35,452][log.py:228]Internal Server Error: /
Traceback (most recent call last):
  File "/usr/local/lib/python3.7/site-packages/django/template/base.py", line 828, in _resolve_lookup
    current = current[bit]
TypeError: 'Products' object is not subscriptable

During handling of the above exception, another exception occurred:

Traceback (most recent call last):
  File "/usr/local/lib/python3.7/site-packages/django/core/handlers/exception.py", line 34, in inner
    response = get_response(request)
  File "/usr/local/lib/python3.7/site-packages/django/core/handlers/base.py", line 145, in _get_response
    response = self.process_exception_by_middleware(e, request)
  File "/usr/local/lib/python3.7/site-packages/django/core/handlers/base.py", line 143, in _get_response
    response = response.render()
  File "/usr/local/lib/python3.7/site-packages/django/template/response.py", line 105, in render
    self.content = self.rendered_content
  File "/usr/local/lib/python3.7/site-packages/django/template/response.py", line 83, in rendered_content
    return template.render(context, self._request)
  File "/usr/local/lib/python3.7/site-packages/django/template/backends/django.py", line 61, in render
    return self.template.render(context)
  File "/usr/local/lib/python3.7/site-packages/django/template/base.py", line 171, in render
    return self._render(context)
  File "/usr/local/lib/python3.7/site-packages/django/template/base.py", line 163, in _render
    return self.nodelist.render(context)
  File "/usr/local/lib/python3.7/site-packages/django/template/base.py", line 936, in render
    bit = node.render_annotated(context)
  File "/usr/local/lib/python3.7/site-packages/django/template/base.py", line 903, in render_annotated
    return self.render(context)
  File "/usr/local/lib/python3.7/site-packages/django/template/loader_tags.py", line 150, in render
    return compiled_parent._render(context)
  File "/usr/local/lib/python3.7/site-packages/django/template/base.py", line 163, in _render
    return self.nodelist.render(context)
  File "/usr/local/lib/python3.7/site-packages/django/template/base.py", line 936, in render
    bit = node.render_annotated(context)
  File "/usr/local/lib/python3.7/site-packages/django/template/base.py", line 903, in render_annotated
    return self.render(context)
  File "/usr/local/lib/python3.7/site-packages/django/template/loader_tags.py", line 62, in render
    result = block.nodelist.render(context)
  File "/usr/local/lib/python3.7/site-packages/django/template/base.py", line 936, in render
    bit = node.render_annotated(context)
  File "/usr/local/lib/python3.7/site-packages/django/template/base.py", line 903, in render_annotated
    return self.render(context)
  File "/usr/local/lib/python3.7/site-packages/django/template/defaulttags.py", line 209, in render
    nodelist.append(node.render_annotated(context))
  File "/usr/local/lib/python3.7/site-packages/django/template/base.py", line 903, in render_annotated
    return self.render(context)
  File "/usr/local/lib/python3.7/site-packages/django/template/base.py", line 986, in render
    output = self.filter_expression.resolve(context)
  File "/usr/local/lib/python3.7/site-packages/django/template/base.py", line 670, in resolve
    obj = self.var.resolve(context)
  File "/usr/local/lib/python3.7/site-packages/django/template/base.py", line 795, in resolve
    value = self._resolve_lookup(context)
  File "/usr/local/lib/python3.7/site-packages/django/template/base.py", line 836, in _resolve_lookup
    current = getattr(current, bit)
  File "/usr/src/api/webapi/models.py", line 58, in pro_url
    return settings.WEB_BASE_URL + 'products/' + self.id
TypeError: can only concatenate str (not "int") to str
[ERROR][2020-10-15 04:24:54,786][log.py:228]Internal Server Error: /
Traceback (most recent call last):
  File "/usr/local/lib/python3.7/site-packages/django/urls/base.py", line 72, in reverse
    extra, resolver = resolver.namespace_dict[ns]
KeyError: 'http'

During handling of the above exception, another exception occurred:

Traceback (most recent call last):
  File "/usr/local/lib/python3.7/site-packages/django/core/handlers/exception.py", line 34, in inner
    response = get_response(request)
  File "/usr/local/lib/python3.7/site-packages/django/core/handlers/base.py", line 145, in _get_response
    response = self.process_exception_by_middleware(e, request)
  File "/usr/local/lib/python3.7/site-packages/django/core/handlers/base.py", line 143, in _get_response
    response = response.render()
  File "/usr/local/lib/python3.7/site-packages/django/template/response.py", line 105, in render
    self.content = self.rendered_content
  File "/usr/local/lib/python3.7/site-packages/django/template/response.py", line 83, in rendered_content
    return template.render(context, self._request)
  File "/usr/local/lib/python3.7/site-packages/django/template/backends/django.py", line 61, in render
    return self.template.render(context)
  File "/usr/local/lib/python3.7/site-packages/django/template/base.py", line 171, in render
    return self._render(context)
  File "/usr/local/lib/python3.7/site-packages/django/template/base.py", line 163, in _render
    return self.nodelist.render(context)
  File "/usr/local/lib/python3.7/site-packages/django/template/base.py", line 936, in render
    bit = node.render_annotated(context)
  File "/usr/local/lib/python3.7/site-packages/django/template/base.py", line 903, in render_annotated
    return self.render(context)
  File "/usr/local/lib/python3.7/site-packages/django/template/loader_tags.py", line 150, in render
    return compiled_parent._render(context)
  File "/usr/local/lib/python3.7/site-packages/django/template/base.py", line 163, in _render
    return self.nodelist.render(context)
  File "/usr/local/lib/python3.7/site-packages/django/template/base.py", line 936, in render
    bit = node.render_annotated(context)
  File "/usr/local/lib/python3.7/site-packages/django/template/base.py", line 903, in render_annotated
    return self.render(context)
  File "/usr/local/lib/python3.7/site-packages/django/template/loader_tags.py", line 62, in render
    result = block.nodelist.render(context)
  File "/usr/local/lib/python3.7/site-packages/django/template/base.py", line 936, in render
    bit = node.render_annotated(context)
  File "/usr/local/lib/python3.7/site-packages/django/template/base.py", line 903, in render_annotated
    return self.render(context)
  File "/usr/local/lib/python3.7/site-packages/django/template/defaulttags.py", line 209, in render
    nodelist.append(node.render_annotated(context))
  File "/usr/local/lib/python3.7/site-packages/django/template/base.py", line 903, in render_annotated
    return self.render(context)
  File "/usr/local/lib/python3.7/site-packages/django/template/defaulttags.py", line 443, in render
    url = reverse(view_name, args=args, kwargs=kwargs, current_app=current_app)
  File "/usr/local/lib/python3.7/site-packages/django/urls/base.py", line 83, in reverse
    raise NoReverseMatch("%s is not a registered namespace" % key)
django.urls.exceptions.NoReverseMatch: 'http' is not a registered namespace
[ERROR][2020-10-15 04:29:48,930][log.py:228]Internal Server Error: /
Traceback (most recent call last):
  File "/usr/local/lib/python3.7/site-packages/django/core/handlers/exception.py", line 34, in inner
    response = get_response(request)
  File "/usr/local/lib/python3.7/site-packages/django/core/handlers/base.py", line 145, in _get_response
    response = self.process_exception_by_middleware(e, request)
  File "/usr/local/lib/python3.7/site-packages/django/core/handlers/base.py", line 143, in _get_response
    response = response.render()
  File "/usr/local/lib/python3.7/site-packages/django/template/response.py", line 105, in render
    self.content = self.rendered_content
  File "/usr/local/lib/python3.7/site-packages/django/template/response.py", line 83, in rendered_content
    return template.render(context, self._request)
  File "/usr/local/lib/python3.7/site-packages/django/template/backends/django.py", line 61, in render
    return self.template.render(context)
  File "/usr/local/lib/python3.7/site-packages/django/template/base.py", line 171, in render
    return self._render(context)
  File "/usr/local/lib/python3.7/site-packages/django/template/base.py", line 163, in _render
    return self.nodelist.render(context)
  File "/usr/local/lib/python3.7/site-packages/django/template/base.py", line 936, in render
    bit = node.render_annotated(context)
  File "/usr/local/lib/python3.7/site-packages/django/template/base.py", line 903, in render_annotated
    return self.render(context)
  File "/usr/local/lib/python3.7/site-packages/django/template/loader_tags.py", line 150, in render
    return compiled_parent._render(context)
  File "/usr/local/lib/python3.7/site-packages/django/template/base.py", line 163, in _render
    return self.nodelist.render(context)
  File "/usr/local/lib/python3.7/site-packages/django/template/base.py", line 936, in render
    bit = node.render_annotated(context)
  File "/usr/local/lib/python3.7/site-packages/django/template/base.py", line 903, in render_annotated
    return self.render(context)
  File "/usr/local/lib/python3.7/site-packages/django/template/loader_tags.py", line 62, in render
    result = block.nodelist.render(context)
  File "/usr/local/lib/python3.7/site-packages/django/template/base.py", line 936, in render
    bit = node.render_annotated(context)
  File "/usr/local/lib/python3.7/site-packages/django/template/base.py", line 903, in render_annotated
    return self.render(context)
  File "/usr/local/lib/python3.7/site-packages/django/template/defaulttags.py", line 209, in render
    nodelist.append(node.render_annotated(context))
  File "/usr/local/lib/python3.7/site-packages/django/template/base.py", line 903, in render_annotated
    return self.render(context)
  File "/usr/local/lib/python3.7/site-packages/django/template/defaulttags.py", line 443, in render
    url = reverse(view_name, args=args, kwargs=kwargs, current_app=current_app)
  File "/usr/local/lib/python3.7/site-packages/django/urls/base.py", line 87, in reverse
    return iri_to_uri(resolver._reverse_with_prefix(view, prefix, *args, **kwargs))
  File "/usr/local/lib/python3.7/site-packages/django/urls/resolvers.py", line 677, in _reverse_with_prefix
    raise NoReverseMatch(msg)
django.urls.exceptions.NoReverseMatch: Reverse for 'product_detail' with arguments '(None,)' not found. 1 pattern(s) tried: ['product/(?P<pk>[0-9]+)$']
[ERROR][2020-10-15 04:30:23,367][log.py:228]Internal Server Error: /
Traceback (most recent call last):
  File "/usr/local/lib/python3.7/site-packages/django/core/handlers/exception.py", line 34, in inner
    response = get_response(request)
  File "/usr/local/lib/python3.7/site-packages/django/core/handlers/base.py", line 145, in _get_response
    response = self.process_exception_by_middleware(e, request)
  File "/usr/local/lib/python3.7/site-packages/django/core/handlers/base.py", line 143, in _get_response
    response = response.render()
  File "/usr/local/lib/python3.7/site-packages/django/template/response.py", line 105, in render
    self.content = self.rendered_content
  File "/usr/local/lib/python3.7/site-packages/django/template/response.py", line 83, in rendered_content
    return template.render(context, self._request)
  File "/usr/local/lib/python3.7/site-packages/django/template/backends/django.py", line 61, in render
    return self.template.render(context)
  File "/usr/local/lib/python3.7/site-packages/django/template/base.py", line 171, in render
    return self._render(context)
  File "/usr/local/lib/python3.7/site-packages/django/template/base.py", line 163, in _render
    return self.nodelist.render(context)
  File "/usr/local/lib/python3.7/site-packages/django/template/base.py", line 936, in render
    bit = node.render_annotated(context)
  File "/usr/local/lib/python3.7/site-packages/django/template/base.py", line 903, in render_annotated
    return self.render(context)
  File "/usr/local/lib/python3.7/site-packages/django/template/loader_tags.py", line 150, in render
    return compiled_parent._render(context)
  File "/usr/local/lib/python3.7/site-packages/django/template/base.py", line 163, in _render
    return self.nodelist.render(context)
  File "/usr/local/lib/python3.7/site-packages/django/template/base.py", line 936, in render
    bit = node.render_annotated(context)
  File "/usr/local/lib/python3.7/site-packages/django/template/base.py", line 903, in render_annotated
    return self.render(context)
  File "/usr/local/lib/python3.7/site-packages/django/template/loader_tags.py", line 62, in render
    result = block.nodelist.render(context)
  File "/usr/local/lib/python3.7/site-packages/django/template/base.py", line 936, in render
    bit = node.render_annotated(context)
  File "/usr/local/lib/python3.7/site-packages/django/template/base.py", line 903, in render_annotated
    return self.render(context)
  File "/usr/local/lib/python3.7/site-packages/django/template/defaulttags.py", line 209, in render
    nodelist.append(node.render_annotated(context))
  File "/usr/local/lib/python3.7/site-packages/django/template/base.py", line 903, in render_annotated
    return self.render(context)
  File "/usr/local/lib/python3.7/site-packages/django/template/defaulttags.py", line 443, in render
    url = reverse(view_name, args=args, kwargs=kwargs, current_app=current_app)
  File "/usr/local/lib/python3.7/site-packages/django/urls/base.py", line 87, in reverse
    return iri_to_uri(resolver._reverse_with_prefix(view, prefix, *args, **kwargs))
  File "/usr/local/lib/python3.7/site-packages/django/urls/resolvers.py", line 677, in _reverse_with_prefix
    raise NoReverseMatch(msg)
django.urls.exceptions.NoReverseMatch: Reverse for 'product_detail' with arguments '(None,)' not found. 1 pattern(s) tried: ['product/(?P<pk>[0-9]+)$']
[ERROR][2020-10-15 04:30:29,237][log.py:228]Internal Server Error: /
Traceback (most recent call last):
  File "/usr/local/lib/python3.7/site-packages/django/core/handlers/exception.py", line 34, in inner
    response = get_response(request)
  File "/usr/local/lib/python3.7/site-packages/django/core/handlers/base.py", line 145, in _get_response
    response = self.process_exception_by_middleware(e, request)
  File "/usr/local/lib/python3.7/site-packages/django/core/handlers/base.py", line 143, in _get_response
    response = response.render()
  File "/usr/local/lib/python3.7/site-packages/django/template/response.py", line 105, in render
    self.content = self.rendered_content
  File "/usr/local/lib/python3.7/site-packages/django/template/response.py", line 83, in rendered_content
    return template.render(context, self._request)
  File "/usr/local/lib/python3.7/site-packages/django/template/backends/django.py", line 61, in render
    return self.template.render(context)
  File "/usr/local/lib/python3.7/site-packages/django/template/base.py", line 171, in render
    return self._render(context)
  File "/usr/local/lib/python3.7/site-packages/django/template/base.py", line 163, in _render
    return self.nodelist.render(context)
  File "/usr/local/lib/python3.7/site-packages/django/template/base.py", line 936, in render
    bit = node.render_annotated(context)
  File "/usr/local/lib/python3.7/site-packages/django/template/base.py", line 903, in render_annotated
    return self.render(context)
  File "/usr/local/lib/python3.7/site-packages/django/template/loader_tags.py", line 150, in render
    return compiled_parent._render(context)
  File "/usr/local/lib/python3.7/site-packages/django/template/base.py", line 163, in _render
    return self.nodelist.render(context)
  File "/usr/local/lib/python3.7/site-packages/django/template/base.py", line 936, in render
    bit = node.render_annotated(context)
  File "/usr/local/lib/python3.7/site-packages/django/template/base.py", line 903, in render_annotated
    return self.render(context)
  File "/usr/local/lib/python3.7/site-packages/django/template/loader_tags.py", line 62, in render
    result = block.nodelist.render(context)
  File "/usr/local/lib/python3.7/site-packages/django/template/base.py", line 936, in render
    bit = node.render_annotated(context)
  File "/usr/local/lib/python3.7/site-packages/django/template/base.py", line 903, in render_annotated
    return self.render(context)
  File "/usr/local/lib/python3.7/site-packages/django/template/defaulttags.py", line 209, in render
    nodelist.append(node.render_annotated(context))
  File "/usr/local/lib/python3.7/site-packages/django/template/base.py", line 903, in render_annotated
    return self.render(context)
  File "/usr/local/lib/python3.7/site-packages/django/template/defaulttags.py", line 443, in render
    url = reverse(view_name, args=args, kwargs=kwargs, current_app=current_app)
  File "/usr/local/lib/python3.7/site-packages/django/urls/base.py", line 87, in reverse
    return iri_to_uri(resolver._reverse_with_prefix(view, prefix, *args, **kwargs))
  File "/usr/local/lib/python3.7/site-packages/django/urls/resolvers.py", line 677, in _reverse_with_prefix
    raise NoReverseMatch(msg)
django.urls.exceptions.NoReverseMatch: Reverse for 'product_detail' with arguments '(None,)' not found. 1 pattern(s) tried: ['product/(?P<pk>[0-9]+)$']
[ERROR][2020-10-15 04:30:30,706][log.py:228]Internal Server Error: /
Traceback (most recent call last):
  File "/usr/local/lib/python3.7/site-packages/django/core/handlers/exception.py", line 34, in inner
    response = get_response(request)
  File "/usr/local/lib/python3.7/site-packages/django/core/handlers/base.py", line 145, in _get_response
    response = self.process_exception_by_middleware(e, request)
  File "/usr/local/lib/python3.7/site-packages/django/core/handlers/base.py", line 143, in _get_response
    response = response.render()
  File "/usr/local/lib/python3.7/site-packages/django/template/response.py", line 105, in render
    self.content = self.rendered_content
  File "/usr/local/lib/python3.7/site-packages/django/template/response.py", line 83, in rendered_content
    return template.render(context, self._request)
  File "/usr/local/lib/python3.7/site-packages/django/template/backends/django.py", line 61, in render
    return self.template.render(context)
  File "/usr/local/lib/python3.7/site-packages/django/template/base.py", line 171, in render
    return self._render(context)
  File "/usr/local/lib/python3.7/site-packages/django/template/base.py", line 163, in _render
    return self.nodelist.render(context)
  File "/usr/local/lib/python3.7/site-packages/django/template/base.py", line 936, in render
    bit = node.render_annotated(context)
  File "/usr/local/lib/python3.7/site-packages/django/template/base.py", line 903, in render_annotated
    return self.render(context)
  File "/usr/local/lib/python3.7/site-packages/django/template/loader_tags.py", line 150, in render
    return compiled_parent._render(context)
  File "/usr/local/lib/python3.7/site-packages/django/template/base.py", line 163, in _render
    return self.nodelist.render(context)
  File "/usr/local/lib/python3.7/site-packages/django/template/base.py", line 936, in render
    bit = node.render_annotated(context)
  File "/usr/local/lib/python3.7/site-packages/django/template/base.py", line 903, in render_annotated
    return self.render(context)
  File "/usr/local/lib/python3.7/site-packages/django/template/loader_tags.py", line 62, in render
    result = block.nodelist.render(context)
  File "/usr/local/lib/python3.7/site-packages/django/template/base.py", line 936, in render
    bit = node.render_annotated(context)
  File "/usr/local/lib/python3.7/site-packages/django/template/base.py", line 903, in render_annotated
    return self.render(context)
  File "/usr/local/lib/python3.7/site-packages/django/template/defaulttags.py", line 209, in render
    nodelist.append(node.render_annotated(context))
  File "/usr/local/lib/python3.7/site-packages/django/template/base.py", line 903, in render_annotated
    return self.render(context)
  File "/usr/local/lib/python3.7/site-packages/django/template/defaulttags.py", line 443, in render
    url = reverse(view_name, args=args, kwargs=kwargs, current_app=current_app)
  File "/usr/local/lib/python3.7/site-packages/django/urls/base.py", line 87, in reverse
    return iri_to_uri(resolver._reverse_with_prefix(view, prefix, *args, **kwargs))
  File "/usr/local/lib/python3.7/site-packages/django/urls/resolvers.py", line 677, in _reverse_with_prefix
    raise NoReverseMatch(msg)
django.urls.exceptions.NoReverseMatch: Reverse for 'product_detail' with arguments '(None,)' not found. 1 pattern(s) tried: ['product/(?P<pk>[0-9]+)$']
[ERROR][2020-10-15 04:32:21,349][log.py:228]Internal Server Error: /
Traceback (most recent call last):
  File "/usr/local/lib/python3.7/site-packages/django/core/handlers/exception.py", line 34, in inner
    response = get_response(request)
  File "/usr/local/lib/python3.7/site-packages/django/core/handlers/base.py", line 145, in _get_response
    response = self.process_exception_by_middleware(e, request)
  File "/usr/local/lib/python3.7/site-packages/django/core/handlers/base.py", line 143, in _get_response
    response = response.render()
  File "/usr/local/lib/python3.7/site-packages/django/template/response.py", line 105, in render
    self.content = self.rendered_content
  File "/usr/local/lib/python3.7/site-packages/django/template/response.py", line 83, in rendered_content
    return template.render(context, self._request)
  File "/usr/local/lib/python3.7/site-packages/django/template/backends/django.py", line 61, in render
    return self.template.render(context)
  File "/usr/local/lib/python3.7/site-packages/django/template/base.py", line 171, in render
    return self._render(context)
  File "/usr/local/lib/python3.7/site-packages/django/template/base.py", line 163, in _render
    return self.nodelist.render(context)
  File "/usr/local/lib/python3.7/site-packages/django/template/base.py", line 936, in render
    bit = node.render_annotated(context)
  File "/usr/local/lib/python3.7/site-packages/django/template/base.py", line 903, in render_annotated
    return self.render(context)
  File "/usr/local/lib/python3.7/site-packages/django/template/loader_tags.py", line 150, in render
    return compiled_parent._render(context)
  File "/usr/local/lib/python3.7/site-packages/django/template/base.py", line 163, in _render
    return self.nodelist.render(context)
  File "/usr/local/lib/python3.7/site-packages/django/template/base.py", line 936, in render
    bit = node.render_annotated(context)
  File "/usr/local/lib/python3.7/site-packages/django/template/base.py", line 903, in render_annotated
    return self.render(context)
  File "/usr/local/lib/python3.7/site-packages/django/template/loader_tags.py", line 62, in render
    result = block.nodelist.render(context)
  File "/usr/local/lib/python3.7/site-packages/django/template/base.py", line 936, in render
    bit = node.render_annotated(context)
  File "/usr/local/lib/python3.7/site-packages/django/template/base.py", line 903, in render_annotated
    return self.render(context)
  File "/usr/local/lib/python3.7/site-packages/django/template/defaulttags.py", line 209, in render
    nodelist.append(node.render_annotated(context))
  File "/usr/local/lib/python3.7/site-packages/django/template/base.py", line 903, in render_annotated
    return self.render(context)
  File "/usr/local/lib/python3.7/site-packages/django/template/defaulttags.py", line 443, in render
    url = reverse(view_name, args=args, kwargs=kwargs, current_app=current_app)
  File "/usr/local/lib/python3.7/site-packages/django/urls/base.py", line 87, in reverse
    return iri_to_uri(resolver._reverse_with_prefix(view, prefix, *args, **kwargs))
  File "/usr/local/lib/python3.7/site-packages/django/urls/resolvers.py", line 677, in _reverse_with_prefix
    raise NoReverseMatch(msg)
django.urls.exceptions.NoReverseMatch: Reverse for 'product_detail' with arguments '(None,)' not found. 1 pattern(s) tried: ['product/(?P<pk>[0-9]+)$']
[ERROR][2020-10-15 04:32:31,206][log.py:228]Internal Server Error: /
Traceback (most recent call last):
  File "/usr/local/lib/python3.7/site-packages/django/core/handlers/exception.py", line 34, in inner
    response = get_response(request)
  File "/usr/local/lib/python3.7/site-packages/django/core/handlers/base.py", line 145, in _get_response
    response = self.process_exception_by_middleware(e, request)
  File "/usr/local/lib/python3.7/site-packages/django/core/handlers/base.py", line 143, in _get_response
    response = response.render()
  File "/usr/local/lib/python3.7/site-packages/django/template/response.py", line 105, in render
    self.content = self.rendered_content
  File "/usr/local/lib/python3.7/site-packages/django/template/response.py", line 83, in rendered_content
    return template.render(context, self._request)
  File "/usr/local/lib/python3.7/site-packages/django/template/backends/django.py", line 61, in render
    return self.template.render(context)
  File "/usr/local/lib/python3.7/site-packages/django/template/base.py", line 171, in render
    return self._render(context)
  File "/usr/local/lib/python3.7/site-packages/django/template/base.py", line 163, in _render
    return self.nodelist.render(context)
  File "/usr/local/lib/python3.7/site-packages/django/template/base.py", line 936, in render
    bit = node.render_annotated(context)
  File "/usr/local/lib/python3.7/site-packages/django/template/base.py", line 903, in render_annotated
    return self.render(context)
  File "/usr/local/lib/python3.7/site-packages/django/template/loader_tags.py", line 150, in render
    return compiled_parent._render(context)
  File "/usr/local/lib/python3.7/site-packages/django/template/base.py", line 163, in _render
    return self.nodelist.render(context)
  File "/usr/local/lib/python3.7/site-packages/django/template/base.py", line 936, in render
    bit = node.render_annotated(context)
  File "/usr/local/lib/python3.7/site-packages/django/template/base.py", line 903, in render_annotated
    return self.render(context)
  File "/usr/local/lib/python3.7/site-packages/django/template/loader_tags.py", line 62, in render
    result = block.nodelist.render(context)
  File "/usr/local/lib/python3.7/site-packages/django/template/base.py", line 936, in render
    bit = node.render_annotated(context)
  File "/usr/local/lib/python3.7/site-packages/django/template/base.py", line 903, in render_annotated
    return self.render(context)
  File "/usr/local/lib/python3.7/site-packages/django/template/defaulttags.py", line 209, in render
    nodelist.append(node.render_annotated(context))
  File "/usr/local/lib/python3.7/site-packages/django/template/base.py", line 903, in render_annotated
    return self.render(context)
  File "/usr/local/lib/python3.7/site-packages/django/template/defaulttags.py", line 443, in render
    url = reverse(view_name, args=args, kwargs=kwargs, current_app=current_app)
  File "/usr/local/lib/python3.7/site-packages/django/urls/base.py", line 87, in reverse
    return iri_to_uri(resolver._reverse_with_prefix(view, prefix, *args, **kwargs))
  File "/usr/local/lib/python3.7/site-packages/django/urls/resolvers.py", line 677, in _reverse_with_prefix
    raise NoReverseMatch(msg)
django.urls.exceptions.NoReverseMatch: Reverse for 'product_detail' with arguments '('home.pro_number_id',)' not found. 1 pattern(s) tried: ['product/(?P<pk>[0-9]+)$']
[ERROR][2020-10-15 04:33:09,018][log.py:228]Internal Server Error: /
Traceback (most recent call last):
  File "/usr/local/lib/python3.7/site-packages/django/core/handlers/exception.py", line 34, in inner
    response = get_response(request)
  File "/usr/local/lib/python3.7/site-packages/django/core/handlers/base.py", line 145, in _get_response
    response = self.process_exception_by_middleware(e, request)
  File "/usr/local/lib/python3.7/site-packages/django/core/handlers/base.py", line 143, in _get_response
    response = response.render()
  File "/usr/local/lib/python3.7/site-packages/django/template/response.py", line 105, in render
    self.content = self.rendered_content
  File "/usr/local/lib/python3.7/site-packages/django/template/response.py", line 83, in rendered_content
    return template.render(context, self._request)
  File "/usr/local/lib/python3.7/site-packages/django/template/backends/django.py", line 61, in render
    return self.template.render(context)
  File "/usr/local/lib/python3.7/site-packages/django/template/base.py", line 171, in render
    return self._render(context)
  File "/usr/local/lib/python3.7/site-packages/django/template/base.py", line 163, in _render
    return self.nodelist.render(context)
  File "/usr/local/lib/python3.7/site-packages/django/template/base.py", line 936, in render
    bit = node.render_annotated(context)
  File "/usr/local/lib/python3.7/site-packages/django/template/base.py", line 903, in render_annotated
    return self.render(context)
  File "/usr/local/lib/python3.7/site-packages/django/template/loader_tags.py", line 150, in render
    return compiled_parent._render(context)
  File "/usr/local/lib/python3.7/site-packages/django/template/base.py", line 163, in _render
    return self.nodelist.render(context)
  File "/usr/local/lib/python3.7/site-packages/django/template/base.py", line 936, in render
    bit = node.render_annotated(context)
  File "/usr/local/lib/python3.7/site-packages/django/template/base.py", line 903, in render_annotated
    return self.render(context)
  File "/usr/local/lib/python3.7/site-packages/django/template/loader_tags.py", line 62, in render
    result = block.nodelist.render(context)
  File "/usr/local/lib/python3.7/site-packages/django/template/base.py", line 936, in render
    bit = node.render_annotated(context)
  File "/usr/local/lib/python3.7/site-packages/django/template/base.py", line 903, in render_annotated
    return self.render(context)
  File "/usr/local/lib/python3.7/site-packages/django/template/defaulttags.py", line 209, in render
    nodelist.append(node.render_annotated(context))
  File "/usr/local/lib/python3.7/site-packages/django/template/base.py", line 903, in render_annotated
    return self.render(context)
  File "/usr/local/lib/python3.7/site-packages/django/template/defaulttags.py", line 443, in render
    url = reverse(view_name, args=args, kwargs=kwargs, current_app=current_app)
  File "/usr/local/lib/python3.7/site-packages/django/urls/base.py", line 87, in reverse
    return iri_to_uri(resolver._reverse_with_prefix(view, prefix, *args, **kwargs))
  File "/usr/local/lib/python3.7/site-packages/django/urls/resolvers.py", line 677, in _reverse_with_prefix
    raise NoReverseMatch(msg)
django.urls.exceptions.NoReverseMatch: Reverse for 'product_detail' with arguments '(None,)' not found. 1 pattern(s) tried: ['product/(?P<pk>[0-9]+)$']
[ERROR][2020-10-15 04:35:32,959][log.py:228]Internal Server Error: /
Traceback (most recent call last):
  File "/usr/local/lib/python3.7/site-packages/django/core/handlers/exception.py", line 34, in inner
    response = get_response(request)
  File "/usr/local/lib/python3.7/site-packages/django/core/handlers/base.py", line 145, in _get_response
    response = self.process_exception_by_middleware(e, request)
  File "/usr/local/lib/python3.7/site-packages/django/core/handlers/base.py", line 143, in _get_response
    response = response.render()
  File "/usr/local/lib/python3.7/site-packages/django/template/response.py", line 105, in render
    self.content = self.rendered_content
  File "/usr/local/lib/python3.7/site-packages/django/template/response.py", line 83, in rendered_content
    return template.render(context, self._request)
  File "/usr/local/lib/python3.7/site-packages/django/template/backends/django.py", line 61, in render
    return self.template.render(context)
  File "/usr/local/lib/python3.7/site-packages/django/template/base.py", line 171, in render
    return self._render(context)
  File "/usr/local/lib/python3.7/site-packages/django/template/base.py", line 163, in _render
    return self.nodelist.render(context)
  File "/usr/local/lib/python3.7/site-packages/django/template/base.py", line 936, in render
    bit = node.render_annotated(context)
  File "/usr/local/lib/python3.7/site-packages/django/template/base.py", line 903, in render_annotated
    return self.render(context)
  File "/usr/local/lib/python3.7/site-packages/django/template/loader_tags.py", line 150, in render
    return compiled_parent._render(context)
  File "/usr/local/lib/python3.7/site-packages/django/template/base.py", line 163, in _render
    return self.nodelist.render(context)
  File "/usr/local/lib/python3.7/site-packages/django/template/base.py", line 936, in render
    bit = node.render_annotated(context)
  File "/usr/local/lib/python3.7/site-packages/django/template/base.py", line 903, in render_annotated
    return self.render(context)
  File "/usr/local/lib/python3.7/site-packages/django/template/loader_tags.py", line 62, in render
    result = block.nodelist.render(context)
  File "/usr/local/lib/python3.7/site-packages/django/template/base.py", line 936, in render
    bit = node.render_annotated(context)
  File "/usr/local/lib/python3.7/site-packages/django/template/base.py", line 903, in render_annotated
    return self.render(context)
  File "/usr/local/lib/python3.7/site-packages/django/template/defaulttags.py", line 209, in render
    nodelist.append(node.render_annotated(context))
  File "/usr/local/lib/python3.7/site-packages/django/template/base.py", line 903, in render_annotated
    return self.render(context)
  File "/usr/local/lib/python3.7/site-packages/django/template/defaulttags.py", line 443, in render
    url = reverse(view_name, args=args, kwargs=kwargs, current_app=current_app)
  File "/usr/local/lib/python3.7/site-packages/django/urls/base.py", line 87, in reverse
    return iri_to_uri(resolver._reverse_with_prefix(view, prefix, *args, **kwargs))
  File "/usr/local/lib/python3.7/site-packages/django/urls/resolvers.py", line 677, in _reverse_with_prefix
    raise NoReverseMatch(msg)
django.urls.exceptions.NoReverseMatch: Reverse for 'product_detail' with keyword arguments '{'pk': None}' not found. 1 pattern(s) tried: ['product/(?P<pk>[0-9]+)$']
[ERROR][2020-10-15 04:35:34,658][log.py:228]Internal Server Error: /
Traceback (most recent call last):
  File "/usr/local/lib/python3.7/site-packages/django/core/handlers/exception.py", line 34, in inner
    response = get_response(request)
  File "/usr/local/lib/python3.7/site-packages/django/core/handlers/base.py", line 145, in _get_response
    response = self.process_exception_by_middleware(e, request)
  File "/usr/local/lib/python3.7/site-packages/django/core/handlers/base.py", line 143, in _get_response
    response = response.render()
  File "/usr/local/lib/python3.7/site-packages/django/template/response.py", line 105, in render
    self.content = self.rendered_content
  File "/usr/local/lib/python3.7/site-packages/django/template/response.py", line 83, in rendered_content
    return template.render(context, self._request)
  File "/usr/local/lib/python3.7/site-packages/django/template/backends/django.py", line 61, in render
    return self.template.render(context)
  File "/usr/local/lib/python3.7/site-packages/django/template/base.py", line 171, in render
    return self._render(context)
  File "/usr/local/lib/python3.7/site-packages/django/template/base.py", line 163, in _render
    return self.nodelist.render(context)
  File "/usr/local/lib/python3.7/site-packages/django/template/base.py", line 936, in render
    bit = node.render_annotated(context)
  File "/usr/local/lib/python3.7/site-packages/django/template/base.py", line 903, in render_annotated
    return self.render(context)
  File "/usr/local/lib/python3.7/site-packages/django/template/loader_tags.py", line 150, in render
    return compiled_parent._render(context)
  File "/usr/local/lib/python3.7/site-packages/django/template/base.py", line 163, in _render
    return self.nodelist.render(context)
  File "/usr/local/lib/python3.7/site-packages/django/template/base.py", line 936, in render
    bit = node.render_annotated(context)
  File "/usr/local/lib/python3.7/site-packages/django/template/base.py", line 903, in render_annotated
    return self.render(context)
  File "/usr/local/lib/python3.7/site-packages/django/template/loader_tags.py", line 62, in render
    result = block.nodelist.render(context)
  File "/usr/local/lib/python3.7/site-packages/django/template/base.py", line 936, in render
    bit = node.render_annotated(context)
  File "/usr/local/lib/python3.7/site-packages/django/template/base.py", line 903, in render_annotated
    return self.render(context)
  File "/usr/local/lib/python3.7/site-packages/django/template/defaulttags.py", line 209, in render
    nodelist.append(node.render_annotated(context))
  File "/usr/local/lib/python3.7/site-packages/django/template/base.py", line 903, in render_annotated
    return self.render(context)
  File "/usr/local/lib/python3.7/site-packages/django/template/defaulttags.py", line 443, in render
    url = reverse(view_name, args=args, kwargs=kwargs, current_app=current_app)
  File "/usr/local/lib/python3.7/site-packages/django/urls/base.py", line 87, in reverse
    return iri_to_uri(resolver._reverse_with_prefix(view, prefix, *args, **kwargs))
  File "/usr/local/lib/python3.7/site-packages/django/urls/resolvers.py", line 677, in _reverse_with_prefix
    raise NoReverseMatch(msg)
django.urls.exceptions.NoReverseMatch: Reverse for 'product_detail' with keyword arguments '{'pk': None}' not found. 1 pattern(s) tried: ['product/(?P<pk>[0-9]+)$']
[ERROR][2020-10-15 04:35:36,206][log.py:228]Internal Server Error: /
Traceback (most recent call last):
  File "/usr/local/lib/python3.7/site-packages/django/core/handlers/exception.py", line 34, in inner
    response = get_response(request)
  File "/usr/local/lib/python3.7/site-packages/django/core/handlers/base.py", line 145, in _get_response
    response = self.process_exception_by_middleware(e, request)
  File "/usr/local/lib/python3.7/site-packages/django/core/handlers/base.py", line 143, in _get_response
    response = response.render()
  File "/usr/local/lib/python3.7/site-packages/django/template/response.py", line 105, in render
    self.content = self.rendered_content
  File "/usr/local/lib/python3.7/site-packages/django/template/response.py", line 83, in rendered_content
    return template.render(context, self._request)
  File "/usr/local/lib/python3.7/site-packages/django/template/backends/django.py", line 61, in render
    return self.template.render(context)
  File "/usr/local/lib/python3.7/site-packages/django/template/base.py", line 171, in render
    return self._render(context)
  File "/usr/local/lib/python3.7/site-packages/django/template/base.py", line 163, in _render
    return self.nodelist.render(context)
  File "/usr/local/lib/python3.7/site-packages/django/template/base.py", line 936, in render
    bit = node.render_annotated(context)
  File "/usr/local/lib/python3.7/site-packages/django/template/base.py", line 903, in render_annotated
    return self.render(context)
  File "/usr/local/lib/python3.7/site-packages/django/template/loader_tags.py", line 150, in render
    return compiled_parent._render(context)
  File "/usr/local/lib/python3.7/site-packages/django/template/base.py", line 163, in _render
    return self.nodelist.render(context)
  File "/usr/local/lib/python3.7/site-packages/django/template/base.py", line 936, in render
    bit = node.render_annotated(context)
  File "/usr/local/lib/python3.7/site-packages/django/template/base.py", line 903, in render_annotated
    return self.render(context)
  File "/usr/local/lib/python3.7/site-packages/django/template/loader_tags.py", line 62, in render
    result = block.nodelist.render(context)
  File "/usr/local/lib/python3.7/site-packages/django/template/base.py", line 936, in render
    bit = node.render_annotated(context)
  File "/usr/local/lib/python3.7/site-packages/django/template/base.py", line 903, in render_annotated
    return self.render(context)
  File "/usr/local/lib/python3.7/site-packages/django/template/defaulttags.py", line 209, in render
    nodelist.append(node.render_annotated(context))
  File "/usr/local/lib/python3.7/site-packages/django/template/base.py", line 903, in render_annotated
    return self.render(context)
  File "/usr/local/lib/python3.7/site-packages/django/template/defaulttags.py", line 443, in render
    url = reverse(view_name, args=args, kwargs=kwargs, current_app=current_app)
  File "/usr/local/lib/python3.7/site-packages/django/urls/base.py", line 87, in reverse
    return iri_to_uri(resolver._reverse_with_prefix(view, prefix, *args, **kwargs))
  File "/usr/local/lib/python3.7/site-packages/django/urls/resolvers.py", line 677, in _reverse_with_prefix
    raise NoReverseMatch(msg)
django.urls.exceptions.NoReverseMatch: Reverse for 'product_detail' with keyword arguments '{'pk': None}' not found. 1 pattern(s) tried: ['product/(?P<pk>[0-9]+)$']
[ERROR][2020-10-15 04:35:37,546][log.py:228]Internal Server Error: /
Traceback (most recent call last):
  File "/usr/local/lib/python3.7/site-packages/django/core/handlers/exception.py", line 34, in inner
    response = get_response(request)
  File "/usr/local/lib/python3.7/site-packages/django/core/handlers/base.py", line 145, in _get_response
    response = self.process_exception_by_middleware(e, request)
  File "/usr/local/lib/python3.7/site-packages/django/core/handlers/base.py", line 143, in _get_response
    response = response.render()
  File "/usr/local/lib/python3.7/site-packages/django/template/response.py", line 105, in render
    self.content = self.rendered_content
  File "/usr/local/lib/python3.7/site-packages/django/template/response.py", line 83, in rendered_content
    return template.render(context, self._request)
  File "/usr/local/lib/python3.7/site-packages/django/template/backends/django.py", line 61, in render
    return self.template.render(context)
  File "/usr/local/lib/python3.7/site-packages/django/template/base.py", line 171, in render
    return self._render(context)
  File "/usr/local/lib/python3.7/site-packages/django/template/base.py", line 163, in _render
    return self.nodelist.render(context)
  File "/usr/local/lib/python3.7/site-packages/django/template/base.py", line 936, in render
    bit = node.render_annotated(context)
  File "/usr/local/lib/python3.7/site-packages/django/template/base.py", line 903, in render_annotated
    return self.render(context)
  File "/usr/local/lib/python3.7/site-packages/django/template/loader_tags.py", line 150, in render
    return compiled_parent._render(context)
  File "/usr/local/lib/python3.7/site-packages/django/template/base.py", line 163, in _render
    return self.nodelist.render(context)
  File "/usr/local/lib/python3.7/site-packages/django/template/base.py", line 936, in render
    bit = node.render_annotated(context)
  File "/usr/local/lib/python3.7/site-packages/django/template/base.py", line 903, in render_annotated
    return self.render(context)
  File "/usr/local/lib/python3.7/site-packages/django/template/loader_tags.py", line 62, in render
    result = block.nodelist.render(context)
  File "/usr/local/lib/python3.7/site-packages/django/template/base.py", line 936, in render
    bit = node.render_annotated(context)
  File "/usr/local/lib/python3.7/site-packages/django/template/base.py", line 903, in render_annotated
    return self.render(context)
  File "/usr/local/lib/python3.7/site-packages/django/template/defaulttags.py", line 209, in render
    nodelist.append(node.render_annotated(context))
  File "/usr/local/lib/python3.7/site-packages/django/template/base.py", line 903, in render_annotated
    return self.render(context)
  File "/usr/local/lib/python3.7/site-packages/django/template/defaulttags.py", line 443, in render
    url = reverse(view_name, args=args, kwargs=kwargs, current_app=current_app)
  File "/usr/local/lib/python3.7/site-packages/django/urls/base.py", line 87, in reverse
    return iri_to_uri(resolver._reverse_with_prefix(view, prefix, *args, **kwargs))
  File "/usr/local/lib/python3.7/site-packages/django/urls/resolvers.py", line 677, in _reverse_with_prefix
    raise NoReverseMatch(msg)
django.urls.exceptions.NoReverseMatch: Reverse for 'product_detail' with keyword arguments '{'pk': None}' not found. 1 pattern(s) tried: ['product/(?P<pk>[0-9]+)$']
[ERROR][2020-10-15 04:37:20,409][log.py:228]Internal Server Error: /
Traceback (most recent call last):
  File "/usr/local/lib/python3.7/site-packages/django/core/handlers/exception.py", line 34, in inner
    response = get_response(request)
  File "/usr/local/lib/python3.7/site-packages/django/core/handlers/base.py", line 145, in _get_response
    response = self.process_exception_by_middleware(e, request)
  File "/usr/local/lib/python3.7/site-packages/django/core/handlers/base.py", line 143, in _get_response
    response = response.render()
  File "/usr/local/lib/python3.7/site-packages/django/template/response.py", line 105, in render
    self.content = self.rendered_content
  File "/usr/local/lib/python3.7/site-packages/django/template/response.py", line 83, in rendered_content
    return template.render(context, self._request)
  File "/usr/local/lib/python3.7/site-packages/django/template/backends/django.py", line 61, in render
    return self.template.render(context)
  File "/usr/local/lib/python3.7/site-packages/django/template/base.py", line 171, in render
    return self._render(context)
  File "/usr/local/lib/python3.7/site-packages/django/template/base.py", line 163, in _render
    return self.nodelist.render(context)
  File "/usr/local/lib/python3.7/site-packages/django/template/base.py", line 936, in render
    bit = node.render_annotated(context)
  File "/usr/local/lib/python3.7/site-packages/django/template/base.py", line 903, in render_annotated
    return self.render(context)
  File "/usr/local/lib/python3.7/site-packages/django/template/loader_tags.py", line 150, in render
    return compiled_parent._render(context)
  File "/usr/local/lib/python3.7/site-packages/django/template/base.py", line 163, in _render
    return self.nodelist.render(context)
  File "/usr/local/lib/python3.7/site-packages/django/template/base.py", line 936, in render
    bit = node.render_annotated(context)
  File "/usr/local/lib/python3.7/site-packages/django/template/base.py", line 903, in render_annotated
    return self.render(context)
  File "/usr/local/lib/python3.7/site-packages/django/template/loader_tags.py", line 62, in render
    result = block.nodelist.render(context)
  File "/usr/local/lib/python3.7/site-packages/django/template/base.py", line 936, in render
    bit = node.render_annotated(context)
  File "/usr/local/lib/python3.7/site-packages/django/template/base.py", line 903, in render_annotated
    return self.render(context)
  File "/usr/local/lib/python3.7/site-packages/django/template/defaulttags.py", line 209, in render
    nodelist.append(node.render_annotated(context))
  File "/usr/local/lib/python3.7/site-packages/django/template/base.py", line 903, in render_annotated
    return self.render(context)
  File "/usr/local/lib/python3.7/site-packages/django/template/defaulttags.py", line 443, in render
    url = reverse(view_name, args=args, kwargs=kwargs, current_app=current_app)
  File "/usr/local/lib/python3.7/site-packages/django/urls/base.py", line 87, in reverse
    return iri_to_uri(resolver._reverse_with_prefix(view, prefix, *args, **kwargs))
  File "/usr/local/lib/python3.7/site-packages/django/urls/resolvers.py", line 677, in _reverse_with_prefix
    raise NoReverseMatch(msg)
django.urls.exceptions.NoReverseMatch: Reverse for 'product_detail' with arguments '(None,)' not found. 1 pattern(s) tried: ['product/(?P<pk>[0-9]+)$']
[ERROR][2020-10-15 04:38:15,094][log.py:228]Internal Server Error: /
Traceback (most recent call last):
  File "/usr/local/lib/python3.7/site-packages/django/core/handlers/exception.py", line 34, in inner
    response = get_response(request)
  File "/usr/local/lib/python3.7/site-packages/django/core/handlers/base.py", line 145, in _get_response
    response = self.process_exception_by_middleware(e, request)
  File "/usr/local/lib/python3.7/site-packages/django/core/handlers/base.py", line 143, in _get_response
    response = response.render()
  File "/usr/local/lib/python3.7/site-packages/django/template/response.py", line 105, in render
    self.content = self.rendered_content
  File "/usr/local/lib/python3.7/site-packages/django/template/response.py", line 83, in rendered_content
    return template.render(context, self._request)
  File "/usr/local/lib/python3.7/site-packages/django/template/backends/django.py", line 61, in render
    return self.template.render(context)
  File "/usr/local/lib/python3.7/site-packages/django/template/base.py", line 171, in render
    return self._render(context)
  File "/usr/local/lib/python3.7/site-packages/django/template/base.py", line 163, in _render
    return self.nodelist.render(context)
  File "/usr/local/lib/python3.7/site-packages/django/template/base.py", line 936, in render
    bit = node.render_annotated(context)
  File "/usr/local/lib/python3.7/site-packages/django/template/base.py", line 903, in render_annotated
    return self.render(context)
  File "/usr/local/lib/python3.7/site-packages/django/template/loader_tags.py", line 150, in render
    return compiled_parent._render(context)
  File "/usr/local/lib/python3.7/site-packages/django/template/base.py", line 163, in _render
    return self.nodelist.render(context)
  File "/usr/local/lib/python3.7/site-packages/django/template/base.py", line 936, in render
    bit = node.render_annotated(context)
  File "/usr/local/lib/python3.7/site-packages/django/template/base.py", line 903, in render_annotated
    return self.render(context)
  File "/usr/local/lib/python3.7/site-packages/django/template/loader_tags.py", line 62, in render
    result = block.nodelist.render(context)
  File "/usr/local/lib/python3.7/site-packages/django/template/base.py", line 936, in render
    bit = node.render_annotated(context)
  File "/usr/local/lib/python3.7/site-packages/django/template/base.py", line 903, in render_annotated
    return self.render(context)
  File "/usr/local/lib/python3.7/site-packages/django/template/defaulttags.py", line 209, in render
    nodelist.append(node.render_annotated(context))
  File "/usr/local/lib/python3.7/site-packages/django/template/base.py", line 903, in render_annotated
    return self.render(context)
  File "/usr/local/lib/python3.7/site-packages/django/template/defaulttags.py", line 443, in render
    url = reverse(view_name, args=args, kwargs=kwargs, current_app=current_app)
  File "/usr/local/lib/python3.7/site-packages/django/urls/base.py", line 87, in reverse
    return iri_to_uri(resolver._reverse_with_prefix(view, prefix, *args, **kwargs))
  File "/usr/local/lib/python3.7/site-packages/django/urls/resolvers.py", line 677, in _reverse_with_prefix
    raise NoReverseMatch(msg)
django.urls.exceptions.NoReverseMatch: Reverse for 'product_detail' with arguments '(None,)' not found. 1 pattern(s) tried: ['product/(?P<pk>[0-9]+)$']
[ERROR][2020-10-15 04:38:17,903][log.py:228]Internal Server Error: /
Traceback (most recent call last):
  File "/usr/local/lib/python3.7/site-packages/django/core/handlers/exception.py", line 34, in inner
    response = get_response(request)
  File "/usr/local/lib/python3.7/site-packages/django/core/handlers/base.py", line 145, in _get_response
    response = self.process_exception_by_middleware(e, request)
  File "/usr/local/lib/python3.7/site-packages/django/core/handlers/base.py", line 143, in _get_response
    response = response.render()
  File "/usr/local/lib/python3.7/site-packages/django/template/response.py", line 105, in render
    self.content = self.rendered_content
  File "/usr/local/lib/python3.7/site-packages/django/template/response.py", line 83, in rendered_content
    return template.render(context, self._request)
  File "/usr/local/lib/python3.7/site-packages/django/template/backends/django.py", line 61, in render
    return self.template.render(context)
  File "/usr/local/lib/python3.7/site-packages/django/template/base.py", line 171, in render
    return self._render(context)
  File "/usr/local/lib/python3.7/site-packages/django/template/base.py", line 163, in _render
    return self.nodelist.render(context)
  File "/usr/local/lib/python3.7/site-packages/django/template/base.py", line 936, in render
    bit = node.render_annotated(context)
  File "/usr/local/lib/python3.7/site-packages/django/template/base.py", line 903, in render_annotated
    return self.render(context)
  File "/usr/local/lib/python3.7/site-packages/django/template/loader_tags.py", line 150, in render
    return compiled_parent._render(context)
  File "/usr/local/lib/python3.7/site-packages/django/template/base.py", line 163, in _render
    return self.nodelist.render(context)
  File "/usr/local/lib/python3.7/site-packages/django/template/base.py", line 936, in render
    bit = node.render_annotated(context)
  File "/usr/local/lib/python3.7/site-packages/django/template/base.py", line 903, in render_annotated
    return self.render(context)
  File "/usr/local/lib/python3.7/site-packages/django/template/loader_tags.py", line 62, in render
    result = block.nodelist.render(context)
  File "/usr/local/lib/python3.7/site-packages/django/template/base.py", line 936, in render
    bit = node.render_annotated(context)
  File "/usr/local/lib/python3.7/site-packages/django/template/base.py", line 903, in render_annotated
    return self.render(context)
  File "/usr/local/lib/python3.7/site-packages/django/template/defaulttags.py", line 209, in render
    nodelist.append(node.render_annotated(context))
  File "/usr/local/lib/python3.7/site-packages/django/template/base.py", line 903, in render_annotated
    return self.render(context)
  File "/usr/local/lib/python3.7/site-packages/django/template/defaulttags.py", line 443, in render
    url = reverse(view_name, args=args, kwargs=kwargs, current_app=current_app)
  File "/usr/local/lib/python3.7/site-packages/django/urls/base.py", line 87, in reverse
    return iri_to_uri(resolver._reverse_with_prefix(view, prefix, *args, **kwargs))
  File "/usr/local/lib/python3.7/site-packages/django/urls/resolvers.py", line 677, in _reverse_with_prefix
    raise NoReverseMatch(msg)
django.urls.exceptions.NoReverseMatch: Reverse for 'product_detail' with arguments '(None,)' not found. 1 pattern(s) tried: ['product/(?P<pk>[0-9]+)$']
