[ERROR][2020-10-01 02:15:39,169][log.py:228]Internal Server Error: /api/get_logs/
Traceback (most recent call last):
  File "/usr/local/lib/python3.7/site-packages/django/core/handlers/exception.py", line 34, in inner
    response = get_response(request)
  File "/usr/local/lib/python3.7/site-packages/django/core/handlers/base.py", line 115, in _get_response
    response = self.process_exception_by_middleware(e, request)
  File "/usr/local/lib/python3.7/site-packages/django/core/handlers/base.py", line 113, in _get_response
    response = wrapped_callback(request, *callback_args, **callback_kwargs)
  File "/usr/local/lib/python3.7/site-packages/django/views/decorators/csrf.py", line 54, in wrapped_view
    return view_func(*args, **kwargs)
  File "/usr/local/lib/python3.7/site-packages/django/views/generic/base.py", line 71, in view
    return self.dispatch(request, *args, **kwargs)
  File "/usr/local/lib/python3.7/site-packages/rest_framework/views.py", line 505, in dispatch
    response = self.handle_exception(exc)
  File "/usr/local/lib/python3.7/site-packages/rest_framework/views.py", line 465, in handle_exception
    self.raise_uncaught_exception(exc)
  File "/usr/local/lib/python3.7/site-packages/rest_framework/views.py", line 476, in raise_uncaught_exception
    raise exc
  File "/usr/local/lib/python3.7/site-packages/rest_framework/views.py", line 502, in dispatch
    response = handler(request, *args, **kwargs)
  File "/usr/src/api/api/views.py", line 385, in get
    l_split = json.loads(line.strip('\n'))
  File "/usr/local/lib/python3.7/json/__init__.py", line 348, in loads
    return _default_decoder.decode(s)
  File "/usr/local/lib/python3.7/json/decoder.py", line 340, in decode
    raise JSONDecodeError("Extra data", s, end)
json.decoder.JSONDecodeError: Extra data: line 1 column 5 (char 4)
[ERROR][2020-10-01 02:36:10,606][log.py:228]Internal Server Error: /api/get_logs/
Traceback (most recent call last):
  File "/usr/local/lib/python3.7/site-packages/django/core/handlers/exception.py", line 34, in inner
    response = get_response(request)
  File "/usr/local/lib/python3.7/site-packages/django/core/handlers/base.py", line 115, in _get_response
    response = self.process_exception_by_middleware(e, request)
  File "/usr/local/lib/python3.7/site-packages/django/core/handlers/base.py", line 113, in _get_response
    response = wrapped_callback(request, *callback_args, **callback_kwargs)
  File "/usr/local/lib/python3.7/site-packages/django/views/decorators/csrf.py", line 54, in wrapped_view
    return view_func(*args, **kwargs)
  File "/usr/local/lib/python3.7/site-packages/django/views/generic/base.py", line 71, in view
    return self.dispatch(request, *args, **kwargs)
  File "/usr/local/lib/python3.7/site-packages/rest_framework/views.py", line 505, in dispatch
    response = self.handle_exception(exc)
  File "/usr/local/lib/python3.7/site-packages/rest_framework/views.py", line 465, in handle_exception
    self.raise_uncaught_exception(exc)
  File "/usr/local/lib/python3.7/site-packages/rest_framework/views.py", line 476, in raise_uncaught_exception
    raise exc
  File "/usr/local/lib/python3.7/site-packages/rest_framework/views.py", line 502, in dispatch
    response = handler(request, *args, **kwargs)
  File "/usr/src/api/api/views.py", line 385, in get
    l_split = json.loads(line.strip('\n'))
  File "/usr/local/lib/python3.7/json/__init__.py", line 348, in loads
    return _default_decoder.decode(s)
  File "/usr/local/lib/python3.7/json/decoder.py", line 337, in decode
    obj, end = self.raw_decode(s, idx=_w(s, 0).end())
  File "/usr/local/lib/python3.7/json/decoder.py", line 355, in raw_decode
    raise JSONDecodeError("Expecting value", s, err.value) from None
json.decoder.JSONDecodeError: Expecting value: line 1 column 491 (char 490)
[ERROR][2020-10-12 07:13:05,904][log.py:228]Internal Server Error: /api/staffs/null/
Traceback (most recent call last):
  File "/usr/local/lib/python3.7/site-packages/rest_framework/request.py", line 74, in wrap_attributeerrors
    yield
  File "/usr/local/lib/python3.7/site-packages/rest_framework/request.py", line 220, in user
    self._authenticate()
  File "/usr/local/lib/python3.7/site-packages/rest_framework/request.py", line 373, in _authenticate
    user_auth_tuple = authenticator.authenticate(self)
  File "/usr/src/api/user/authentications.py", line 25, in authenticate
    if token and user.is_use == 1:
AttributeError: 'NoneType' object has no attribute 'is_use'

During handling of the above exception, another exception occurred:

Traceback (most recent call last):
  File "/usr/local/lib/python3.7/site-packages/django/core/handlers/exception.py", line 34, in inner
    response = get_response(request)
  File "/usr/local/lib/python3.7/site-packages/django/core/handlers/base.py", line 115, in _get_response
    response = self.process_exception_by_middleware(e, request)
  File "/usr/local/lib/python3.7/site-packages/django/core/handlers/base.py", line 113, in _get_response
    response = wrapped_callback(request, *callback_args, **callback_kwargs)
  File "/usr/local/lib/python3.7/site-packages/django/views/decorators/csrf.py", line 54, in wrapped_view
    return view_func(*args, **kwargs)
  File "/usr/local/lib/python3.7/site-packages/rest_framework/viewsets.py", line 114, in view
    return self.dispatch(request, *args, **kwargs)
  File "/usr/local/lib/python3.7/site-packages/rest_framework/views.py", line 505, in dispatch
    response = self.handle_exception(exc)
  File "/usr/local/lib/python3.7/site-packages/rest_framework/views.py", line 465, in handle_exception
    self.raise_uncaught_exception(exc)
  File "/usr/local/lib/python3.7/site-packages/rest_framework/views.py", line 476, in raise_uncaught_exception
    raise exc
  File "/usr/local/lib/python3.7/site-packages/rest_framework/views.py", line 493, in dispatch
    self.initial(request, *args, **kwargs)
  File "/usr/local/lib/python3.7/site-packages/rest_framework/views.py", line 410, in initial
    self.perform_authentication(request)
  File "/usr/local/lib/python3.7/site-packages/rest_framework/views.py", line 324, in perform_authentication
    request.user
  File "/usr/local/lib/python3.7/site-packages/rest_framework/request.py", line 220, in user
    self._authenticate()
  File "/usr/local/lib/python3.7/contextlib.py", line 130, in __exit__
    self.gen.throw(type, value, traceback)
  File "/usr/local/lib/python3.7/site-packages/rest_framework/request.py", line 78, in wrap_attributeerrors
    raise exc.with_traceback(info[2])
  File "/usr/local/lib/python3.7/site-packages/rest_framework/request.py", line 74, in wrap_attributeerrors
    yield
  File "/usr/local/lib/python3.7/site-packages/rest_framework/request.py", line 220, in user
    self._authenticate()
  File "/usr/local/lib/python3.7/site-packages/rest_framework/request.py", line 373, in _authenticate
    user_auth_tuple = authenticator.authenticate(self)
  File "/usr/src/api/user/authentications.py", line 25, in authenticate
    if token and user.is_use == 1:
rest_framework.request.WrappedAttributeError: 'NoneType' object has no attribute 'is_use'
